Workbook

Sheet Schedule
A1: f | B1: Sunday | D1: Monday | F1: Tuesday | H1: Wednesday | J1: Thursday | L1: Friday | N1: Saturday
A3: Date | B3: 43127 | D3: 43128 | F3: 43129 | H3: 43130 | J3: 43131 | L3: 43132 | N3: 43133 | P3: Date
A4: 8:00pm est | D4: Tuna (5) @ CD (2) | J4: SR (5) @ Knights (2) | K4: TBD (0) @ RBB (5) | P4: 8:00pm est | Q4: Team Name | R4: Abb. | S4: Wins | T4: Losses | U4: Goals | V4: Goals Against | W4: Goal Eff
A5: 8:00pm est | F5: NLG (0) @ Str8 (5) | J5: Str8 (5) @ Pls (4) | P5: 8:00pm est | Q5: Str8 Griffin | R5: Str8 | S5: 21 | T5: 1 | U5: 87 | V5: 24 | W5: =U5/(U5+V5) -> 0.78378378
A6: 9:00pm est | B6: Standings to the right of Calendar | D6: CD (5) @ PW (0) | G6: TBD (3) @ Tuna (5) | H6: RBB (5) @ Tuna (0) | I6: Ninja (5) @ PW (3) | J6: TBD (2) @ SR (5) | K6: RBB (5) @ Knights (1) | P6: 9:00pm est | Q6: We Respect Hoez | R6: Pls | S6: 18 | T6: 4 | U6: 82 | V6: 42 | W6: =U6/(U6+V6) -> 0.66129032
A7: 9:00pm est | F7: Str8 (5) @ WTF (3) | G7: NLG (5) @ SPU (1) | J7: SPU (FF L) @ Str8 (FF W) | K7: NLG (5) @ Ninja (0) | P7: 9:00pm est | Q7: Way To Fail | R7: WTF | S7: 15 | T7: 7 | U7: 78 | V7: 44 | W7: =U7/(U7+V7) -> 0.63934426
A8: 10:00pm est | F8: Tuna (5) @ Knights (0) | G8: TBD (5) @ SML08 (4) | H8: SML08 (1) @ Tuna (5) | I8: SR (0) @ RBB (5) | J8: WTF (5) @ Ninja (0) | K8: Pork @ NLG (FF W) | P8: 10:00pm est | Q8: Never Let Go | R8: NLG | S8: 14 | T8: 8 | U8: 68 | V8: 49 | W8: =U8/(U8+V8) -> 0.58119658
A9: 10:00pm est | F9: WTF (5) @ SPU (2) | G9: Ninja (0) @ Ncro (5) | P9: 10:00pm est | Q9: Collateral Damage | R9: CD | S9: 8 | T9: 14 | U9: 22 | V9: 59 | W9: =U9/(U9+V9) -> 0.27160494
A10: 11:00pm est | F10: SML08 (5) @ Knights (2) | G10: Ncro (5) @ Pork (0) | H10: SML08 (2) @ SR (5) | J10: Pork (1) @ WTF (5) | P10: 11:00pm est | Q10: Paradox Warriors | R10: PW | S10: 6 | T10: 16 | U10: 8 | V10: 80 | W10: =U10/(U10+V10) -> 0.090909091
A11: 11:00pm est | P11: 11:00pm est | Q11: NecroBonk | R11: Ncro | S11: 3 | T11: 19 | U11: 15 | V11: 23 | W11: =U11/(U11+V11) -> 0.39473684
Q12: Stat Padders United | R12: SPU | S12: 0 | T12: 22 | U12: 3 | V12: 15 | W12: =U12/(U12+V12) -> 0.16666667
A13: Date | B13: 43134 | D13: 43135 | F13: 43136 | H13: 43137 | J13: 43138 | L13: 43139 | N13: 43140 | P13: Date
A14: 8:00pm est | F14: Ninja (5) @ Pork (2) | G14: TBD (5) @ Knights (2) | H14: Ninja (0) @ SR (5) | I14: RBB (5) @ Pork (0) | J14: NLG (5) @ PW (0) | P14: 8:00pm est | Q14: Team Name | R14: Abb. | S14: Wins | T14: Losses | U14: Goals | V14: Goals Against | W14: Goal Eff
A15: 8:00pm est | H15: NLG (5) @ CD (0) | J15: RBB (4) @ Str8 (5) | P15: 8:00pm est | Q15: Rooster Bux to Blow | R15: RBB | S15: 20 | T15: 2 | U15: 96 | V15: 22 | W15: =U15/(U15+V15) -> 0.81355932
A16: 9:00pm est | F16: Knights (5) @ Ninja (2) | G16: TBD (FF W) @ Pork | H16: RBB (5) @ Ninja (0) | I16: Pork (2) @ SR (5) | J16: Pls (3) @ NLG (5) | K16: WTF (5) @ PW (1) | P16: 9:00pm est | Q16: Shadow Realm | R16: SR | S16: 16 | T16: 6 | U16: 72 | V16: 50 | W16: =U16/(U16+V16) -> 0.59016393
A17: 9:00pm est | H17: PW (1) @ Knights (5) | L17: Str8 (5) @ PW (0) | P17: 9:00pm est | Q17: Our Lady Tuna | R17: Tuna | S17: 14 | T17: 8 | U17: 67 | V17: 54 | W17: =U17/(U17+V17) -> 0.55371901
A18: 10:00pm est | D18: CD (FF W) @ SPU (FF L) | E18: Pls (5) @ SML08 (0) | G18: SPU (0) @ Pls (5) | J18: Pls (5) @ WTF (3) | P18: 10:00pm est | Q18: SML08 All Stars and Kazink | R18: SML08 | S18: 12 | T18: 10 | U18: 62 | V18: 65 | W18: =U18/(U18+V18) -> 0.48818898
A19: 10:00pm est | D19: Ncro (0) @ RBB (5) | F19: Ncro (0) @ WTF (5) | G19: SML08 (1) @ Str8 (5) | L19: Ncro (0) @ Str8 (5) | P19: 10:00pm est | Q19: Lumbridge White Knights | R19: Knights | S19: 12 | T19: 10 | U19: 62 | V19: 65 | W19: =U19/(U19+V19) -> 0.48818898
A20: 11:00pm est | D20: Ncro @ SPU (DBL FF) | E20: SR (5) @ CD (0) | F20: SML08 (5) @ WTF (4) | P20: 11:00pm est | Q20: TBD | R20: TBD | S20: 9 | T20: 13 | U20: 49 | V20: 74 | W20: =U20/(U20+V20) -> 0.39837398
A21: 11:00pm est | F21: Ncro (5) @ Pls (3) | L21: NLG (5) @ Ncro (0) | P21: 11:00pm est | Q21: Team Ninja | R21: Ninja | S21: 5 | T21: 17 | U21: 26 | V21: 86 | W21: =U21/(U21+V21) -> 0.23214286
Q22: PORKCHOP SANDWICHES | R22: Pork | S22: 1 | T22: 21 | U22: 10 | V22: 55 | W22: =U22/(U22+V22) -> 0.15384615
A23: Date | B23: 43141 | D23: 43142 | F23: 43143 | H23: 43144 | J23: 43145 | L23: 43146 | N23: 43147 | P23: Date | S23: =SUM(S5:S12,S15:S22) -> 174 | T23: =SUM(T5:T12,T15:T22) -> 178 | U23: =SUM(U5:U12,U15:U22) -> 807 | V23: =SUM(V5:V12,V15:V22) -> 807
A24: 8:00pm est | F24: TBD (5) @ Ninja (1) | H24: Tuna (5) @ Ninja (1) | J24: TBD (5) @ PW (0) | P24: 8:00pm est | Q24: Color=Rescheduled | T24: 2 DBL FF
A25: 8:00pm est | F25: Knights (0) @ Str8 (5) | H25: SML08 (5) @ NLG (3) | J25: NLG (2) @ SR (5) | P25: 8:00pm est
A26: 9:00pm est | B26: Str8 (5) @ CD (0) | D26: Pls (5) @ PW (1) | F26: Str8 (5) @ TBD (0) | G26: SPU (FF L)@ Tuna (FF W) | H26: SR (5) @ Tuna (1) | I26: CD (1) @ Knights (5) | J26: TBD (0) @ Pls (5) | K26: PW (0) @ SML08 (5) | P26: 9:00pm est | Q26: Wild Card Standings | R26: Abb. | S26: Wins | T26: Losses | U26: Goals | V26: Goals Against | W26: Goal Eff
A27: 9:00pm est | J27: NLG (5) @ WTF (0) | K27: SR (2) @ Pls (5) | P27: 9:00pm est | Q27: We Respect Hoez | R27: Pls | S27: 18 | T27: 4 | U27: 82 | V27: 42 | W27: =U27/(U27+V27) -> 0.66129032
A28: 10:00pm est | D28: CD (2) @ Pls (5) | E28: Ncro @ PW (FF W) | F28: SML08 (5) @ Ninja (2) | G28: Pork (0) @ Tuna (5) | H28: RBB (5) @ SML08 (2) | I28: SR (5) @ PW (0) | J28: SML08 (FF W) @ SPU (FF L) | P28: 10:00pm est | Q28: Shadow Realm | R28: SR | S28: 16 | T28: 6 | U28: 72 | V28: 50 | W28: =U28/(U28+V28) -> 0.59016393
A29: 10:00pm est | F29: Knights (FF W) @ SPU | H29: Knights (5) @ Pork (1) | I29: WTF (5) @ CD (0) | P29: 10:00pm est | Q29: Way To Fail | R29: WTF | S29: 15 | T29: 7 | U29: 78 | V29: 44 | W29: =U29/(U29+V29) -> 0.63934426
A30: 11:00pm est | D30: CD (FF W) @ Ncro (FF L) | F30: SML08 (5) @ Pork (1) | H30: RBB (5) @ WTF (2) | P30: 11:00pm est | Q30: Never Let Go | R30: NLG | S30: 14 | T30: 8 | U30: 68 | V30: 49 | W30: =U30/(U30+V30) -> 0.58119658
A31: 11:00pm est | P31: 11:00pm est | Q31: Our Lady Tuna | R31: Tuna | S31: 14 | T31: 8 | U31: 67 | V31: 54 | W31: =U31/(U31+V31) -> 0.55371901
Q32: SML08 All Stars and Kazink | R32: SML08 | S32: 12 | T32: 10 | U32: 62 | V32: 65 | W32: =U32/(U32+V32) -> 0.48818898
A33: Date | B33: 43148 | D33: 43149 | F33: 43150 | H33: 43151 | J33: 43152 | L33: 43153 | N33: 43154 | P33: Date | Q33: Lumbridge White Knights | R33: Knights | S33: 12 | T33: 10 | U33: 62 | V33: 65 | W33: =U33/(U33+V33) -> 0.48818898
A34: 8:00pm est | F34: Pork (1) @ Ninja (5) | G34: Knights (5) @ TBD (2) | H34: SR (5) @ Ninja (1) | I34: Pork @ RBB (FF W) | J34: PW (FF W) @ Pork | P34: 8:00pm est | Q34: TBD | R34: TBD | S34: 9 | T34: 13 | U34: 49 | V34: 74 | W34: =U34/(U34+V34) -> 0.39837398
A35: 8:00pm est | F35: Str8 (5) @ NLG (0) | H35: NLG (5) @ TBD (3) | J35: Str8 (FF W) @ SPU (L) | K35: Pls (2) @ RBB (5) | P35: 8:00pm est | Q35: Collateral Damage | R35: CD | S35: 8 | T35: 14 | U35: 22 | V35: 59 | W35: =U35/(U35+V35) -> 0.27160494
A36: 9:00pm est | D36: Pork (FF W) @ SPU (FF L) | E36: Tuna (4) @ Pls (5) | F36: Ninja (3) @ Knights (5) | G36: Pork (1) @ TBD (5) | H36: Ninja (0) @ RBB (5) | I36: SR (FF W) @ Pork | J36: Knights (5) @ NLG (2) | K36: PW (FF W) @ SPU (L) | P36: 9:00pm est | Q36: Paradox Warriors | R36: PW | S36: 6 | T36: 16 | U36: 8 | V36: 80 | W36: =U36/(U36+V36) -> 0.090909091
A37: 9:00pm est | F37: WTF (1) @ Str8 (5) | G37: SPU (L) @ NLG (FF W) | H37: Tuna (5) @ PW (0) | J37: Pls (5) @ Str8 (2) | K37: CD (1) @ RBB (5) | P37: 9:00pm est | Q37: Team Ninja | R37: Ninja | S37: 5 | T37: 17 | U37: 26 | V37: 86 | W37: =U37/(U37+V37) -> 0.23214286
A38: 10:00pm est | D38: Ncro (FF L) @ SML08 (FF W) | E38: CD (FF W) @ Pork | I38: WTF (5) @ TBD (1) | K38: NLG (5) @ Tuna (2) | P38: 10:00pm est | Q38: NecroBonk | R38: Ncro | S38: 3 | T38: 19 | U38: 15 | V38: 23 | W38: =U38/(U38+V38) -> 0.39473684
A39: 10:00pm est | D39: Pls (5) @ Knights (3) | F39: SPU (L) @ WTF (FF W) | P39: 10:00pm est | Q39: PORKCHOP SANDWICHES | R39: Pork | S39: 1 | T39: 21 | U39: 10 | V39: 55 | W39: =U39/(U39+V39) -> 0.15384615
A40: 11:00pm est | D40: CD (5) @ SML08 (2) | E40: Ncro @ Knights (FF W) | F40: SR (FF W) @ Ncro (L) | H40: WTF (5) @ Tuna (0) | P40: 11:00pm est | Q40: Stat Padders United | R40: SPU | S40: 0 | T40: 22 | U40: 3 | V40: 15 | W40: =U40/(U40+V40) -> 0.16666667
A41: 11:00pm est | P41: 11:00pm est | S41: =SUM(S27:S40)+S5+S15 -> 174 | T41: =SUM(T27:T40)+T5+T15 -> 178 | U41: =SUM(U27:U40)+U5+U15 -> 807 | V41: =SUM(V27:V40)+V5+V15 -> 807
...

Sheet Team and Player Stats
A1: AGLA WL19 Rosters and Regular Season Statistics
A2: Team | B2: Player | C2: Games Played | D2: Wins | E2: Minutes | F2: Goals | G2: Kills | H2: Assists | I2: Deaths | J2: Spread | K2: K/D Ratio | L2: Average Life | M2: Medals | N2: Games with Medals | O2: Minutes | P2: Carrier Kills | Q2: Beatdown | R2: Bulltrue | S2: Killjoys | T2: Double Kill | U2: Triple Kill | V2: Overkill | W2: Killtacular | X2: Killtrocity | Y2: Killmanjaro | Z2: Killpocalypse | AA2: Killtastrophe | AB2: Killionaire | AC2: Killing Spree | AD2: Killing Frenzy | AE2: Running Riot | AF2: Rampage | AG2: Extermination | AH2: Sword Spree
A3: Never Let Go | B3: AtoneMilitant (c) | C3: =SUM('Game Results'!C70+'Game Results'!C118+'Game Results'!C449+'Game Results'!C809+'Game Results'!C887+'Game Results'!C926+'Game Results'!C1020+'Game Results'!C2584+'Game Results'!C1535+'Game Results'!C2162+'Game Results'!C1763+'Game Results'!C1921+'Game Results'!C1311+'Game Results'!C2097+'Game Results'!C1484+'Game Results'!C2670+'Game Results'!C2435+'Game Results'!C3099+'Game Results'!C3153) -> 17 | D3: =SUM('Game Results'!D70+'Game Results'!D118+'Game Results'!D449+'Game Results'!D809+'Game Results'!D887+'Game Results'!D926+'Game Results'!D1020+'Game Results'!D2584+'Game Results'!D1535+'Game Results'!D2162+'Game Results'!D1763+'Game Results'!D1921+'Game Results'!D1311+'Game Results'!D2097+'Game Results'!D1484+'Game Results'!D2670+'Game Results'!D2435+'Game Results'!D3099+'Game Results'!D3153) -> 9 | E3: =SUM('Game Results'!E70+'Game Results'!E118+'Game Results'!E449+'Game Results'!E809+'Game Results'!E887+'Game Results'!E926+'Game Results'!E1020+'Game Results'!E2584+'Game Results'!E1535+'Game Results'!E2162+'Game Results'!E1763+'Game Results'!E1921+'Game Results'!E1311+'Game Results'!E2097+'Game Results'!E1484+'Game Results'!E2670+'Game Results'!E2435+'Game Results'!E3099+'Game Results'!E3153) -> 203.51667 | F3: =SUM('Game Results'!F70+'Game Results'!F118+'Game Results'!F449+'Game Results'!F809+'Game Results'!F887+'Game Results'!F926+'Game Results'!F1020+'Game Results'!F2584+'Game Results'!F1535+'Game Results'!F2162+'Game Results'!F1763+'Game Results'!F1921+'Game Results'!F1311+'Game Results'!F2097+'Game Results'!F1484+'Game Results'!F2670+'Game Results'!F2435+'Game Results'!F3099+'Game Results'!F3153) -> 10 | G3: =SUM('Game Results'!G70+'Game Results'!G118+'Game Results'!G449+'Game Results'!G809+'Game Results'!G887+'Game Results'!G926+'Game Results'!G1020+'Game Results'!G2584+'Game Results'!G1535+'Game Results'!G2162+'Game Results'!G1763+'Game Results'!G1921+'Game Results'!G1311+'Game Results'!G2097+'Game Results'!G1484+'Game Results'!G2670+'Game Results'!G2435+'Game Results'!G3099+'Game Results'!G3153) -> 853 | H3: =SUM('Game Results'!H70+'Game Results'!H118+'Game Results'!H449+'Game Results'!H809+'Game Results'!H887+'Game Results'!H926+'Game Results'!H1020+'Game Results'!H2584+'Game Results'!H1535+'Game Results'!H2162+'Game Results'!H1763+'Game Results'!H1921+'Game Results'!H1311+'Game Results'!H2097+'Game Results'!H1484+'Game Results'!H2670+'Game Results'!H2435+'Game Results'!H3099+'Game Results'!H3153) -> 2 | I3: =SUM('Game Results'!I70+'Game Results'!I118+'Game Results'!I449+'Game Results'!I809+'Game Results'!I887+'Game Results'!I926+'Game Results'!I1020+'Game Results'!I2584+'Game Results'!I1535+'Game Results'!I2162+'Game Results'!I1763+'Game Results'!I1921+'Game Results'!I1311+'Game Results'!I2097+'Game Results'!I1484+'Game Results'!I2670+'Game Results'!I2435+'Game Results'!I3099+'Game Results'!I3153) -> 908 | J3: =SUM('Game Results'!J70+'Game Results'!J118+'Game Results'!J449+'Game Results'!J809+'Game Results'!J887+'Game Results'!J926+'Game Results'!J1020+'Game Results'!J2584+'Game Results'!J1535+'Game Results'!J2162+'Game Results'!J1763+'Game Results'!J1921+'Game Results'!J1311+'Game Results'!J2097+'Game Results'!J1484+'Game Results'!J2670+'Game Results'!J2435+'Game Results'!J3099+'Game Results'!J3153) -> -55 | K3: =SUM(G3/I3) -> 0.93942731 | L3: =SUM(E3*60)/I3 -> 13.448238 | M3: =SUM('Game Results'!M70+'Game Results'!M118+'Game Results'!M449+'Game Results'!M809+'Game Results'!M887+'Game Results'!M926+'Game Results'!M1020+'Game Results'!M2584+'Game Results'!M1535+'Game Results'!M2162+'Game Results'!M1763+'Game Results'!M1921+'Game Results'!M1311+'Game Results'!M2097+'Game Results'!M1484+'Game Results'!M2670+'Game Results'!M2435+'Game Results'!M3099+'Game Results'!M3153) -> 1029 | N3: =SUM('Game Results'!N70+'Game Results'!N118+'Game Results'!N449+'Game Results'!N809+'Game Results'!N887+'Game Results'!N926+'Game Results'!N1020+'Game Results'!N2584+'Game Results'!N1535+'Game Results'!N2162+'Game Results'!N1763+'Game Results'!N1921+'Game Results'!N1311+'Game Results'!N2097+'Game Results'!N1484+'Game Results'!N2670+'Game Results'!N2435+'Game Results'!N3099+'Game Results'!N3153) -> 17 | O3: =SUM('Game Results'!O70+'Game Results'!O118+'Game Results'!O449+'Game Results'!O809+'Game Results'!O887+'Game Results'!O926+'Game Results'!O1020+'Game Results'!O2584+'Game Results'!O1535+'Game Results'!O2162+'Game Results'!O1763+'Game Results'!O1921+'Game Results'!O1311+'Game Results'!O2097+'Game Results'!O1484+'Game Results'!O2670+'Game Results'!O2435+'Game Results'!O3099+'Game Results'!O3153) -> 196.08333 | P3: =SUM('Game Results'!P70+'Game Results'!P118+'Game Results'!P449+'Game Results'!P809+'Game Results'!P887+'Game Results'!P926+'Game Results'!P1020+'Game Results'!P2584+'Game Results'!P1535+'Game Results'!P2162+'Game Results'!P1763+'Game Results'!P1921+'Game Results'!P1311+'Game Results'!P2097+'Game Results'!P1484+'Game Results'!P2670+'Game Results'!P2435+'Game Results'!P3099+'Game Results'!P3153) -> 30 | Q3: =SUM('Game Results'!Q70+'Game Results'!Q118+'Game Results'!Q449+'Game Results'!Q809+'Game Results'!Q887+'Game Results'!Q926+'Game Results'!Q1020+'Game Results'!Q2584+'Game Results'!Q1535+'Game Results'!Q2162+'Game Results'!Q1763+'Game Results'!Q1921+'Game Results'!Q1311+'Game Results'!Q2097+'Game Results'!Q1484+'Game Results'!Q2670+'Game Results'!Q2435+'Game Results'!Q3099+'Game Results'!Q3153) -> 14 | R3: =SUM('Game Results'!R70+'Game Results'!R118+'Game Results'!R449+'Game Results'!R809+'Game Results'!R887+'Game Results'!R926+'Game Results'!R1020+'Game Results'!R2584+'Game Results'!R1535+'Game Results'!R2162+'Game Results'!R1763+'Game Results'!R1921+'Game Results'!R1311+'Game Results'!R2097+'Game Results'!R1484+'Game Results'!R2670+'Game Results'!R2435+'Game Results'!R3099+'Game Results'!R3153) -> 63 | S3: =SUM('Game Results'!S70+'Game Results'!S118+'Game Results'!S449+'Game Results'!S809+'Game Results'!S887+'Game Results'!S926+'Game Results'!S1020+'Game Results'!S2584+'Game Results'!S1535+'Game Results'!S2162+'Game Results'!S1763+'Game Results'!S1921+'Game Results'!S1311+'Game Results'!S2097+'Game Results'!S1484+'Game Results'!S2670+'Game Results'!S2435+'Game Results'!S3099+'Game Results'!S3153) -> 19 | T3: =SUM('Game Results'!T70+'Game Results'!T118+'Game Results'!T449+'Game Results'!T809+'Game Results'!T887+'Game Results'!T926+'Game Results'!T1020+'Game Results'!T2584+'Game Results'!T1535+'Game Results'!T2162+'Game Results'!T1763+'Game Results'!T1921+'Game Results'!T1311+'Game Results'!T2097+'Game Results'!T1484+'Game Results'!T2670+'Game Results'!T2435+'Game Results'!T3099+'Game Results'!T3153) -> 114 | ... AH3: =SUM('Game Results'!AH70+'Game Results'!AH118+'Game Results'!AH449+'Game Results'!AH809+'Game Results'!AH887+'Game Results'!AH926+'Game Results'!AH1020+'Game Results'!AH2584+'Game Results'!AH1535+'Game Results'!AH2162+'Game Results'!AH1763+'Game Results'!AH1921+'Game Results'!AH1311+'Game Results'!AH2097+'Game Results'!AH1484+'Game Results'!AH2670+'Game Results'!AH2435+'Game Results'!AH3099+'Game Results'!AH3153) -> 0
A4: Never Let Go | B4: Melvishdon | C4: =SUM('Game Results'!C71+'Game Results'!C119+'Game Results'!C450+'Game Results'!C810+'Game Results'!C888+'Game Results'!C927+'Game Results'!C1021+'Game Results'!C2585+'Game Results'!C1536+'Game Results'!C2163+'Game Results'!C1764+'Game Results'!C1922+'Game Results'!C1312+'Game Results'!C2098+'Game Results'!C1485+'Game Results'!C2671+'Game Results'!C2436+'Game Results'!C3100+'Game Results'!C3154) -> 12 | D4: =SUM('Game Results'!D71+'Game Results'!D119+'Game Results'!D450+'Game Results'!D810+'Game Results'!D888+'Game Results'!D927+'Game Results'!D1021+'Game Results'!D2585+'Game Results'!D1536+'Game Results'!D2163+'Game Results'!D1764+'Game Results'!D1922+'Game Results'!D1312+'Game Results'!D2098+'Game Results'!D1485+'Game Results'!D2671+'Game Results'!D2436+'Game Results'!D3100+'Game Results'!D3154) -> 8 | E4: =SUM('Game Results'!E71+'Game Results'!E119+'Game Results'!E450+'Game Results'!E810+'Game Results'!E888+'Game Results'!E927+'Game Results'!E1021+'Game Results'!E2585+'Game Results'!E1536+'Game Results'!E2163+'Game Results'!E1764+'Game Results'!E1922+'Game Results'!E1312+'Game Results'!E2098+'Game Results'!E1485+'Game Results'!E2671+'Game Results'!E2436+'Game Results'!E3100+'Game Results'!E3154) -> 121.83333 | F4: =SUM('Game Results'!F71+'Game Results'!F119+'Game Results'!F450+'Game Results'!F810+'Game Results'!F888+'Game Results'!F927+'Game Results'!F1021+'Game Results'!F2585+'Game Results'!F1536+'Game Results'!F2163+'Game Results'!F1764+'Game Results'!F1922+'Game Results'!F1312+'Game Results'!F2098+'Game Results'!F1485+'Game Results'!F2671+'Game Results'!F2436+'Game Results'!F3100+'Game Results'!F3154) -> 12 | G4: =SUM('Game Results'!G71+'Game Results'!G119+'Game Results'!G450+'Game Results'!G810+'Game Results'!G888+'Game Results'!G927+'Game Results'!G1021+'Game Results'!G2585+'Game Results'!G1536+'Game Results'!G2163+'Game Results'!G1764+'Game Results'!G1922+'Game Results'!G1312+'Game Results'!G2098+'Game Results'!G1485+'Game Results'!G2671+'Game Results'!G2436+'Game Results'!G3100+'Game Results'!G3154) -> 469 | H4: =SUM('Game Results'!H71+'Game Results'!H119+'Game Results'!H450+'Game Results'!H810+'Game Results'!H888+'Game Results'!H927+'Game Results'!H1021+'Game Results'!H2585+'Game Results'!H1536+'Game Results'!H2163+'Game Results'!H1764+'Game Results'!H1922+'Game Results'!H1312+'Game Results'!H2098+'Game Results'!H1485+'Game Results'!H2671+'Game Results'!H2436+'Game Results'!H3100+'Game Results'!H3154) -> 2 | I4: =SUM('Game Results'!I71+'Game Results'!I119+'Game Results'!I450+'Game Results'!I810+'Game Results'!I888+'Game Results'!I927+'Game Results'!I1021+'Game Results'!I2585+'Game Results'!I1536+'Game Results'!I2163+'Game Results'!I1764+'Game Results'!I1922+'Game Results'!I1312+'Game Results'!I2098+'Game Results'!I1485+'Game Results'!I2671+'Game Results'!I2436+'Game Results'!I3100+'Game Results'!I3154) -> 551 | J4: =SUM('Game Results'!J71+'Game Results'!J119+'Game Results'!J450+'Game Results'!J810+'Game Results'!J888+'Game Results'!J927+'Game Results'!J1021+'Game Results'!J2585+'Game Results'!J1536+'Game Results'!J2163+'Game Results'!J1764+'Game Results'!J1922+'Game Results'!J1312+'Game Results'!J2098+'Game Results'!J1485+'Game Results'!J2671+'Game Results'!J2436+'Game Results'!J3100+'Game Results'!J3154) -> -82 | K4: =SUM(G4/I4) -> 0.85117967 | L4: =SUM(E4*60)/I4 -> 13.266788 | M4: =SUM('Game Results'!M71+'Game Results'!M119+'Game Results'!M450+'Game Results'!M810+'Game Results'!M888+'Game Results'!M927+'Game Results'!M1021+'Game Results'!M2585+'Game Results'!M1536+'Game Results'!M2163+'Game Results'!M1764+'Game Results'!M1922+'Game Results'!M1312+'Game Results'!M2098+'Game Results'!M1485+'Game Results'!M2671+'Game Results'!M2436+'Game Results'!M3100+'Game Results'!M3154) -> 641 | N4: =SUM('Game Results'!N71+'Game Results'!N119+'Game Results'!N450+'Game Results'!N810+'Game Results'!N888+'Game Results'!N927+'Game Results'!N1021+'Game Results'!N2585+'Game Results'!N1536+'Game Results'!N2163+'Game Results'!N1764+'Game Results'!N1922+'Game Results'!N1312+'Game Results'!N2098+'Game Results'!N1485+'Game Results'!N2671+'Game Results'!N2436+'Game Results'!N3100+'Game Results'!N3154) -> 12 | O4: =SUM('Game Results'!O71+'Game Results'!O119+'Game Results'!O450+'Game Results'!O810+'Game Results'!O888+'Game Results'!O927+'Game Results'!O1021+'Game Results'!O2585+'Game Results'!O1536+'Game Results'!O2163+'Game Results'!O1764+'Game Results'!O1922+'Game Results'!O1312+'Game Results'!O2098+'Game Results'!O1485+'Game Results'!O2671+'Game Results'!O2436+'Game Results'!O3100+'Game Results'!O3154) -> 121.83333 | P4: =SUM('Game Results'!P71+'Game Results'!P119+'Game Results'!P450+'Game Results'!P810+'Game Results'!P888+'Game Results'!P927+'Game Results'!P1021+'Game Results'!P2585+'Game Results'!P1536+'Game Results'!P2163+'Game Results'!P1764+'Game Results'!P1922+'Game Results'!P1312+'Game Results'!P2098+'Game Results'!P1485+'Game Results'!P2671+'Game Results'!P2436+'Game Results'!P3100+'Game Results'!P3154) -> 24 | Q4: =SUM('Game Results'!Q71+'Game Results'!Q119+'Game Results'!Q450+'Game Results'!Q810+'Game Results'!Q888+'Game Results'!Q927+'Game Results'!Q1021+'Game Results'!Q2585+'Game Results'!Q1536+'Game Results'!Q2163+'Game Results'!Q1764+'Game Results'!Q1922+'Game Results'!Q1312+'Game Results'!Q2098+'Game Results'!Q1485+'Game Results'!Q2671+'Game Results'!Q2436+'Game Results'!Q3100+'Game Results'!Q3154) -> 12 | R4: =SUM('Game Results'!R71+'Game Results'!R119+'Game Results'!R450+'Game Results'!R810+'Game Results'!R888+'Game Results'!R927+'Game Results'!R1021+'Game Results'!R2585+'Game Results'!R1536+'Game Results'!R2163+'Game Results'!R1764+'Game Results'!R1922+'Game Results'!R1312+'Game Results'!R2098+'Game Results'!R1485+'Game Results'!R2671+'Game Results'!R2436+'Game Results'!R3100+'Game Results'!R3154) -> 27 | S4: =SUM('Game Results'!S71+'Game Results'!S119+'Game Results'!S450+'Game Results'!S810+'Game Results'!S888+'Game Results'!S927+'Game Results'!S1021+'Game Results'!S2585+'Game Results'!S1536+'Game Results'!S2163+'Game Results'!S1764+'Game Results'!S1922+'Game Results'!S1312+'Game Results'!S2098+'Game Results'!S1485+'Game Results'!S2671+'Game Results'!S2436+'Game Results'!S3100+'Game Results'!S3154) -> 7 | T4: =SUM('Game Results'!T71+'Game Results'!T119+'Game Results'!T450+'Game Results'!T810+'Game Results'!T888+'Game Results'!T927+'Game Results'!T1021+'Game Results'!T2585+'Game Results'!T1536+'Game Results'!T2163+'Game Results'!T1764+'Game Results'!T1922+'Game Results'!T1312+'Game Results'!T2098+'Game Results'!T1485+'Game Results'!T2671+'Game Results'!T2436+'Game Results'!T3100+'Game Results'!T3154) -> 80 | ... AH4: =SUM('Game Results'!AH71+'Game Results'!AH119+'Game Results'!AH450+'Game Results'!AH810+'Game Results'!AH888+'Game Results'!AH927+'Game Results'!AH1021+'Game Results'!AH2585+'Game Results'!AH1536+'Game Results'!AH2163+'Game Results'!AH1764+'Game Results'!AH1922+'Game Results'!AH1312+'Game Results'!AH2098+'Game Results'!AH1485+'Game Results'!AH2671+'Game Results'!AH2436+'Game Results'!AH3100+'Game Results'!AH3154) -> 0
A5: Never Let Go | B5: Blootzy | C5: =SUM('Game Results'!C72+'Game Results'!C120+'Game Results'!C451+'Game Results'!C811+'Game Results'!C889+'Game Results'!C928+'Game Results'!C1022+'Game Results'!C2586+'Game Results'!C1537+'Game Results'!C2164+'Game Results'!C1765+'Game Results'!C1923+'Game Results'!C1313+'Game Results'!C2099+'Game Results'!C1486+'Game Results'!C2672+'Game Results'!C2437+'Game Results'!C3101+'Game Results'!C3155) -> 18 | D5: =SUM('Game Results'!D72+'Game Results'!D120+'Game Results'!D451+'Game Results'!D811+'Game Results'!D889+'Game Results'!D928+'Game Results'!D1022+'Game Results'!D2586+'Game Results'!D1537+'Game Results'!D2164+'Game Results'!D1765+'Game Results'!D1923+'Game Results'!D1313+'Game Results'!D2099+'Game Results'!D1486+'Game Results'!D2672+'Game Results'!D2437+'Game Results'!D3101+'Game Results'!D3155) -> 9 | E5: =SUM('Game Results'!E72+'Game Results'!E120+'Game Results'!E451+'Game Results'!E811+'Game Results'!E889+'Game Results'!E928+'Game Results'!E1022+'Game Results'!E2586+'Game Results'!E1537+'Game Results'!E2164+'Game Results'!E1765+'Game Results'!E1923+'Game Results'!E1313+'Game Results'!E2099+'Game Results'!E1486+'Game Results'!E2672+'Game Results'!E2437+'Game Results'!E3101+'Game Results'!E3155) -> 216.13333 | F5: =SUM('Game Results'!F72+'Game Results'!F120+'Game Results'!F451+'Game Results'!F811+'Game Results'!F889+'Game Results'!F928+'Game Results'!F1022+'Game Results'!F2586+'Game Results'!F1537+'Game Results'!F2164+'Game Results'!F1765+'Game Results'!F1923+'Game Results'!F1313+'Game Results'!F2099+'Game Results'!F1486+'Game Results'!F2672+'Game Results'!F2437+'Game Results'!F3101+'Game Results'!F3155) -> 9 | G5: =SUM('Game Results'!G72+'Game Results'!G120+'Game Results'!G451+'Game Results'!G811+'Game Results'!G889+'Game Results'!G928+'Game Results'!G1022+'Game Results'!G2586+'Game Results'!G1537+'Game Results'!G2164+'Game Results'!G1765+'Game Results'!G1923+'Game Results'!G1313+'Game Results'!G2099+'Game Results'!G1486+'Game Results'!G2672+'Game Results'!G2437+'Game Results'!G3101+'Game Results'!G3155) -> 1147 | H5: =SUM('Game Results'!H72+'Game Results'!H120+'Game Results'!H451+'Game Results'!H811+'Game Results'!H889+'Game Results'!H928+'Game Results'!H1022+'Game Results'!H2586+'Game Results'!H1537+'Game Results'!H2164+'Game Results'!H1765+'Game Results'!H1923+'Game Results'!H1313+'Game Results'!H2099+'Game Results'!H1486+'Game Results'!H2672+'Game Results'!H2437+'Game Results'!H3101+'Game Results'!H3155) -> 8 | I5: =SUM('Game Results'!I72+'Game Results'!I120+'Game Results'!I451+'Game Results'!I811+'Game Results'!I889+'Game Results'!I928+'Game Results'!I1022+'Game Results'!I2586+'Game Results'!I1537+'Game Results'!I2164+'Game Results'!I1765+'Game Results'!I1923+'Game Results'!I1313+'Game Results'!I2099+'Game Results'!I1486+'Game Results'!I2672+'Game Results'!I2437+'Game Results'!I3101+'Game Results'!I3155) -> 997 | J5: =SUM('Game Results'!J72+'Game Results'!J120+'Game Results'!J451+'Game Results'!J811+'Game Results'!J889+'Game Results'!J928+'Game Results'!J1022+'Game Results'!J2586+'Game Results'!J1537+'Game Results'!J2164+'Game Results'!J1765+'Game Results'!J1923+'Game Results'!J1313+'Game Results'!J2099+'Game Results'!J1486+'Game Results'!J2672+'Game Results'!J2437+'Game Results'!J3101+'Game Results'!J3155) -> 150 | K5: =SUM(G5/I5) -> 1.1504514 | L5: =SUM(E5*60)/I5 -> 13.007021 | M5: =SUM('Game Results'!M72+'Game Results'!M120+'Game Results'!M451+'Game Results'!M811+'Game Results'!M889+'Game Results'!M928+'Game Results'!M1022+'Game Results'!M2586+'Game Results'!M1537+'Game Results'!M2164+'Game Results'!M1765+'Game Results'!M1923+'Game Results'!M1313+'Game Results'!M2099+'Game Results'!M1486+'Game Results'!M2672+'Game Results'!M2437+'Game Results'!M3101+'Game Results'!M3155) -> 1470 | N5: =SUM('Game Results'!N72+'Game Results'!N120+'Game Results'!N451+'Game Results'!N811+'Game Results'!N889+'Game Results'!N928+'Game Results'!N1022+'Game Results'!N2586+'Game Results'!N1537+'Game Results'!N2164+'Game Results'!N1765+'Game Results'!N1923+'Game Results'!N1313+'Game Results'!N2099+'Game Results'!N1486+'Game Results'!N2672+'Game Results'!N2437+'Game Results'!N3101+'Game Results'!N3155) -> 17 | O5: =SUM('Game Results'!O72+'Game Results'!O120+'Game Results'!O451+'Game Results'!O811+'Game Results'!O889+'Game Results'!O928+'Game Results'!O1022+'Game Results'!O2586+'Game Results'!O1537+'Game Results'!O2164+'Game Results'!O1765+'Game Results'!O1923+'Game Results'!O1313+'Game Results'!O2099+'Game Results'!O1486+'Game Results'!O2672+'Game Results'!O2437+'Game Results'!O3101+'Game Results'!O3155) -> 210.43333 | P5: =SUM('Game Results'!P72+'Game Results'!P120+'Game Results'!P451+'Game Results'!P811+'Game Results'!P889+'Game Results'!P928+'Game Results'!P1022+'Game Results'!P2586+'Game Results'!P1537+'Game Results'!P2164+'Game Results'!P1765+'Game Results'!P1923+'Game Results'!P1313+'Game Results'!P2099+'Game Results'!P1486+'Game Results'!P2672+'Game Results'!P2437+'Game Results'!P3101+'Game Results'!P3155) -> 34 | Q5: =SUM('Game Results'!Q72+'Game Results'!Q120+'Game Results'!Q451+'Game Results'!Q811+'Game Results'!Q889+'Game Results'!Q928+'Game Results'!Q1022+'Game Results'!Q2586+'Game Results'!Q1537+'Game Results'!Q2164+'Game Results'!Q1765+'Game Results'!Q1923+'Game Results'!Q1313+'Game Results'!Q2099+'Game Results'!Q1486+'Game Results'!Q2672+'Game Results'!Q2437+'Game Results'!Q3101+'Game Results'!Q3155) -> 23 | R5: =SUM('Game Results'!R72+'Game Results'!R120+'Game Results'!R451+'Game Results'!R811+'Game Results'!R889+'Game Results'!R928+'Game Results'!R1022+'Game Results'!R2586+'Game Results'!R1537+'Game Results'!R2164+'Game Results'!R1765+'Game Results'!R1923+'Game Results'!R1313+'Game Results'!R2099+'Game Results'!R1486+'Game Results'!R2672+'Game Results'!R2437+'Game Results'!R3101+'Game Results'!R3155) -> 66 | S5: =SUM('Game Results'!S72+'Game Results'!S120+'Game Results'!S451+'Game Results'!S811+'Game Results'!S889+'Game Results'!S928+'Game Results'!S1022+'Game Results'!S2586+'Game Results'!S1537+'Game Results'!S2164+'Game Results'!S1765+'Game Results'!S1923+'Game Results'!S1313+'Game Results'!S2099+'Game Results'!S1486+'Game Results'!S2672+'Game Results'!S2437+'Game Results'!S3101+'Game Results'!S3155) -> 18 | T5: =SUM('Game Results'!T72+'Game Results'!T120+'Game Results'!T451+'Game Results'!T811+'Game Results'!T889+'Game Results'!T928+'Game Results'!T1022+'Game Results'!T2586+'Game Results'!T1537+'Game Results'!T2164+'Game Results'!T1765+'Game Results'!T1923+'Game Results'!T1313+'Game Results'!T2099+'Game Results'!T1486+'Game Results'!T2672+'Game Results'!T2437+'Game Results'!T3101+'Game Results'!T3155) -> 164 | ... AH5: =SUM('Game Results'!AH72+'Game Results'!AH120+'Game Results'!AH451+'Game Results'!AH811+'Game Results'!AH889+'Game Results'!AH928+'Game Results'!AH1022+'Game Results'!AH2586+'Game Results'!AH1537+'Game Results'!AH2164+'Game Results'!AH1765+'Game Results'!AH1923+'Game Results'!AH1313+'Game Results'!AH2099+'Game Results'!AH1486+'Game Results'!AH2672+'Game Results'!AH2437+'Game Results'!AH3101+'Game Results'!AH3155) -> 0
A6: Never Let Go | B6: TITAN MAN23 | C6: =SUM('Game Results'!C73+'Game Results'!C121+'Game Results'!C452+'Game Results'!C812+'Game Results'!C890+'Game Results'!C929+'Game Results'!C1023+'Game Results'!C2587+'Game Results'!C1538+'Game Results'!C2165+'Game Results'!C1766+'Game Results'!C1924+'Game Results'!C1314+'Game Results'!C2100+'Game Results'!C1487+'Game Results'!C2673+'Game Results'!C2438+'Game Results'!C3102+'Game Results'!C3156) -> 10 | D6: =SUM('Game Results'!D73+'Game Results'!D121+'Game Results'!D452+'Game Results'!D812+'Game Results'!D890+'Game Results'!D929+'Game Results'!D1023+'Game Results'!D2587+'Game Results'!D1538+'Game Results'!D2165+'Game Results'!D1766+'Game Results'!D1924+'Game Results'!D1314+'Game Results'!D2100+'Game Results'!D1487+'Game Results'!D2673+'Game Results'!D2438+'Game Results'!D3102+'Game Results'!D3156) -> 7 | E6: =SUM('Game Results'!E73+'Game Results'!E121+'Game Results'!E452+'Game Results'!E812+'Game Results'!E890+'Game Results'!E929+'Game Results'!E1023+'Game Results'!E2587+'Game Results'!E1538+'Game Results'!E2165+'Game Results'!E1766+'Game Results'!E1924+'Game Results'!E1314+'Game Results'!E2100+'Game Results'!E1487+'Game Results'!E2673+'Game Results'!E2438+'Game Results'!E3102+'Game Results'!E3156) -> 141.75 | F6: =SUM('Game Results'!F73+'Game Results'!F121+'Game Results'!F452+'Game Results'!F812+'Game Results'!F890+'Game Results'!F929+'Game Results'!F1023+'Game Results'!F2587+'Game Results'!F1538+'Game Results'!F2165+'Game Results'!F1766+'Game Results'!F1924+'Game Results'!F1314+'Game Results'!F2100+'Game Results'!F1487+'Game Results'!F2673+'Game Results'!F2438+'Game Results'!F3102+'Game Results'!F3156) -> 29 | G6: =SUM('Game Results'!G73+'Game Results'!G121+'Game Results'!G452+'Game Results'!G812+'Game Results'!G890+'Game Results'!G929+'Game Results'!G1023+'Game Results'!G2587+'Game Results'!G1538+'Game Results'!G2165+'Game Results'!G1766+'Game Results'!G1924+'Game Results'!G1314+'Game Results'!G2100+'Game Results'!G1487+'Game Results'!G2673+'Game Results'!G2438+'Game Results'!G3102+'Game Results'!G3156) -> 355 | H6: =SUM('Game Results'!H73+'Game Results'!H121+'Game Results'!H452+'Game Results'!H812+'Game Results'!H890+'Game Results'!H929+'Game Results'!H1023+'Game Results'!H2587+'Game Results'!H1538+'Game Results'!H2165+'Game Results'!H1766+'Game Results'!H1924+'Game Results'!H1314+'Game Results'!H2100+'Game Results'!H1487+'Game Results'!H2673+'Game Results'!H2438+'Game Results'!H3102+'Game Results'!H3156) -> 2 | I6: =SUM('Game Results'!I73+'Game Results'!I121+'Game Results'!I452+'Game Results'!I812+'Game Results'!I890+'Game Results'!I929+'Game Results'!I1023+'Game Results'!I2587+'Game Results'!I1538+'Game Results'!I2165+'Game Results'!I1766+'Game Results'!I1924+'Game Results'!I1314+'Game Results'!I2100+'Game Results'!I1487+'Game Results'!I2673+'Game Results'!I2438+'Game Results'!I3102+'Game Results'!I3156) -> 541 | J6: =SUM('Game Results'!J73+'Game Results'!J121+'Game Results'!J452+'Game Results'!J812+'Game Results'!J890+'Game Results'!J929+'Game Results'!J1023+'Game Results'!J2587+'Game Results'!J1538+'Game Results'!J2165+'Game Results'!J1766+'Game Results'!J1924+'Game Results'!J1314+'Game Results'!J2100+'Game Results'!J1487+'Game Results'!J2673+'Game Results'!J2438+'Game Results'!J3102+'Game Results'!J3156) -> -186 | K6: =SUM(G6/I6) -> 0.65619224 | L6: =SUM(E6*60)/I6 -> 15.720887 | M6: =SUM('Game Results'!M73+'Game Results'!M121+'Game Results'!M452+'Game Results'!M812+'Game Results'!M890+'Game Results'!M929+'Game Results'!M1023+'Game Results'!M2587+'Game Results'!M1538+'Game Results'!M2165+'Game Results'!M1766+'Game Results'!M1924+'Game Results'!M1314+'Game Results'!M2100+'Game Results'!M1487+'Game Results'!M2673+'Game Results'!M2438+'Game Results'!M3102+'Game Results'!M3156) -> 413 | N6: =SUM('Game Results'!N73+'Game Results'!N121+'Game Results'!N452+'Game Results'!N812+'Game Results'!N890+'Game Results'!N929+'Game Results'!N1023+'Game Results'!N2587+'Game Results'!N1538+'Game Results'!N2165+'Game Results'!N1766+'Game Results'!N1924+'Game Results'!N1314+'Game Results'!N2100+'Game Results'!N1487+'Game Results'!N2673+'Game Results'!N2438+'Game Results'!N3102+'Game Results'!N3156) -> 10 | O6: =SUM('Game Results'!O73+'Game Results'!O121+'Game Results'!O452+'Game Results'!O812+'Game Results'!O890+'Game Results'!O929+'Game Results'!O1023+'Game Results'!O2587+'Game Results'!O1538+'Game Results'!O2165+'Game Results'!O1766+'Game Results'!O1924+'Game Results'!O1314+'Game Results'!O2100+'Game Results'!O1487+'Game Results'!O2673+'Game Results'!O2438+'Game Results'!O3102+'Game Results'!O3156) -> 138.58333 | P6: =SUM('Game Results'!P73+'Game Results'!P121+'Game Results'!P452+'Game Results'!P812+'Game Results'!P890+'Game Results'!P929+'Game Results'!P1023+'Game Results'!P2587+'Game Results'!P1538+'Game Results'!P2165+'Game Results'!P1766+'Game Results'!P1924+'Game Results'!P1314+'Game Results'!P2100+'Game Results'!P1487+'Game Results'!P2673+'Game Results'!P2438+'Game Results'!P3102+'Game Results'!P3156) -> 31 | Q6: =SUM('Game Results'!Q73+'Game Results'!Q121+'Game Results'!Q452+'Game Results'!Q812+'Game Results'!Q890+'Game Results'!Q929+'Game Results'!Q1023+'Game Results'!Q2587+'Game Results'!Q1538+'Game Results'!Q2165+'Game Results'!Q1766+'Game Results'!Q1924+'Game Results'!Q1314+'Game Results'!Q2100+'Game Results'!Q1487+'Game Results'!Q2673+'Game Results'!Q2438+'Game Results'!Q3102+'Game Results'!Q3156) -> 7 | R6: =SUM('Game Results'!R73+'Game Results'!R121+'Game Results'!R452+'Game Results'!R812+'Game Results'!R890+'Game Results'!R929+'Game Results'!R1023+'Game Results'!R2587+'Game Results'!R1538+'Game Results'!R2165+'Game Results'!R1766+'Game Results'!R1924+'Game Results'!R1314+'Game Results'!R2100+'Game Results'!R1487+'Game Results'!R2673+'Game Results'!R2438+'Game Results'!R3102+'Game Results'!R3156) -> 5 | S6: =SUM('Game Results'!S73+'Game Results'!S121+'Game Results'!S452+'Game Results'!S812+'Game Results'!S890+'Game Results'!S929+'Game Results'!S1023+'Game Results'!S2587+'Game Results'!S1538+'Game Results'!S2165+'Game Results'!S1766+'Game Results'!S1924+'Game Results'!S1314+'Game Results'!S2100+'Game Results'!S1487+'Game Results'!S2673+'Game Results'!S2438+'Game Results'!S3102+'Game Results'!S3156) -> 8 | T6: =SUM('Game Results'!T73+'Game Results'!T121+'Game Results'!T452+'Game Results'!T812+'Game Results'!T890+'Game Results'!T929+'Game Results'!T1023+'Game Results'!T2587+'Game Results'!T1538+'Game Results'!T2165+'Game Results'!T1766+'Game Results'!T1924+'Game Results'!T1314+'Game Results'!T2100+'Game Results'!T1487+'Game Results'!T2673+'Game Results'!T2438+'Game Results'!T3102+'Game Results'!T3156) -> 30 | ... AH6: =SUM('Game Results'!AH73+'Game Results'!AH121+'Game Results'!AH452+'Game Results'!AH812+'Game Results'!AH890+'Game Results'!AH929+'Game Results'!AH1023+'Game Results'!AH2587+'Game Results'!AH1538+'Game Results'!AH2165+'Game Results'!AH1766+'Game Results'!AH1924+'Game Results'!AH1314+'Game Results'!AH2100+'Game Results'!AH1487+'Game Results'!AH2673+'Game Results'!AH2438+'Game Results'!AH3102+'Game Results'!AH3156) -> 0
A7: Never Let Go | B7: Mystical Novice | C7: =SUM('Game Results'!C74+'Game Results'!C122+'Game Results'!C453+'Game Results'!C813+'Game Results'!C891+'Game Results'!C930+'Game Results'!C1024+'Game Results'!C2588+'Game Results'!C1539+'Game Results'!C2166+'Game Results'!C1767+'Game Results'!C1925+'Game Results'!C1315+'Game Results'!C2101+'Game Results'!C1488+'Game Results'!C2674+'Game Results'!C2439+'Game Results'!C3103+'Game Results'!C3157) -> 2 | D7: =SUM('Game Results'!D74+'Game Results'!D122+'Game Results'!D453+'Game Results'!D813+'Game Results'!D891+'Game Results'!D930+'Game Results'!D1024+'Game Results'!D2588+'Game Results'!D1539+'Game Results'!D2166+'Game Results'!D1767+'Game Results'!D1925+'Game Results'!D1315+'Game Results'!D2101+'Game Results'!D1488+'Game Results'!D2674+'Game Results'!D2439+'Game Results'!D3103+'Game Results'!D3157) -> 1 | E7: =SUM('Game Results'!E74+'Game Results'!E122+'Game Results'!E453+'Game Results'!E813+'Game Results'!E891+'Game Results'!E930+'Game Results'!E1024+'Game Results'!E2588+'Game Results'!E1539+'Game Results'!E2166+'Game Results'!E1767+'Game Results'!E1925+'Game Results'!E1315+'Game Results'!E2101+'Game Results'!E1488+'Game Results'!E2674+'Game Results'!E2439+'Game Results'!E3103+'Game Results'!E3157) -> 18.533333 | F7: =SUM('Game Results'!F74+'Game Results'!F122+'Game Results'!F453+'Game Results'!F813+'Game Results'!F891+'Game Results'!F930+'Game Results'!F1024+'Game Results'!F2588+'Game Results'!F1539+'Game Results'!F2166+'Game Results'!F1767+'Game Results'!F1925+'Game Results'!F1315+'Game Results'!F2101+'Game Results'!F1488+'Game Results'!F2674+'Game Results'!F2439+'Game Results'!F3103+'Game Results'!F3157) -> 1 | G7: =SUM('Game Results'!G74+'Game Results'!G122+'Game Results'!G453+'Game Results'!G813+'Game Results'!G891+'Game Results'!G930+'Game Results'!G1024+'Game Results'!G2588+'Game Results'!G1539+'Game Results'!G2166+'Game Results'!G1767+'Game Results'!G1925+'Game Results'!G1315+'Game Results'!G2101+'Game Results'!G1488+'Game Results'!G2674+'Game Results'!G2439+'Game Results'!G3103+'Game Results'!G3157) -> 73 | H7: =SUM('Game Results'!H74+'Game Results'!H122+'Game Results'!H453+'Game Results'!H813+'Game Results'!H891+'Game Results'!H930+'Game Results'!H1024+'Game Results'!H2588+'Game Results'!H1539+'Game Results'!H2166+'Game Results'!H1767+'Game Results'!H1925+'Game Results'!H1315+'Game Results'!H2101+'Game Results'!H1488+'Game Results'!H2674+'Game Results'!H2439+'Game Results'!H3103+'Game Results'!H3157) -> 2 | I7: =SUM('Game Results'!I74+'Game Results'!I122+'Game Results'!I453+'Game Results'!I813+'Game Results'!I891+'Game Results'!I930+'Game Results'!I1024+'Game Results'!I2588+'Game Results'!I1539+'Game Results'!I2166+'Game Results'!I1767+'Game Results'!I1925+'Game Results'!I1315+'Game Results'!I2101+'Game Results'!I1488+'Game Results'!I2674+'Game Results'!I2439+'Game Results'!I3103+'Game Results'!I3157) -> 83 | J7: =SUM('Game Results'!J74+'Game Results'!J122+'Game Results'!J453+'Game Results'!J813+'Game Results'!J891+'Game Results'!J930+'Game Results'!J1024+'Game Results'!J2588+'Game Results'!J1539+'Game Results'!J2166+'Game Results'!J1767+'Game Results'!J1925+'Game Results'!J1315+'Game Results'!J2101+'Game Results'!J1488+'Game Results'!J2674+'Game Results'!J2439+'Game Results'!J3103+'Game Results'!J3157) -> -10 | K7: =SUM(G7/I7) -> 0.87951807 | L7: =SUM(E7*60)/I7 -> 13.39759 | M7: =SUM('Game Results'!M74+'Game Results'!M122+'Game Results'!M453+'Game Results'!M813+'Game Results'!M891+'Game Results'!M930+'Game Results'!M1024+'Game Results'!M2588+'Game Results'!M1539+'Game Results'!M2166+'Game Results'!M1767+'Game Results'!M1925+'Game Results'!M1315+'Game Results'!M2101+'Game Results'!M1488+'Game Results'!M2674+'Game Results'!M2439+'Game Results'!M3103+'Game Results'!M3157) -> 91 | N7: =SUM('Game Results'!N74+'Game Results'!N122+'Game Results'!N453+'Game Results'!N813+'Game Results'!N891+'Game Results'!N930+'Game Results'!N1024+'Game Results'!N2588+'Game Results'!N1539+'Game Results'!N2166+'Game Results'!N1767+'Game Results'!N1925+'Game Results'!N1315+'Game Results'!N2101+'Game Results'!N1488+'Game Results'!N2674+'Game Results'!N2439+'Game Results'!N3103+'Game Results'!N3157) -> 2 | O7: =SUM('Game Results'!O74+'Game Results'!O122+'Game Results'!O453+'Game Results'!O813+'Game Results'!O891+'Game Results'!O930+'Game Results'!O1024+'Game Results'!O2588+'Game Results'!O1539+'Game Results'!O2166+'Game Results'!O1767+'Game Results'!O1925+'Game Results'!O1315+'Game Results'!O2101+'Game Results'!O1488+'Game Results'!O2674+'Game Results'!O2439+'Game Results'!O3103+'Game Results'!O3157) -> 18.533333 | P7: =SUM('Game Results'!P74+'Game Results'!P122+'Game Results'!P453+'Game Results'!P813+'Game Results'!P891+'Game Results'!P930+'Game Results'!P1024+'Game Results'!P2588+'Game Results'!P1539+'Game Results'!P2166+'Game Results'!P1767+'Game Results'!P1925+'Game Results'!P1315+'Game Results'!P2101+'Game Results'!P1488+'Game Results'!P2674+'Game Results'!P2439+'Game Results'!P3103+'Game Results'!P3157) -> 6 | Q7: =SUM('Game Results'!Q74+'Game Results'!Q122+'Game Results'!Q453+'Game Results'!Q813+'Game Results'!Q891+'Game Results'!Q930+'Game Results'!Q1024+'Game Results'!Q2588+'Game Results'!Q1539+'Game Results'!Q2166+'Game Results'!Q1767+'Game Results'!Q1925+'Game Results'!Q1315+'Game Results'!Q2101+'Game Results'!Q1488+'Game Results'!Q2674+'Game Results'!Q2439+'Game Results'!Q3103+'Game Results'!Q3157) -> 4 | R7: =SUM('Game Results'!R74+'Game Results'!R122+'Game Results'!R453+'Game Results'!R813+'Game Results'!R891+'Game Results'!R930+'Game Results'!R1024+'Game Results'!R2588+'Game Results'!R1539+'Game Results'!R2166+'Game Results'!R1767+'Game Results'!R1925+'Game Results'!R1315+'Game Results'!R2101+'Game Results'!R1488+'Game Results'!R2674+'Game Results'!R2439+'Game Results'!R3103+'Game Results'!R3157) -> 4 | S7: =SUM('Game Results'!S74+'Game Results'!S122+'Game Results'!S453+'Game Results'!S813+'Game Results'!S891+'Game Results'!S930+'Game Results'!S1024+'Game Results'!S2588+'Game Results'!S1539+'Game Results'!S2166+'Game Results'!S1767+'Game Results'!S1925+'Game Results'!S1315+'Game Results'!S2101+'Game Results'!S1488+'Game Results'!S2674+'Game Results'!S2439+'Game Results'!S3103+'Game Results'!S3157) -> 1 | T7: =SUM('Game Results'!T74+'Game Results'!T122+'Game Results'!T453+'Game Results'!T813+'Game Results'!T891+'Game Results'!T930+'Game Results'!T1024+'Game Results'!T2588+'Game Results'!T1539+'Game Results'!T2166+'Game Results'!T1767+'Game Results'!T1925+'Game Results'!T1315+'Game Results'!T2101+'Game Results'!T1488+'Game Results'!T2674+'Game Results'!T2439+'Game Results'!T3103+'Game Results'!T3157) -> 11 | ... AH7: =SUM('Game Results'!AH74+'Game Results'!AH122+'Game Results'!AH453+'Game Results'!AH813+'Game Results'!AH891+'Game Results'!AH930+'Game Results'!AH1024+'Game Results'!AH2588+'Game Results'!AH1539+'Game Results'!AH2166+'Game Results'!AH1767+'Game Results'!AH1925+'Game Results'!AH1315+'Game Results'!AH2101+'Game Results'!AH1488+'Game Results'!AH2674+'Game Results'!AH2439+'Game Results'!AH3103+'Game Results'!AH3157) -> 0
A8: Never Let Go | B8: Liion Wiinz | C8: =SUM('Game Results'!C75+'Game Results'!C123+'Game Results'!C454+'Game Results'!C814+'Game Results'!C892+'Game Results'!C931+'Game Results'!C1025+'Game Results'!C2589+'Game Results'!C1540+'Game Results'!C2167+'Game Results'!C1768+'Game Results'!C1926+'Game Results'!C1316+'Game Results'!C2102+'Game Results'!C1489+'Game Results'!C2675+'Game Results'!C2440+'Game Results'!C3104+'Game Results'!C3158) -> 13 | D8: =SUM('Game Results'!D75+'Game Results'!D123+'Game Results'!D454+'Game Results'!D814+'Game Results'!D892+'Game Results'!D931+'Game Results'!D1025+'Game Results'!D2589+'Game Results'!D1540+'Game Results'!D2167+'Game Results'!D1768+'Game Results'!D1926+'Game Results'!D1316+'Game Results'!D2102+'Game Results'!D1489+'Game Results'!D2675+'Game Results'!D2440+'Game Results'!D3104+'Game Results'!D3158) -> 6 | E8: =SUM('Game Results'!E75+'Game Results'!E123+'Game Results'!E454+'Game Results'!E814+'Game Results'!E892+'Game Results'!E931+'Game Results'!E1025+'Game Results'!E2589+'Game Results'!E1540+'Game Results'!E2167+'Game Results'!E1768+'Game Results'!E1926+'Game Results'!E1316+'Game Results'!E2102+'Game Results'!E1489+'Game Results'!E2675+'Game Results'!E2440+'Game Results'!E3104+'Game Results'!E3158) -> 151.43333 | F8: =SUM('Game Results'!F75+'Game Results'!F123+'Game Results'!F454+'Game Results'!F814+'Game Results'!F892+'Game Results'!F931+'Game Results'!F1025+'Game Results'!F2589+'Game Results'!F1540+'Game Results'!F2167+'Game Results'!F1768+'Game Results'!F1926+'Game Results'!F1316+'Game Results'!F2102+'Game Results'!F1489+'Game Results'!F2675+'Game Results'!F2440+'Game Results'!F3104+'Game Results'!F3158) -> 3 | G8: =SUM('Game Results'!G75+'Game Results'!G123+'Game Results'!G454+'Game Results'!G814+'Game Results'!G892+'Game Results'!G931+'Game Results'!G1025+'Game Results'!G2589+'Game Results'!G1540+'Game Results'!G2167+'Game Results'!G1768+'Game Results'!G1926+'Game Results'!G1316+'Game Results'!G2102+'Game Results'!G1489+'Game Results'!G2675+'Game Results'!G2440+'Game Results'!G3104+'Game Results'!G3158) -> 669 | H8: =SUM('Game Results'!H75+'Game Results'!H123+'Game Results'!H454+'Game Results'!H814+'Game Results'!H892+'Game Results'!H931+'Game Results'!H1025+'Game Results'!H2589+'Game Results'!H1540+'Game Results'!H2167+'Game Results'!H1768+'Game Results'!H1926+'Game Results'!H1316+'Game Results'!H2102+'Game Results'!H1489+'Game Results'!H2675+'Game Results'!H2440+'Game Results'!H3104+'Game Results'!H3158) -> 3 | I8: =SUM('Game Results'!I75+'Game Results'!I123+'Game Results'!I454+'Game Results'!I814+'Game Results'!I892+'Game Results'!I931+'Game Results'!I1025+'Game Results'!I2589+'Game Results'!I1540+'Game Results'!I2167+'Game Results'!I1768+'Game Results'!I1926+'Game Results'!I1316+'Game Results'!I2102+'Game Results'!I1489+'Game Results'!I2675+'Game Results'!I2440+'Game Results'!I3104+'Game Results'!I3158) -> 622 | J8: =SUM('Game Results'!J75+'Game Results'!J123+'Game Results'!J454+'Game Results'!J814+'Game Results'!J892+'Game Results'!J931+'Game Results'!J1025+'Game Results'!J2589+'Game Results'!J1540+'Game Results'!J2167+'Game Results'!J1768+'Game Results'!J1926+'Game Results'!J1316+'Game Results'!J2102+'Game Results'!J1489+'Game Results'!J2675+'Game Results'!J2440+'Game Results'!J3104+'Game Results'!J3158) -> 47 | K8: =SUM(G8/I8) -> 1.0755627 | L8: =SUM(E8*60)/I8 -> 14.607717 | M8: =SUM('Game Results'!M75+'Game Results'!M123+'Game Results'!M454+'Game Results'!M814+'Game Results'!M892+'Game Results'!M931+'Game Results'!M1025+'Game Results'!M2589+'Game Results'!M1540+'Game Results'!M2167+'Game Results'!M1768+'Game Results'!M1926+'Game Results'!M1316+'Game Results'!M2102+'Game Results'!M1489+'Game Results'!M2675+'Game Results'!M2440+'Game Results'!M3104+'Game Results'!M3158) -> 762 | N8: =SUM('Game Results'!N75+'Game Results'!N123+'Game Results'!N454+'Game Results'!N814+'Game Results'!N892+'Game Results'!N931+'Game Results'!N1025+'Game Results'!N2589+'Game Results'!N1540+'Game Results'!N2167+'Game Results'!N1768+'Game Results'!N1926+'Game Results'!N1316+'Game Results'!N2102+'Game Results'!N1489+'Game Results'!N2675+'Game Results'!N2440+'Game Results'!N3104+'Game Results'!N3158) -> 12 | O8: =SUM('Game Results'!O75+'Game Results'!O123+'Game Results'!O454+'Game Results'!O814+'Game Results'!O892+'Game Results'!O931+'Game Results'!O1025+'Game Results'!O2589+'Game Results'!O1540+'Game Results'!O2167+'Game Results'!O1768+'Game Results'!O1926+'Game Results'!O1316+'Game Results'!O2102+'Game Results'!O1489+'Game Results'!O2675+'Game Results'!O2440+'Game Results'!O3104+'Game Results'!O3158) -> 144.58333 | P8: =SUM('Game Results'!P75+'Game Results'!P123+'Game Results'!P454+'Game Results'!P814+'Game Results'!P892+'Game Results'!P931+'Game Results'!P1025+'Game Results'!P2589+'Game Results'!P1540+'Game Results'!P2167+'Game Results'!P1768+'Game Results'!P1926+'Game Results'!P1316+'Game Results'!P2102+'Game Results'!P1489+'Game Results'!P2675+'Game Results'!P2440+'Game Results'!P3104+'Game Results'!P3158) -> 20 | Q8: =SUM('Game Results'!Q75+'Game Results'!Q123+'Game Results'!Q454+'Game Results'!Q814+'Game Results'!Q892+'Game Results'!Q931+'Game Results'!Q1025+'Game Results'!Q2589+'Game Results'!Q1540+'Game Results'!Q2167+'Game Results'!Q1768+'Game Results'!Q1926+'Game Results'!Q1316+'Game Results'!Q2102+'Game Results'!Q1489+'Game Results'!Q2675+'Game Results'!Q2440+'Game Results'!Q3104+'Game Results'!Q3158) -> 6 | R8: =SUM('Game Results'!R75+'Game Results'!R123+'Game Results'!R454+'Game Results'!R814+'Game Results'!R892+'Game Results'!R931+'Game Results'!R1025+'Game Results'!R2589+'Game Results'!R1540+'Game Results'!R2167+'Game Results'!R1768+'Game Results'!R1926+'Game Results'!R1316+'Game Results'!R2102+'Game Results'!R1489+'Game Results'!R2675+'Game Results'!R2440+'Game Results'!R3104+'Game Results'!R3158) -> 29 | S8: =SUM('Game Results'!S75+'Game Results'!S123+'Game Results'!S454+'Game Results'!S814+'Game Results'!S892+'Game Results'!S931+'Game Results'!S1025+'Game Results'!S2589+'Game Results'!S1540+'Game Results'!S2167+'Game Results'!S1768+'Game Results'!S1926+'Game Results'!S1316+'Game Results'!S2102+'Game Results'!S1489+'Game Results'!S2675+'Game Results'!S2440+'Game Results'!S3104+'Game Results'!S3158) -> 12 | T8: =SUM('Game Results'!T75+'Game Results'!T123+'Game Results'!T454+'Game Results'!T814+'Game Results'!T892+'Game Results'!T931+'Game Results'!T1025+'Game Results'!T2589+'Game Results'!T1540+'Game Results'!T2167+'Game Results'!T1768+'Game Results'!T1926+'Game Results'!T1316+'Game Results'!T2102+'Game Results'!T1489+'Game Results'!T2675+'Game Results'!T2440+'Game Results'!T3104+'Game Results'!T3158) -> 84 | ... AH8: =SUM('Game Results'!AH75+'Game Results'!AH123+'Game Results'!AH454+'Game Results'!AH814+'Game Results'!AH892+'Game Results'!AH931+'Game Results'!AH1025+'Game Results'!AH2589+'Game Results'!AH1540+'Game Results'!AH2167+'Game Results'!AH1768+'Game Results'!AH1926+'Game Results'!AH1316+'Game Results'!AH2102+'Game Results'!AH1489+'Game Results'!AH2675+'Game Results'!AH2440+'Game Results'!AH3104+'Game Results'!AH3158) -> 0
A9: Sub | B9: Aspence501 | C9: ='Game Results'!C2676+'Game Results'!C2441+'Game Results'!C3105+'Game Results'!C3159 -> 4 | D9: ='Game Results'!D2676+'Game Results'!D2441+'Game Results'!D3105+'Game Results'!D3159 -> 0 | E9: ='Game Results'!E2676+'Game Results'!E2441+'Game Results'!E3105+'Game Results'!E3159 -> 34.266667 | F9: ='Game Results'!F2676+'Game Results'!F2441+'Game Results'!F3105+'Game Results'!F3159 -> 4 | G9: ='Game Results'!G2676+'Game Results'!G2441+'Game Results'!G3105+'Game Results'!G3159 -> 117 | H9: ='Game Results'!H2676+'Game Results'!H2441+'Game Results'!H3105+'Game Results'!H3159 -> 1 | I9: ='Game Results'!I2676+'Game Results'!I2441+'Game Results'!I3105+'Game Results'!I3159 -> 138 | J9: ='Game Results'!J2676+'Game Results'!J2441+'Game Results'!J3105+'Game Results'!J3159 -> -21 | K9: =SUM(G9/I9) -> 0.84782609 | L9: =SUM(E9*60)/I9 -> 14.898551 | M9: ='Game Results'!M2676+'Game Results'!M2441+'Game Results'!M3105+'Game Results'!M3159 -> 159 | N9: ='Game Results'!N2676+'Game Results'!N2441+'Game Results'!N3105+'Game Results'!N3159 -> 4 | O9: ='Game Results'!O2676+'Game Results'!O2441+'Game Results'!O3105+'Game Results'!O3159 -> 32.666667 | P9: ='Game Results'!P2676+'Game Results'!P2441+'Game Results'!P3105+'Game Results'!P3159 -> 9 | Q9: ='Game Results'!Q2676+'Game Results'!Q2441+'Game Results'!Q3105+'Game Results'!Q3159 -> 1 | R9: ='Game Results'!R2676+'Game Results'!R2441+'Game Results'!R3105+'Game Results'!R3159 -> 7 | S9: ='Game Results'!S2676+'Game Results'!S2441+'Game Results'!S3105+'Game Results'!S3159 -> 2 | T9: ='Game Results'!T2676+'Game Results'!T2441+'Game Results'!T3105+'Game Results'!T3159 -> 15 | ... AH9: ='Game Results'!AH2676+'Game Results'!AH2441+'Game Results'!AH3105+'Game Results'!AH3159 -> 0
A10: Totals: | C10: =SUM(C3:C9)/4 -> 19 | D10: =SUM(D3:D9)/4 -> 10 | E10: =SUM(E3:E9) -> 887.46667 | F10: =SUM(F3:F9) -> 68 | G10: =SUM(G3:G9) -> 3683 | H10: =SUM(H3:H9) -> 20 | I10: =SUM(I3:I9) -> 3840 | J10: =SUM(J3:J9) -> -157 | K10: =SUM(G10/I10) -> 0.95911458 | L10: =SUM(E10*60)/I10 -> 13.866667 | M10: =SUM(M3:M9) -> 4565 | N10: =SUM(N3:N9) -> 74 | O10: =SUM(O3:O9) -> 862.71667 | P10: =SUM(P3:P9) -> 154 | Q10: =SUM(Q3:Q9) -> 67 | R10: =SUM(R3:R9) -> 201 | S10: =SUM(S3:S9) -> 67 | T10: =SUM(T3:T9) -> 498 | ... AH10: =SUM(AH3:AH9) -> 0
A11: Collateral Damage | B11: godwit1ivy (c) | C11: =SUM('Game Results'!C31+'Game Results'!C42+'Game Results'!C816+'Game Results'!C1045+'Game Results'!C581+'Game Results'!C1341+'Game Results'!C1077+'Game Results'!C1680+'Game Results'!C2188+'Game Results'!C2151+'Game Results'!C2885+'Game Results'!C2443+'Game Results'!C1427+'Game Results'!C2985) -> 12 | D11: =SUM('Game Results'!D31+'Game Results'!D42+'Game Results'!D816+'Game Results'!D1045+'Game Results'!D581+'Game Results'!D1341+'Game Results'!D1077+'Game Results'!D1680+'Game Results'!D2188+'Game Results'!D2151+'Game Results'!D2885+'Game Results'!D2443+'Game Results'!D1427+'Game Results'!D2985) -> 3 | E11: =SUM('Game Results'!E31+'Game Results'!E42+'Game Results'!E816+'Game Results'!E1045+'Game Results'!E581+'Game Results'!E1341+'Game Results'!E1077+'Game Results'!E1680+'Game Results'!E2188+'Game Results'!E2151+'Game Results'!E2885+'Game Results'!E2443+'Game Results'!E1427+'Game Results'!E2985) -> 150.33333 | F11: =SUM('Game Results'!F31+'Game Results'!F42+'Game Results'!F816+'Game Results'!F1045+'Game Results'!F581+'Game Results'!F1341+'Game Results'!F1077+'Game Results'!F1680+'Game Results'!F2188+'Game Results'!F2151+'Game Results'!F2885+'Game Results'!F2443+'Game Results'!F1427+'Game Results'!F2985) -> 0 | G11: =SUM('Game Results'!G31+'Game Results'!G42+'Game Results'!G816+'Game Results'!G1045+'Game Results'!G581+'Game Results'!G1341+'Game Results'!G1077+'Game Results'!G1680+'Game Results'!G2188+'Game Results'!G2151+'Game Results'!G2885+'Game Results'!G2443+'Game Results'!G1427+'Game Results'!G2985) -> 494 | H11: =SUM('Game Results'!H31+'Game Results'!H42+'Game Results'!H816+'Game Results'!H1045+'Game Results'!H581+'Game Results'!H1341+'Game Results'!H1077+'Game Results'!H1680+'Game Results'!H2188+'Game Results'!H2151+'Game Results'!H2885+'Game Results'!H2443+'Game Results'!H1427+'Game Results'!H2985) -> 5 | I11: =SUM('Game Results'!I31+'Game Results'!I42+'Game Results'!I816+'Game Results'!I1045+'Game Results'!I581+'Game Results'!I1341+'Game Results'!I1077+'Game Results'!I1680+'Game Results'!I2188+'Game Results'!I2151+'Game Results'!I2885+'Game Results'!I2443+'Game Results'!I1427+'Game Results'!I2985) -> 667 | J11: =SUM('Game Results'!J31+'Game Results'!J42+'Game Results'!J816+'Game Results'!J1045+'Game Results'!J581+'Game Results'!J1341+'Game Results'!J1077+'Game Results'!J1680+'Game Results'!J2188+'Game Results'!J2151+'Game Results'!J2885+'Game Results'!J2443+'Game Results'!J1427+'Game Results'!J2985) -> -173 | K11: =SUM(G11/I11) -> 0.74062969 | L11: =SUM(E11*60)/I11 -> 13.523238 | M11: =SUM('Game Results'!M31+'Game Results'!M42+'Game Results'!M816+'Game Results'!M1045+'Game Results'!M581+'Game Results'!M1341+'Game Results'!M1077+'Game Results'!M1680+'Game Results'!M2188+'Game Results'!M2151+'Game Results'!M2885+'Game Results'!M2443+'Game Results'!M1427+'Game Results'!M2985) -> 520 | N11: =SUM('Game Results'!N31+'Game Results'!N42+'Game Results'!N816+'Game Results'!N1045+'Game Results'!N581+'Game Results'!N1341+'Game Results'!N1077+'Game Results'!N1680+'Game Results'!N2188+'Game Results'!N2151+'Game Results'!N2885+'Game Results'!N2443+'Game Results'!N1427+'Game Results'!N2985) -> 9 | O11: =SUM('Game Results'!O31+'Game Results'!O42+'Game Results'!O816+'Game Results'!O1045+'Game Results'!O581+'Game Results'!O1341+'Game Results'!O1077+'Game Results'!O1680+'Game Results'!O2188+'Game Results'!O2151+'Game Results'!O2885+'Game Results'!O2443+'Game Results'!O1427+'Game Results'!O2985) -> 99.35 | P11: =SUM('Game Results'!P31+'Game Results'!P42+'Game Results'!P816+'Game Results'!P1045+'Game Results'!P581+'Game Results'!P1341+'Game Results'!P1077+'Game Results'!P1680+'Game Results'!P2188+'Game Results'!P2151+'Game Results'!P2885+'Game Results'!P2443+'Game Results'!P1427+'Game Results'!P2985) -> 14 | Q11: =SUM('Game Results'!Q31+'Game Results'!Q42+'Game Results'!Q816+'Game Results'!Q1045+'Game Results'!Q581+'Game Results'!Q1341+'Game Results'!Q1077+'Game Results'!Q1680+'Game Results'!Q2188+'Game Results'!Q2151+'Game Results'!Q2885+'Game Results'!Q2443+'Game Results'!Q1427+'Game Results'!Q2985) -> 3 | R11: =SUM('Game Results'!R31+'Game Results'!R42+'Game Results'!R816+'Game Results'!R1045+'Game Results'!R581+'Game Results'!R1341+'Game Results'!R1077+'Game Results'!R1680+'Game Results'!R2188+'Game Results'!R2151+'Game Results'!R2885+'Game Results'!R2443+'Game Results'!R1427+'Game Results'!R2985) -> 17 | S11: =SUM('Game Results'!S31+'Game Results'!S42+'Game Results'!S816+'Game Results'!S1045+'Game Results'!S581+'Game Results'!S1341+'Game Results'!S1077+'Game Results'!S1680+'Game Results'!S2188+'Game Results'!S2151+'Game Results'!S2885+'Game Results'!S2443+'Game Results'!S1427+'Game Results'!S2985) -> 7 | T11: =SUM('Game Results'!T31+'Game Results'!T42+'Game Results'!T816+'Game Results'!T1045+'Game Results'!T581+'Game Results'!T1341+'Game Results'!T1077+'Game Results'!T1680+'Game Results'!T2188+'Game Results'!T2151+'Game Results'!T2885+'Game Results'!T2443+'Game Results'!T1427+'Game Results'!T2985) -> 39 | ... AH11: =SUM('Game Results'!AH31+'Game Results'!AH42+'Game Results'!AH816+'Game Results'!AH1045+'Game Results'!AH581+'Game Results'!AH1341+'Game Results'!AH1077+'Game Results'!AH1680+'Game Results'!AH2188+'Game Results'!AH2151+'Game Results'!AH2885+'Game Results'!AH2443+'Game Results'!AH1427+'Game Results'!AH2985) -> 0
