Workbook

Sheet Reported Games
A1: Pro Games | E1: Legacy Games | I1: Ammy Games
A2: =IFERROR(__xludf.DUMMYFUNCTION("IMPORTRANGE(""https://docs.google.com/spreadsheets/d/1JR5LFsvurVDJDan0J41sUvpdEmU_bCrBTQdyvT_QPkc/edit"",""Schedule!M14:O200"")"),"#REF!") -> #REF! | E2: =IFERROR(__xludf.DUMMYFUNCTION("IMPORTRANGE(""https://docs.google.com/spreadsheets/d/1RRoDr9bmj5g2RByTBFQDzH3H-fsFm1u_RSEw_NV2MDE/edit"",""Schedule!M14:O200"")"),"#REF!") -> #REF! | I2: =IFERROR(__xludf.DUMMYFUNCTION("IMPORTRANGE(""https://docs.google.com/spreadsheets/d/1srKzhMz0keQSWpKGQR5P3281KrGCBzL0tLp_FHRez9k/edit"",""Schedule!M14:O200"")"),"#REF!") -> #REF!

Sheet League Table
E1: Fantasy League Table | J1: Form
A2: Pos | B2: Team | C2: Manager | D2: Won | E2: Tie | F2: Loss | G2: Fantasy Points | H2: Win % | J2: Fortnight 1 | Q2: Fortnight 2 | X2: Fortnight 3 | AD2: Fortnight 4
A3: 1st | B3: Reyley FC | C3: Reyas | D3: =0 -> 0 | E3: =0 -> 0 | F3: =0 -> 0 | G3: ='W1 Team Points'!F16+'W2 Team Points'!F16+'W3 Team Points'!F16+'W4 Team Points'!F16 -> 0 | H3: =D3/(D3+E3+F3) -> #DIV/0!
A4: 2nd | B4: Tormenting Teutons | C4: Xknight25R9270 | D4: =0 -> 0 | E4: =0 -> 0 | F4: =0 -> 0 | G4: ='W1 Team Points'!M16+'W2 Team Points'!M16+'W3 Team Points'!M16+'W4 Team Points'!M16 -> 0 | H4: =D4/(D4+E4+F4) -> #DIV/0!
A5: 3rd | B5: Gingy | C5: ixGingy | D5: =0 -> 0 | E5: =0 -> 0 | F5: =0 -> 0 | G5: ='W1 Team Points'!T16+'W2 Team Points'!T16+'W3 Team Points'!T16+'W4 Team Points'!T16 -> 234 | H5: =D5/(D5+E5+F5) -> #DIV/0!
A6: 4th | B6: Sab | C6: Sabasauros Rex | D6: =0 -> 0 | E6: =0 -> 0 | F6: =0 -> 0 | G6: ='W1 Team Points'!F32+'W2 Team Points'!F32+'W3 Team Points'!F32+'W4 Team Points'!F32 -> 271 | H6: =D6/(D6+E6+F6) -> #DIV/0!
A7: 5th | B7: Ammyships | C7: The Texorcist | D7: =0 -> 0 | E7: =0 -> 0 | F7: =0 -> 0 | G7: ='W1 Team Points'!M32+'W2 Team Points'!M32+'W3 Team Points'!M32+'W4 Team Points'!M32 -> 215 | H7: =D7/(D7+E7+F7) -> #DIV/0!
A8: 6th | B8: Sonic | C8: SonicNachos | D8: =0 -> 0 | E8: =0 -> 0 | F8: =0 -> 0 | G8: ='W1 Team Points'!T32+'W2 Team Points'!T32+'W3 Team Points'!T32+'W4 Team Points'!T32 -> 0 | H8: =D8/(D8+E8+F8) -> #DIV/0!
A9: 7th | B9: Sader's Tots | C9: Ming Crusader | D9: =0 -> 0 | E9: =0 -> 0 | F9: =0 -> 0 | G9: ='W1 Team Points'!F48+'W2 Team Points'!F48+'W3 Team Points'!F48+'W4 Team Points'!F48 -> 0 | H9: =D9/(D9+E9+F9) -> #DIV/0!
A10: 8th | B10: KDSkill | C10: KDSkill | D10: =0 -> 0 | E10: =0 -> 0 | F10: =0 -> 0 | G10: ='W1 Team Points'!M48+'W2 Team Points'!M48+'W3 Team Points'!M48+'W4 Team Points'!M48 -> 215 | H10: =D10/(D10+E10+F10) -> #DIV/0!
A11: 9th | B11: The Black List 2.0 | C11: ActiveHate | D11: =0 -> 0 | E11: =0 -> 0 | F11: =0 -> 0 | G11: ='W1 Team Points'!T48+'W2 Team Points'!T48+'W3 Team Points'!T48+'W4 Team Points'!T48 -> 146 | H11: =D11/(D11+E11+F11) -> #DIV/0!
A12: 10th | B12: Repeat Performance | C12: Silva* | D12: =0 -> 0 | E12: =0 -> 0 | F12: =0 -> 0 | G12: ='W1 Team Points'!F64+'W2 Team Points'!F64+'W3 Team Points'!F64+'W4 Team Points'!F64 -> 215 | H12: =D12/(D12+E12+F12) -> #DIV/0!
A13: 11th | B13: Clutch Coffee | C13: AJ DaJuiceMayne | D13: =0 -> 0 | E13: =0 -> 0 | F13: =0 -> 0 | G13: ='W1 Team Points'!M64+'W2 Team Points'!M64+'W3 Team Points'!M64+'W4 Team Points'!M64 -> 264 | H13: =D13/(D13+E13+F13) -> #DIV/0!
A14: 12th | B14: Filler | C14: - | D14: =0 -> 0 | E14: =0 -> 0 | F14: =0 -> 0 | G14: ='W1 Team Points'!T64+'W2 Team Points'!T64+'W3 Team Points'!T64+'W4 Team Points'!T64 -> 0 | H14: =D14/(D14+E14+F14) -> #DIV/0!

Sheet Fixtures & Results
A1: AGLA SL18 Fixtures & Results | K1: Played Games
A2: Fortnight 1 | K2: Result | L2: Links
A3: Team 1: | B3: Score: | C3: Score: | D3: Team 2: | F3: Team 1: | G3: Score: | H3: Score: | I3: Team 2: | K3: Notorious 2-1 Ghosts Of Grif | L3: =HYPERLINK("https://www.halowaypoint.com/en-us/games/halo-5-guardians/xbox-one/mode/custom/matches/5668bce5-70fe-4523-b93b-dfd5250ee8f3/players/saintz%20the%20god?gameHistoryMatchIndex=55&gameHistoryGameModeFilter=All","5-4") -> 5-4 | M3: =HYPERLINK("https://www.halowaypoint.com/en-us/games/halo-5-guardians/xbox-one/mode/custom/matches/558f96c9-145b-48ff-ac42-614587e1412d/players/saintz%20the%20god?gameHistoryMatchIndex=54&gameHistoryGameModeFilter=All","2-5") -> 2-5 | N3: =HYPERLINK("https://www.halowaypoint.com/en-us/games/halo-5-guardians/xbox-one/mode/custom/matches/2e8056b4-7159-4b0c-87b8-39e579323439/players/saintz%20the%20god?gameHistoryMatchIndex=53&gameHistoryGameModeFilter=All","5-2") -> 5-2
A4: The Black List 2.0 | B4: ='W1 Team Points'!T48 -> 146 | C4: ='W1 Team Points'!M64 -> 264 | D4: Clutch Coffee | F4: Repeat Performance | G4: ='W1 Team Points'!F64 -> 215 | H4: ='W1 Team Points'!T48 -> 146 | I4: The Black List 2.0 | K4: Grammaton Clerics 2-1 Elevate | L4: =HYPERLINK("https://www.halowaypoint.com/en-us/games/halo-5-guardians/xbox-one/mode/custom/matches/c923b91c-083a-4a77-b58d-7857e3cec20e/players/rage%20more%20nerd?gameHistoryMatchIndex=26&gameHistoryGameModeFilter=Custom","4-5") -> 4-5 | M4: =HYPERLINK("https://www.halowaypoint.com/en-us/games/halo-5-guardians/xbox-one/mode/custom/matches/dee8ad31-0be9-45c5-8725-64fd2c889e79/players/rage%20more%20nerd?gameHistoryMatchIndex=25&gameHistoryGameModeFilter=Custom","5-1") -> 5-1 | N4: =HYPERLINK("https://www.halowaypoint.com/en-us/games/halo-5-guardians/xbox-one/mode/custom/matches/7e333166-6350-4ad5-915e-83a26fdd67fa/players/rage%20more%20nerd?gameHistoryMatchIndex=24&gameHistoryGameModeFilter=Custom","5-0") -> 5-0
A5: KDSkill | B5: ='W1 Team Points'!M48 -> 215 | C5: ='W1 Team Points'!T16 -> 234 | D5: Gingy | F5: Sader's Tots | G5: ='W1 Team Points'!F48 -> 0 | H5: ='W1 Team Points'!F16 -> 0 | I5: Reyley FC | K5: Xbox Record That 2-0 Ghosts Of Grif | L5: FF | M5: =HYPERLINK("https://www.halowaypoint.com/en-us/games/halo-5-guardians/xbox-one/mode/custom/matches/34a16586-6f31-4e0c-9678-f97b522c729f/players/poisonxpoptart?gameHistoryMatchIndex=44&gameHistoryGameModeFilter=Custom","5-1") -> 5-1
A6: Sab | B6: ='W1 Team Points'!F32 -> 271 | C6: ='W1 Team Points'!F16 -> 0 | D6: Reyley FC | F6: Ammyships | G6: ='W1 Team Points'!M32 -> 215 | H6: ='W1 Team Points'!T16 -> 234 | I6: Gingy | K6: Notorious 2-1 Elevate | L6: =HYPERLINK("https://www.halowaypoint.com/en-us/games/halo-5-guardians/xbox-one/mode/custom/matches/4a8a20b2-f873-42e2-921d-59b724828f0d/players/rage%20more%20nerd?gameHistoryMatchIndex=10&gameHistoryGameModeFilter=Custom","5-4") -> 5-4 | M6: =HYPERLINK("https://www.halowaypoint.com/en-us/games/halo-5-guardians/xbox-one/mode/custom/matches/45a80853-64e3-43cb-93eb-5b6f9fb1ce48/players/rage%20more%20nerd?gameHistoryMatchIndex=9&gameHistoryGameModeFilter=Custom","0-5") -> 0-5 | N6: =HYPERLINK("https://www.halowaypoint.com/en-us/games/halo-5-guardians/xbox-one/mode/custom/matches/59c13e12-7554-4e2b-9ad6-8c0a0165c2d0/players/rage%20more%20nerd?gameHistoryMatchIndex=8&gameHistoryGameModeFilter=Custom","3-5") -> 3-5
A7: Filler | B7: ='W1 Team Points'!T64 -> 0 | C7: ='W1 Team Points'!F64 -> 215 | D7: Repeat Performance | F7: Sonic | G7: ='W1 Team Points'!T32 -> 0 | H7: ='W1 Team Points'!M64 -> 264 | I7: Clutch Coffee | K7: One Hit Wonders 2-0 Elevate | L7: =HYPERLINK("https://www.halowaypoint.com/en-us/games/halo-5-guardians/xbox-one/mode/custom/matches/2bd8ba12-6de7-48fb-8fe1-bc06bd1c7492/players/rage%20more%20nerd?gameHistoryMatchIndex=7&gameHistoryGameModeFilter=Custom","5-1") -> 5-1 | M7: =HYPERLINK("https://www.halowaypoint.com/en-us/games/halo-5-guardians/xbox-one/mode/custom/matches/9e5be57c-868e-4970-ade6-e0f72edabc4d/players/rage%20more%20nerd?gameHistoryMatchIndex=6&gameHistoryGameModeFilter=Custom","5-2") -> 5-2
A8: Tormenting Teutons | B8: ='W1 Team Points'!M16 -> 0 | C8: ='W1 Team Points'!F48 -> 0 | D8: Sader's Tots | F8: Tormenting Teutons | G8: ='W1 Team Points'!M16 -> 0 | H8: ='W1 Team Points'!M48 -> 215 | I8: KDSkill | K8: Xbox Record That 2-1 Ghosts Of Grif | L8: =HYPERLINK("https://www.halowaypoint.com/en-us/games/halo-5-guardians/xbox-one/mode/custom/matches/818001f0-4d59-4143-91ad-d41de7b22cb5/players/poisonxpoptart?gameHistoryMatchIndex=28&gameHistoryGameModeFilter=Custom","5-2") -> 5-2 | M8: =HYPERLINK("https://www.halowaypoint.com/en-us/games/halo-5-guardians/xbox-one/mode/custom/matches/073c2b54-65ef-47c2-97f9-f203819475da/players/poisonxpoptart?gameHistoryMatchIndex=26&gameHistoryGameModeFilter=Custom","5-1") -> 5-1 | N8: =HYPERLINK("https://www.halowaypoint.com/en-us/games/halo-5-guardians/xbox-one/mode/custom/matches/ed8042a8-f4ee-4858-9a2c-96a56c7566a3/players/poisonxpoptart?gameHistoryMatchIndex=27&gameHistoryGameModeFilter=Custom","5-1") -> 5-1
A9: Sonic | B9: ='W1 Team Points'!T32 -> 0 | C9: ='W1 Team Points'!M32 -> 215 | D9: Ammyships | F9: Filler | G9: ='W1 Team Points'!T64 -> 0 | H9: ='W1 Team Points'!F32 -> 271 | I9: Sab | K9: Grammaton Clerics 2-0 Ghosts Of Grif | L9: =HYPERLINK("https://www.halowaypoint.com/en-us/games/halo-5-guardians/xbox-one/mode/custom/matches/4908a990-98ad-461f-8c13-5e93cb83fa72/players/king%20rickxl?gameHistoryMatchIndex=12&gameHistoryGameModeFilter=Custom","5-1") -> 5-1 | M9: =HYPERLINK("https://www.halowaypoint.com/en-us/games/halo-5-guardians/xbox-one/mode/custom/matches/92a15ea8-9d82-4ea0-aed8-c6278ad421b6/players/king%20rickxl?gameHistoryMatchIndex=13&gameHistoryGameModeFilter=Custom","5-1") -> 5-1
A10: Gingy | B10: ='W1 Team Points'!T16 -> 234 | C10: ='W1 Team Points'!T48 -> 146 | D10: The Black List 2.0 | F10: The Black List 2.0 | G10: ='W1 Team Points'!T48 -> 146 | H10: ='W1 Team Points'!F48 -> 0 | I10: Sader's Tots | K10: Grammaton Clerics 2-1 Ghosts Of Grif | L10: =HYPERLINK("https://www.halowaypoint.com/en-us/games/halo-5-guardians/xbox-one/mode/custom/matches/d2068f50-b643-48d5-9d24-e38528a44a6e/players/king%20rickxl?gameHistoryMatchIndex=11&gameHistoryGameModeFilter=Custom","4-5") -> 4-5 | M10: =HYPERLINK("https://www.halowaypoint.com/en-us/games/halo-5-guardians/xbox-one/mode/custom/matches/364da6eb-00e8-4eb3-9c4c-056bcafcdba1/players/king%20rickxl?gameHistoryMatchIndex=9&gameHistoryGameModeFilter=Custom","5-0") -> 5-0 | N10: =HYPERLINK("https://www.halowaypoint.com/en-us/games/halo-5-guardians/xbox-one/mode/custom/matches/3c23759d-d32b-4f70-9689-c83bffec843c/players/king%20rickxl?gameHistoryMatchIndex=10&gameHistoryGameModeFilter=Custom","5-2") -> 5-2
A11: Reyley FC | B11: ='W1 Team Points'!F16 -> 0 | C11: ='W1 Team Points'!M64 -> 264 | D11: Clutch Coffee | F11: Repeat Performance | G11: ='W1 Team Points'!F64 -> 215 | H11: ='W1 Team Points'!M32 -> 215 | I11: Ammyships | K11: Grammaton Clerics 2-0 One Hit Wonders | L11: =HYPERLINK("https://www.halowaypoint.com/en-us/games/halo-5-guardians/xbox-one/mode/custom/matches/5089ca3c-dd77-46fc-9478-83795eef677f/players/infiniterainge?gameHistoryMatchIndex=4&gameHistoryGameModeFilter=Custom","5-0") -> 5-0 | M11: =HYPERLINK("https://www.halowaypoint.com/en-us/games/halo-5-guardians/xbox-one/mode/custom/matches/0aaf6f37-5a64-40ba-9767-eec5c49a2802/players/infiniterainge?gameHistoryMatchIndex=5&gameHistoryGameModeFilter=Custom","5-3") -> 5-3
A12: Repeat Performance | B12: ='W1 Team Points'!F64 -> 215 | C12: ='W1 Team Points'!M48 -> 215 | D12: KDSkill | F12: Reyley FC | G12: ='W1 Team Points'!F16 -> 0 | H12: ='W1 Team Points'!T32 -> 0 | I12: Sonic
A13: Sader's Tots | B13: ='W1 Team Points'!F48 -> 0 | C13: ='W1 Team Points'!F32 -> 271 | D13: Sab | F13: Gingy | G13: ='W1 Team Points'!T16 -> 234 | H13: ='W1 Team Points'!M16 -> 0 | I13: Tormenting Teutons
A14: Ammyships | B14: ='W1 Team Points'!M32 -> 215 | C14: ='W1 Team Points'!T64 -> 0 | D14: Filler | F14: Clutch Coffee | G14: ='W1 Team Points'!M64 -> 264 | H14: ='W1 Team Points'!T64 -> 0 | I14: Filler
A15: Sonic | B15: ='W1 Team Points'!T32 -> 0 | C15: ='W1 Team Points'!M16 -> 0 | D15: Tormenting Teutons | F15: KDSkill | G15: ='W1 Team Points'!M48 -> 215 | H15: ='W1 Team Points'!F32 -> 271 | I15: Sab
A16: The Black List 2.0 | B16: ='W1 Team Points'!T48 -> 146 | C16: ='W1 Team Points'!F16 -> 0 | D16: Reyley FC | F16: Ammyships | G16: ='W1 Team Points'!M32 -> 215 | H16: ='W1 Team Points'!T48 -> 146 | I16: The Black List 2.0
A17: Gingy | B17: ='W1 Team Points'!T16 -> 234 | C17: ='W1 Team Points'!F64 -> 215 | D17: Repeat Performance | F17: Sonic | G17: ='W1 Team Points'!T32 -> 0 | H17: ='W1 Team Points'!F48 -> 0 | I17: Sader's Tots
A18: Clutch Coffee | B18: ='W1 Team Points'!M64 -> 264 | C18: ='W1 Team Points'!F48 -> 0 | D18: Sader's Tots | F18: Tormenting Teutons | G18: ='W1 Team Points'!M16 -> 0 | H18: ='W1 Team Points'!F64 -> 215 | I18: Repeat Performance
A19: KDSkill | B19: ='W1 Team Points'!M48 -> 215 | C19: ='W1 Team Points'!M32 -> 215 | D19: Ammyships | F19: Filler | G19: ='W1 Team Points'!T64 -> 0 | H19: ='W1 Team Points'!F16 -> 0 | I19: Reyley FC
A20: Sab | B20: ='W1 Team Points'!F32 -> 271 | C20: ='W1 Team Points'!T32 -> 0 | D20: Sonic | F20: Sab | G20: ='W1 Team Points'!F32 -> 271 | H20: ='W1 Team Points'!T16 -> 234 | I20: Gingy
A21: Filler | B21: ='W1 Team Points'!T64 -> 0 | C21: ='W1 Team Points'!M16 -> 0 | D21: Tormenting Teutons | F21: KDSkill | G21: ='W1 Team Points'!M48 -> 215 | H21: ='W1 Team Points'!M64 -> 264 | I21: Clutch Coffee
A23: Fortnight 2 | K23: Result | L23: Links
A24: Team 1: | B24: Score: | C24: Score: | D24: Team 2: | F24: Team 1: | G24: Score: | H24: Score: | I24: Team 2: | K24: Elevate 2-0 Ghosts Of Grif | L24: =HYPERLINK("https://www.halowaypoint.com/en-us/games/halo-5-guardians/xbox-one/mode/custom/matches/48f5abcf-d0a5-4599-a68b-24458ba64d34/players/rage%20more%20nerd?gameHistoryMatchIndex=3&gameHistoryGameModeFilter=All","5-1") -> 5-1 | M24: =HYPERLINK("https://www.halowaypoint.com/en-us/games/halo-5-guardians/xbox-one/mode/custom/matches/89b8affe-2b27-412a-a726-44e7855c02dc/players/rage%20more%20nerd?gameHistoryMatchIndex=2&gameHistoryGameModeFilter=All","5-3") -> 5-3
A25: The Black List 2.0 | B25: ='W2 Team Points'!T48 -> 0 | C25: ='W2 Team Points'!T32 -> 0 | D25: Sonic | F25: Sab | G25: ='W2 Team Points'!F32 -> 0 | H25: ='W2 Team Points'!T48 -> 0 | I25: The Black List 2.0 | K25: Elevate 2-0 Ghosts Of Grif | L25: =HYPERLINK("https://www.halowaypoint.com/en-us/games/halo-5-guardians/xbox-one/mode/custom/matches/5d24faa0-6ec1-44a9-80b4-7d28e7a1a8b2/players/rage%20more%20nerd?gameHistoryMatchIndex=1&gameHistoryGameModeFilter=All","5-2") -> 5-2 | M25: =HYPERLINK("https://www.halowaypoint.com/en-us/games/halo-5-guardians/xbox-one/mode/custom/matches/8472c7d6-ffc4-468f-9b43-0c231e50dcb0/players/rage%20more%20nerd?gameHistoryMatchIndex=0&gameHistoryGameModeFilter=All","5-3") -> 5-3
A26: Ammyships | B26: ='W2 Team Points'!M32 -> 0 | C26: ='W2 Team Points'!M16 -> 0 | D26: Tormenting Teutons | F26: KDSkill | G26: ='W2 Team Points'!M48 -> 0 | H26: ='W2 Team Points'!T64 -> 0 | I26: Filler | K26: One Hit Wonders 2-0 Ghosts Of Grif | L26: =HYPERLINK("https://www.halowaypoint.com/en-us/games/halo-5-guardians/xbox-one/mode/custom/matches/1a298f78-f293-4e8d-a49a-b85facdc7133/players/ohw%20crusader?gameHistoryMatchIndex=1&gameHistoryGameModeFilter=All","5-0") -> 5-0 | M26: =HYPERLINK("https://www.halowaypoint.com/en-us/games/halo-5-guardians/xbox-one/mode/custom/matches/240fe1c7-81f0-4d16-a965-bc07dc6da6d9/players/ohw%20crusader?gameHistoryMatchIndex=0&gameHistoryGameModeFilter=All","5-1") -> 5-1
A27: Sader's Tots | B27: ='W2 Team Points'!F48 -> 0 | C27: ='W2 Team Points'!T64 -> 0 | D27: Filler | F27: Clutch Coffee | G27: ='W2 Team Points'!M64 -> 0 | H27: ='W2 Team Points'!M16 -> 0 | I27: Tormenting Teutons | K27: Grammaton Clerics 1-0 Elevate | L27: =HYPERLINK("https://www.halowaypoint.com/en-us/games/halo-5-guardians/xbox-one/mode/custom/matches/132b74b7-6e02-4064-bd92-e55e2faec6be/players/rage%20more%20nerd?gameHistoryMatchIndex=4&gameHistoryGameModeFilter=All","5-3") -> 5-3
A28: Repeat Performance | B28: ='W2 Team Points'!F64 -> 0 | C28: ='W2 Team Points'!F32 -> 0 | D28: Sab | F28: Gingy | G28: ='W2 Team Points'!T16 -> 0 | H28: ='W2 Team Points'!T32 -> 0 | I28: Sonic
A29: Reyley FC | B29: ='W2 Team Points'!F16 -> 0 | C29: ='W2 Team Points'!M48 -> 0 | D29: KDSkill | F29: Reyley FC | G29: ='W2 Team Points'!F16 -> 0 | H29: ='W2 Team Points'!M32 -> 0 | I29: Ammyships
A30: Gingy | B30: ='W2 Team Points'!T16 -> 0 | C30: ='W2 Team Points'!M64 -> 0 | D30: Clutch Coffee | F30: Repeat Performance | G30: ='W2 Team Points'!F64 -> 0 | H30: ='W2 Team Points'!F48 -> 0 | I30: Sader's Tots
A31: Tormenting Teutons | B31: ='W2 Team Points'!M16 -> 0 | C31: ='W2 Team Points'!T48 -> 0 | D31: The Black List 2.0 | F31: The Black List 2.0 | G31: ='W2 Team Points'!T48 -> 0 | H31: ='W2 Team Points'!M48 -> 0 | I31: KDSkill
A32: Filler | B32: ='W2 Team Points'!T64 -> 0 | C32: ='W2 Team Points'!T32 -> 0 | D32: Sonic | F32: Sab | G32: ='W2 Team Points'!F32 -> 0 | H32: ='W2 Team Points'!M64 -> 0 | I32: Clutch Coffee
A33: Sab | B33: ='W2 Team Points'!F32 -> 0 | C33: ='W2 Team Points'!M32 -> 0 | D33: Ammyships | F33: Filler | G33: ='W2 Team Points'!T64 -> 0 | H33: ='W2 Team Points'!T16 -> 0 | I33: Gingy
A34: KDSkill | B34: ='W2 Team Points'!M48 -> 0 | C34: ='W2 Team Points'!F48 -> 0 | D34: Sader's Tots | F34: Tormenting Teutons | G34: ='W2 Team Points'!M16 -> 0 | H34: ='W2 Team Points'!F16 -> 0 | I34: Reyley FC
A35: Clutch Coffee | B35: ='W2 Team Points'!M64 -> 0 | C35: ='W2 Team Points'!F64 -> 0 | D35: Repeat Performance | F35: Sonic | G35: ='W2 Team Points'!T32 -> 0 | H35: ='W2 Team Points'!F64 -> 0 | I35: Repeat Performance
A36: Gingy | B36: ='W2 Team Points'!T16 -> 0 | C36: ='W2 Team Points'!F16 -> 0 | D36: Reyley FC | F36: Ammyships | G36: ='W2 Team Points'!M32 -> 0 | H36: ='W2 Team Points'!F48 -> 0 | I36: Sader's Tots
A37: The Black List 2.0 | B37: ='W2 Team Points'!T48 -> 0 | C37: ='W2 Team Points'!T64 -> 0 | D37: Filler | F37: Clutch Coffee | G37: ='W2 Team Points'!M64 -> 0 | H37: ='W2 Team Points'!T48 -> 0 | I37: The Black List 2.0
A38: Tormenting Teutons | B38: ='W2 Team Points'!M16 -> 0 | C38: ='W2 Team Points'!F32 -> 0 | D38: Sab | F38: Gingy | G38: ='W2 Team Points'!T16 -> 0 | H38: ='W2 Team Points'!M48 -> 0 | I38: KDSkill
A39: Sonic | B39: ='W2 Team Points'!T32 -> 0 | C39: ='W2 Team Points'!M48 -> 0 | D39: KDSkill | F39: Reyley FC | G39: ='W2 Team Points'!F16 -> 0 | H39: ='W2 Team Points'!F32 -> 0 | I39: Sab
A40: Ammyships | B40: ='W2 Team Points'!M32 -> 0 | C40: ='W2 Team Points'!M64 -> 0 | D40: Clutch Coffee | F40: Repeat Performance | G40: ='W2 Team Points'!F64 -> 0 | H40: ='W2 Team Points'!T64 -> 0 | I40: Filler
A41: Sader's Tots | B41: ='W2 Team Points'!F48 -> 0 | C41: ='W2 Team Points'!T16 -> 0 | D41: Gingy | F41: Sader's Tots | G41: ='W2 Team Points'!F48 -> 0 | H41: ='W2 Team Points'!M16 -> 0 | I41: Tormenting Teutons
...

Sheet _BlockspringConfiguration
A1: Settings:
A2: selection_metadata | B2: {}
A3: Queries:
A4: query id | B4: sheet name | C4: range address | D4: created | E4: updated | F4: selection | G4: clear selection | H4: timed refresh | I4: run | J4: append | K4: match headers | L4: advanced options | M4: custom title | N4: custom description | O4: block id | P4: parameters

Sheet Teams Totals
A1: Reyley FC | H1: Tormenting Teutons | O1: Gingy
A2: Manager | B2: Runner | C2: Tank | D2: Defender | E2: Hybrid | F2: Sub | H2: Manager | I2: Runner | J2: Tank | K2: Defender | L2: Hybrid | M2: Sub | O2: Manager | P2: Runner | Q2: Tank | R2: Defender | S2: Hybrid | T2: Sub
A3: Reyas | B3: Ace B S1lentND1 | C3: Invayda Zim | D3: Rage More Nerd | E3: DCleak | F3: ST0P K1LLING ME | H3: Xknight25R9270 | I3: KDSkill | J3: BCN19 | K3: Ming Crusader | L3: ThumpingHawk | M3: Almighty Tycoon | O3: ixGingy | P3: Almighty Tycoon | Q3: ixGingy | R3: Rage More Nerd | S3: The Piggies | T3: DCleak
A4: Goals | B4: ='Points System'!H30 -> 0 | C4: ='Points System'!I86 | D4: ='Points System'!D16 | E4: ='Points System'!Q30 -> 0 | F4: TUVW30 | H4: Goals | I4: ='Points System'!T58 -> 0 | J4: ='Points System'!I16 | K4: ='Points System'!D58 | L4: ='Points System'!W16 -> 0 | M4: Z-AC72 | O4: Goals | P4: ='Points System'!Z72 -> 45 | Q4: ='Points System'!O72 | R4: ='Points System'!D16 | S4: ='Points System'!E86 -> 0 | T4: NOPQ30
A5: Sword Kills | B5: ='Points System'!H31 | C5: ='Points System'!I87 | D5: ='Points System'!D17 -> 0 | E5: ='Points System'!Q31 | H5: Sword Kills | I5: ='Points System'!T59 | J5: ='Points System'!I17 | K5: ='Points System'!D59 -> 0 | L5: ='Points System'!W17 | O5: Sword Kills | P5: ='Points System'!Z73 | Q5: ='Points System'!O73 | R5: ='Points System'!D17 -> 0 | S5: ='Points System'!E87
A6: Ball Kills | B6: ='Points System'!H32 -> 0 | C6: ='Points System'!I88 | D6: ='Points System'!D18 | E6: ='Points System'!Q32 | H6: Ball Kills | I6: ='Points System'!T60 -> 0 | J6: ='Points System'!I18 | K6: ='Points System'!D60 | L6: ='Points System'!W18 | O6: Ball Kills | P6: ='Points System'!Z74 -> 26 | Q6: ='Points System'!O74 | R6: ='Points System'!D18 | S6: ='Points System'!E88
A7: KD Spread | B7: ='Points System'!H33 | C7: ='Points System'!I89 -> 0 | D7: ='Points System'!D19 | E7: ='Points System'!Q33 -> 0 | H7: KD Spread | I7: ='Points System'!T61 | J7: ='Points System'!I19 -> 0 | K7: ='Points System'!D61 | L7: ='Points System'!W19 -> 0 | O7: KD Spread | P7: ='Points System'!Z75 | Q7: ='Points System'!O75 -> 30 | R7: ='Points System'!D19 | S7: ='Points System'!E89 -> 0
A8: First Strike | B8: ='Points System'!H34 | C8: ='Points System'!I90 -> 0 | D8: ='Points System'!D20 | E8: ='Points System'!Q34 -> 0 | H8: First Strike | I8: ='Points System'!T62 | J8: ='Points System'!I20 -> 0 | K8: ='Points System'!D62 | L8: ='Points System'!W20 -> 0 | O8: First Strike | P8: ='Points System'!Z76 | Q8: ='Points System'!O76 -> 30 | R8: ='Points System'!D20 | S8: ='Points System'!E90 -> 0
A9: First Touch | B9: ='Points System'!H35 -> 0 | C9: ='Points System'!I91 | D9: ='Points System'!D21 -> 0 | E9: ='Points System'!Q35 | H9: First Touch | I9: ='Points System'!T63 -> 0 | J9: ='Points System'!I21 | K9: ='Points System'!D63 -> 0 | L9: ='Points System'!W21 | O9: First Touch | P9: ='Points System'!Z77 -> 30 | Q9: ='Points System'!O77 | R9: ='Points System'!D21 -> 0 | S9: ='Points System'!E91
A10: Multikill | B10: ='Points System'!H36 | C10: ='Points System'!I92 -> 0 | D10: ='Points System'!D22 | E10: ='Points System'!Q36 | H10: Multikill | I10: ='Points System'!T64 | J10: ='Points System'!I22 -> 0 | K10: ='Points System'!D64 | L10: ='Points System'!W22 | O10: Multikill | P10: ='Points System'!Z78 | Q10: ='Points System'!O78 -> 52 | R10: ='Points System'!D22 | S10: ='Points System'!E92
A11: Carrier Kill | B11: ='Points System'!H37 | C11: ='Points System'!I93 | D11: ='Points System'!D23 -> 0 | E11: ='Points System'!Q37 -> 0 | H11: Carrier Kill | I11: ='Points System'!T65 | J11: ='Points System'!I23 | K11: ='Points System'!D65 -> 0 | L11: ='Points System'!W23 -> 0 | O11: Carrier Kill | P11: ='Points System'!Z79 | Q11: ='Points System'!O79 | R11: ='Points System'!D23 -> 0 | S11: ='Points System'!E93 -> 0
A12: Goal Offence | B12: ='Points System'!H38 | C12: ='Points System'!I94 -> 0 | D12: ='Points System'!D24 | E12: ='Points System'!Q38 -> 0 | H12: Goal Offence | I12: ='Points System'!T66 | J12: ='Points System'!I24 -> 0 | K12: ='Points System'!D66 | L12: ='Points System'!W24 -> 0 | O12: Goal Offence | P12: ='Points System'!Z80 | Q12: ='Points System'!O80 -> 21 | R12: ='Points System'!D24 | S12: ='Points System'!E94 -> 0
A13: Goal Defence | B13: ='Points System'!H39 | C13: ='Points System'!I95 | D13: ='Points System'!D25 -> 0 | E13: ='Points System'!Q39 -> 0 | H13: Goal Defence | I13: ='Points System'!T67 | J13: ='Points System'!I25 | K13: ='Points System'!D67 -> 0 | L13: ='Points System'!W25 -> 0 | O13: Goal Defence | P13: ='Points System'!Z81 | Q13: ='Points System'!O81 | R13: ='Points System'!D25 -> 0 | S13: ='Points System'!E95 -> 0
A14: Win | B14: ='Points System'!H40 -> 0 | C14: ='Points System'!I96 -> 0 | D14: ='Points System'!D26 -> 0 | E14: ='Points System'!Q40 -> 0 | H14: Win | I14: ='Points System'!T68 -> 0 | J14: ='Points System'!I26 -> 0 | K14: ='Points System'!D68 -> 0 | L14: ='Points System'!W26 -> 0 | O14: Win | P14: ='Points System'!Z82 -> 0 | Q14: ='Points System'!O82 -> 0 | R14: ='Points System'!D26 -> 0 | S14: ='Points System'!E96 -> 0
A15: Total | B15: =SUM(B4:B14) -> 0 | C15: =SUM(C4:C14) -> 0 | D15: =SUM(D4:D14) -> 0 | E15: =SUM(E4:E14) -> 0 | F15: =SUM(F4:F14) -> 0 | H15: Total | I15: =SUM(I4:I14) -> 0 | J15: =SUM(J4:J14) -> 0 | K15: =SUM(K4:K14) -> 0 | L15: =SUM(L4:L14) -> 0 | M15: =SUM(M4:M14) -> 0 | O15: Total | P15: =SUM(P4:P14) -> 101 | Q15: =SUM(Q4:Q14) -> 133 | R15: =SUM(R4:R14) -> 0 | S15: =SUM(S4:S14) -> 0 | T15: =SUM(T4:T14) -> 0
E16: Total: | F16: =SUM(B15:E15) -> 0 | L16: Total: | M16: =SUM(I15:L15) -> 0 | S16: Total: | T16: =SUM(P15:S15) -> 234
A17: Sab | H17: Ammyships | O17: Sonic
A18: Manager | B18: Runner | C18: Tank | D18: Defender | E18: Hybrid | F18: Sub | H18: Manager | I18: Runner | J18: Tank | K18: Defender | L18: Hybrid | M18: Sub | O18: Manager | P18: Runner | Q18: Tank | R18: Defender | S18: Hybrid | T18: Sub
A19: Sabasauros Rex | B19: Ming Crusader | C19: Saintz The God | D19: KDSkill | E19: Almighty Tycoon | F19: oUnique Rose | H19: The Texorcist | I19: Almighty Tycoon | J19: Saintz The God | K19: Invayda Zim | L19: PoisonxPoptart | M19: ST0P K1LLING ME | O19: SonicNachos | P19: The Eastbrook | Q19: ST0P K1LLING ME | R19: Ming Crusader | S19: Rage More Nerd | T19: Mr AboveAverage
A20: Goals | B20: ='Points System'!B58 -> 0 | C20: ='Points System'!I44 | D20: ='Points System'!V58 | E20: ='Points System'!AC72 -> 30 | F20: Z-AC30 | H20: Goals | I20: ='Points System'!Z30 -> 0 | J20: ='Points System'!I44 | K20: ='Points System'!J86 | L20: ='Points System'!W86 -> 0 | M20: TUVW30 | O20: Goals | P20: ='Points System'!N16 -> 0 | Q20: ='Points System'!U30 | R20: ='Points System'!D58 | S20: ='Points System'!E16 -> 0 | T20: Z-AC16
A21: Sword Kills | B21: ='Points System'!B59 | C21: ='Points System'!I45 | D21: ='Points System'!V59 -> 0 | E21: ='Points System'!AC73 | H21: Sword Kills | I21: ='Points System'!Z31 | J21: ='Points System'!I45 | K21: ='Points System'!J87 -> 0 | L21: ='Points System'!W87 | O21: Sword Kills | P21: ='Points System'!N17 | Q21: ='Points System'!U31 | R21: ='Points System'!D59 -> 0 | S21: ='Points System'!E17
A22: Ball Kills | B22: ='Points System'!B60 -> 0 | C22: ='Points System'!I46 | D22: ='Points System'!V60 | E22: ='Points System'!AC74 | H22: Ball Kills | I22: ='Points System'!Z32 -> 0 | J22: ='Points System'!I46 | K22: ='Points System'!J88 | L22: ='Points System'!W88 | O22: Ball Kills | P22: ='Points System'!N18 -> 0 | Q22: ='Points System'!U32 | R22: ='Points System'!D60 | S22: ='Points System'!E18
A23: KD Spread | B23: ='Points System'!B61 | C23: ='Points System'!I47 -> 116 | D23: ='Points System'!V61 | E23: ='Points System'!AC75 -> -32 | H23: KD Spread | I23: ='Points System'!Z33 | J23: ='Points System'!I47 -> 116 | K23: ='Points System'!J89 | L23: ='Points System'!W89 -> 0 | O23: KD Spread | P23: ='Points System'!N19 | Q23: ='Points System'!U33 -> 0 | R23: ='Points System'!D61 | S23: ='Points System'!E19 -> 0
A24: First Strike | B24: ='Points System'!B62 | C24: ='Points System'!I48 -> 0 | D24: ='Points System'!V62 | E24: ='Points System'!AC76 -> 0 | H24: First Strike | I24: ='Points System'!Z34 | J24: ='Points System'!I48 -> 0 | K24: ='Points System'!J90 | L24: ='Points System'!W90 -> 0 | O24: First Strike | P24: ='Points System'!N20 | Q24: ='Points System'!U34 -> 0 | R24: ='Points System'!D62 | S24: ='Points System'!E20 -> 0
A25: First Touch | B25: ='Points System'!B63 -> 0 | C25: ='Points System'!I49 | D25: ='Points System'!V63 -> 0 | E25: ='Points System'!AC77 | H25: First Touch | I25: ='Points System'!Z35 -> 0 | J25: ='Points System'!I49 | K25: ='Points System'!J91 -> 0 | L25: ='Points System'!W91 | O25: First Touch | P25: ='Points System'!N21 -> 0 | Q25: ='Points System'!U35 | R25: ='Points System'!D63 -> 0 | S25: ='Points System'!E21
A26: Multikill | B26: ='Points System'!B64 | C26: ='Points System'!I50 -> 61 | D26: ='Points System'!V64 | E26: ='Points System'!AC78 | H26: Multikill | I26: ='Points System'!Z36 | J26: ='Points System'!I50 -> 61 | K26: ='Points System'!J92 | L26: ='Points System'!W92 | O26: Multikill | P26: ='Points System'!N22 | Q26: ='Points System'!U36 -> 0 | R26: ='Points System'!D64 | S26: ='Points System'!E22
A27: Carrier Kill | B27: ='Points System'!B65 | C27: ='Points System'!I51 | D27: ='Points System'!V65 -> 0 | E27: ='Points System'!AC79 -> 40 | H27: Carrier Kill | I27: ='Points System'!Z37 | J27: ='Points System'!I51 | K27: ='Points System'!J93 -> 0 | L27: ='Points System'!W93 -> 0 | O27: Carrier Kill | P27: ='Points System'!N23 | Q27: ='Points System'!U37 | R27: ='Points System'!D65 -> 0 | S27: ='Points System'!E23 -> 0
A28: Goal Offence | B28: ='Points System'!B66 | C28: ='Points System'!I52 -> 18 | D28: ='Points System'!V66 | E28: ='Points System'!AC80 -> 10 | H28: Goal Offence | I28: ='Points System'!Z38 | J28: ='Points System'!I52 -> 18 | K28: ='Points System'!J94 | L28: ='Points System'!W94 -> 0 | O28: Goal Offence | P28: ='Points System'!N24 | Q28: ='Points System'!U38 -> 0 | R28: ='Points System'!D66 | S28: ='Points System'!E24 -> 0
A29: Goal Defence | B29: ='Points System'!B67 | C29: ='Points System'!I53 | D29: ='Points System'!V67 -> 0 | E29: ='Points System'!AC81 -> 8 | H29: Goal Defence | I29: ='Points System'!Z39 | J29: ='Points System'!I53 | K29: ='Points System'!J95 -> 0 | L29: ='Points System'!W95 -> 0 | O29: Goal Defence | P29: ='Points System'!N25 | Q29: ='Points System'!U39 | R29: ='Points System'!D67 -> 0 | S29: ='Points System'!E25 -> 0
A30: Win | B30: ='Points System'!B68 -> 0 | C30: ='Points System'!I54 -> 20 | D30: ='Points System'!V68 -> 0 | E30: ='Points System'!AC82 -> 0 | H30: Win | I30: ='Points System'!Z40 -> 0 | J30: ='Points System'!I54 -> 20 | K30: ='Points System'!J96 -> 0 | L30: ='Points System'!W96 -> 0 | O30: Win | P30: ='Points System'!N26 -> 0 | Q30: ='Points System'!U40 -> 0 | R30: ='Points System'!D68 -> 0 | S30: ='Points System'!E26 -> 0
A31: Total | B31: =SUM(B20:B30) -> 0 | C31: =SUM(C20:C30) -> 215 | D31: =SUM(D20:D30) -> 0 | E31: =SUM(E20:E30) -> 56 | F31: =SUM(F20:F30) -> 0 | H31: Total | I31: =SUM(I20:I30) -> 0 | J31: =SUM(J20:J30) -> 215 | K31: =SUM(K20:K30) -> 0 | L31: =SUM(L20:L30) -> 0 | M31: =SUM(M20:M30) -> 0 | O31: Total | P31: =SUM(P20:P30) -> 0 | Q31: =SUM(Q20:Q30) -> 0 | R31: =SUM(R20:R30) -> 0 | S31: =SUM(S20:S30) -> 0 | T31: =SUM(T20:T30) -> 0
E32: Total: | F32: =SUM(B31:E31) -> 271 | L32: Total: | M32: =SUM(I31:L31) -> 215 | S32: Total: | T32: =SUM(P31:S31) -> 0
A33: Sader's Tots | H33: KDSkill | O33: The Black List 2.0
A34: Manager | B34: Runner | C34: Tank | D34: Defender | E34: Hybrid | F34: Sub | H34: Manager | I34: Runner | J34: Tank | K34: Defender | L34: Hybrid | M34: Sub | O34: Manager | P34: Runner | Q34: Tank | R34: Defender | S34: Hybrid | T34: Sub
A35: Ming Crusader | B35: Ming Crusader | C35: DlGITAL PAIN | D35: DCleak | E35: The Piggies | F35: Almighty Tycoon | H35: KDSkill | I35: Almighty Tycoon | J35: Saintz The God | K35: KDSkill | L35: Rage More Nerd | M35: The Piggies | O35: ActiveHate | P35: Almighty Tycoon | Q35: DlGITAL PAIN | R35: NetsPride15 | S35: Ezy08 | T35: BCN19
A36: Goals | B36: ='Points System'!B58 -> 0 | C36: ='Points System'!O86 | D36: ='Points System'!P30 | E36: ='Points System'!E86 -> 0 | F36: Z-AC72 | H36: Goals | I36: ='Points System'!Z30 -> 0 | J36: ='Points System'!I44 | K36: ='Points System'!V58 | L36: ='Points System'!E16 -> 0 | M36: B-E86 | O36: Goals | P36: ='Points System'!Z30 -> 0 | Q36: ='Points System'!O86 | R36: ='Points System'!D44 | S36: ='Points System'!W72 -> 10 | T36: HIJK16
A37: Sword Kills | B37: ='Points System'!B59 | C37: ='Points System'!O87 | D37: ='Points System'!P31 -> 0 | E37: ='Points System'!E87 | H37: Sword Kills | I37: ='Points System'!Z31 | J37: ='Points System'!I45 | K37: ='Points System'!V59 -> 0 | L37: ='Points System'!E17 | O37: Sword Kills | P37: ='Points System'!Z31 | Q37: ='Points System'!O87 | R37: ='Points System'!D45 -> 3 | S37: ='Points System'!W73
A38: Ball Kills | B38: ='Points System'!B60 -> 0 | C38: ='Points System'!O88 | D38: ='Points System'!P32 | E38: ='Points System'!E88 | H38: Ball Kills | I38: ='Points System'!Z32 -> 0 | J38: ='Points System'!I46 | K38: ='Points System'!V60 | L38: ='Points System'!E18 | O38: Ball Kills | P38: ='Points System'!Z32 -> 0 | Q38: ='Points System'!O88 | R38: ='Points System'!D46 | S38: ='Points System'!W74
A39: KD Spread | B39: ='Points System'!B61 | C39: ='Points System'!O89 -> 0 | D39: ='Points System'!P33 | E39: ='Points System'!E89 -> 0 | H39: KD Spread | I39: ='Points System'!Z33 | J39: ='Points System'!I47 -> 116 | K39: ='Points System'!V61 | L39: ='Points System'!E19 -> 0 | O39: KD Spread | P39: ='Points System'!Z33 | Q39: ='Points System'!O89 -> 0 | R39: ='Points System'!D47 | S39: ='Points System'!W75 -> 1
A40: First Strike | B40: ='Points System'!B62 | C40: ='Points System'!O90 -> 0 | D40: ='Points System'!P34 | E40: ='Points System'!E90 -> 0 | H40: First Strike | I40: ='Points System'!Z34 | J40: ='Points System'!I48 -> 0 | K40: ='Points System'!V62 | L40: ='Points System'!E20 -> 0 | O40: First Strike | P40: ='Points System'!Z34 | Q40: ='Points System'!O90 -> 0 | R40: ='Points System'!D48 | S40: ='Points System'!W76 -> 0
...

Sheet Total Stats
N1: AGLA SL18 Stats
B2: Gamertag | C2: Played | D2: Goals | E2: Kills | F2: Deaths | G2: Hammer Kills | H2: Sword Kills | I2: Ball Kills | J2: Spread | K2: First Strike | L2: First Touch | M2: Multikill | N2: Carrier Kill | O2: Goal Offence | P2: Goal Defence | Q2: Win | S2: Runner | T2: Tank | U2: Defender | V2: Hybrid | W2: All
B3: Rage More Nerd | C3: ='W1 Stats'!C3+'W2 Stats'!C3+'W3 Stats'!C3+'W4 Stats'!C3 -> 0 | D3: ='W1 Stats'!D3+'W2 Stats'!D3+'W3 Stats'!D3+'W4 Stats'!D3 -> 0 | E3: ='W1 Stats'!E3+'W2 Stats'!E3+'W3 Stats'!E3+'W4 Stats'!E3 -> 0 | F3: ='W1 Stats'!F3+'W2 Stats'!F3+'W3 Stats'!F3+'W4 Stats'!F3 -> 0 | G3: ='W1 Stats'!G3+'W2 Stats'!G3+'W3 Stats'!G3+'W4 Stats'!G3 -> 0 | H3: ='W1 Stats'!H3+'W2 Stats'!H3+'W3 Stats'!H3+'W4 Stats'!H3 -> 0 | I3: ='W1 Stats'!I3+'W2 Stats'!I3+'W3 Stats'!I3+'W4 Stats'!I3 -> 0 | J3: ='W1 Stats'!J3+'W2 Stats'!J3+'W3 Stats'!J3+'W4 Stats'!J3 -> 0 | ... Q3: ='W1 Stats'!Q3+'W2 Stats'!Q3+'W3 Stats'!Q3+'W4 Stats'!Q3 -> 0 | S3: ='Points System'!B27 -> 0 | T3: ='Points System'!C27 -> 0 | U3: ='Points System'!D27 -> 0 | V3: ='Points System'!E27 -> 0 | W3: =SUM(S3:V3) -> 0
B4: BCN19 | C4: ='W1 Stats'!C4+'W2 Stats'!C4+'W3 Stats'!C4+'W4 Stats'!C4 -> 0 | D4: ='W1 Stats'!D4+'W2 Stats'!D4+'W3 Stats'!D4+'W4 Stats'!D4 -> 0 | E4: ='W1 Stats'!E4+'W2 Stats'!E4+'W3 Stats'!E4+'W4 Stats'!E4 -> 0 | F4: ='W1 Stats'!F4+'W2 Stats'!F4+'W3 Stats'!F4+'W4 Stats'!F4 -> 0 | G4: ='W1 Stats'!G4+'W2 Stats'!G4+'W3 Stats'!G4+'W4 Stats'!G4 -> 0 | H4: ='W1 Stats'!H4+'W2 Stats'!H4+'W3 Stats'!H4+'W4 Stats'!H4 -> 0 | I4: ='W1 Stats'!I4+'W2 Stats'!I4+'W3 Stats'!I4+'W4 Stats'!I4 -> 0 | J4: ='W1 Stats'!J4+'W2 Stats'!J4+'W3 Stats'!J4+'W4 Stats'!J4 -> 0 | ... Q4: ='W1 Stats'!Q4+'W2 Stats'!Q4+'W3 Stats'!Q4+'W4 Stats'!Q4 -> 0 | S4: ='Points System'!H27 -> 0 | T4: ='Points System'!I27 -> 0 | U4: ='Points System'!J27 -> 0 | V4: ='Points System'!K27 -> 0 | W4: =SUM(S4:V4) -> 0
B5: The Eastbrook | C5: ='W1 Stats'!C5+'W2 Stats'!C5+'W3 Stats'!C5+'W4 Stats'!C5 -> 0 | D5: ='W1 Stats'!D5+'W2 Stats'!D5+'W3 Stats'!D5+'W4 Stats'!D5 -> 0 | E5: ='W1 Stats'!E5+'W2 Stats'!E5+'W3 Stats'!E5+'W4 Stats'!E5 -> 0 | F5: ='W1 Stats'!F5+'W2 Stats'!F5+'W3 Stats'!F5+'W4 Stats'!F5 -> 0 | G5: ='W1 Stats'!G5+'W2 Stats'!G5+'W3 Stats'!G5+'W4 Stats'!G5 -> 0 | H5: ='W1 Stats'!H5+'W2 Stats'!H5+'W3 Stats'!H5+'W4 Stats'!H5 -> 0 | I5: ='W1 Stats'!I5+'W2 Stats'!I5+'W3 Stats'!I5+'W4 Stats'!I5 -> 0 | J5: ='W1 Stats'!J5+'W2 Stats'!J5+'W3 Stats'!J5+'W4 Stats'!J5 -> 0 | ... Q5: ='W1 Stats'!Q5+'W2 Stats'!Q5+'W3 Stats'!Q5+'W4 Stats'!Q5 -> 0 | S5: ='Points System'!N27 -> 0 | T5: ='Points System'!O27 -> 0 | U5: ='Points System'!P27 -> 0 | V5: ='Points System'!Q27 -> 0 | W5: =SUM(S5:V5) -> 0
B6: ThumpingHawk | C6: ='W1 Stats'!C6+'W2 Stats'!C6+'W3 Stats'!C6+'W4 Stats'!C6 -> 0 | D6: ='W1 Stats'!D6+'W2 Stats'!D6+'W3 Stats'!D6+'W4 Stats'!D6 -> 0 | E6: ='W1 Stats'!E6+'W2 Stats'!E6+'W3 Stats'!E6+'W4 Stats'!E6 -> 0 | F6: ='W1 Stats'!F6+'W2 Stats'!F6+'W3 Stats'!F6+'W4 Stats'!F6 -> 0 | G6: ='W1 Stats'!G6+'W2 Stats'!G6+'W3 Stats'!G6+'W4 Stats'!G6 -> 0 | H6: ='W1 Stats'!H6+'W2 Stats'!H6+'W3 Stats'!H6+'W4 Stats'!H6 -> 0 | I6: ='W1 Stats'!I6+'W2 Stats'!I6+'W3 Stats'!I6+'W4 Stats'!I6 -> 0 | J6: ='W1 Stats'!J6+'W2 Stats'!J6+'W3 Stats'!J6+'W4 Stats'!J6 -> 0 | ... Q6: ='W1 Stats'!Q6+'W2 Stats'!Q6+'W3 Stats'!Q6+'W4 Stats'!Q6 -> 0 | S6: ='Points System'!T27 -> 0 | T6: ='Points System'!U27 -> 0 | U6: ='Points System'!V27 -> 0 | V6: ='Points System'!W27 -> 0 | W6: =SUM(S6:V6) -> 0
B7: Mr Ab0veAverage | C7: ='W1 Stats'!C7+'W2 Stats'!C7+'W3 Stats'!C7+'W4 Stats'!C7 -> 0 | D7: ='W1 Stats'!D7+'W2 Stats'!D7+'W3 Stats'!D7+'W4 Stats'!D7 -> 0 | E7: ='W1 Stats'!E7+'W2 Stats'!E7+'W3 Stats'!E7+'W4 Stats'!E7 -> 0 | F7: ='W1 Stats'!F7+'W2 Stats'!F7+'W3 Stats'!F7+'W4 Stats'!F7 -> 0 | G7: ='W1 Stats'!G7+'W2 Stats'!G7+'W3 Stats'!G7+'W4 Stats'!G7 -> 0 | H7: ='W1 Stats'!H7+'W2 Stats'!H7+'W3 Stats'!H7+'W4 Stats'!H7 -> 0 | I7: ='W1 Stats'!I7+'W2 Stats'!I7+'W3 Stats'!I7+'W4 Stats'!I7 -> 0 | J7: ='W1 Stats'!J7+'W2 Stats'!J7+'W3 Stats'!J7+'W4 Stats'!J7 -> 0 | ... Q7: ='W1 Stats'!Q7+'W2 Stats'!Q7+'W3 Stats'!Q7+'W4 Stats'!Q7 -> 0 | S7: ='Points System'!Z27 -> 0 | T7: ='Points System'!AA27 -> 0 | U7: ='Points System'!AB27 -> 0 | V7: ='Points System'!AC27 -> 0 | W7: =SUM(S7:V7) -> 0
B8: InfiniteRainge | C8: ='W1 Stats'!C8+'W2 Stats'!C8+'W3 Stats'!C8+'W4 Stats'!C8 -> 0 | D8: ='W1 Stats'!D8+'W2 Stats'!D8+'W3 Stats'!D8+'W4 Stats'!D8 -> 0 | E8: ='W1 Stats'!E8+'W2 Stats'!E8+'W3 Stats'!E8+'W4 Stats'!E8 -> 0 | F8: ='W1 Stats'!F8+'W2 Stats'!F8+'W3 Stats'!F8+'W4 Stats'!F8 -> 0 | G8: ='W1 Stats'!G8+'W2 Stats'!G8+'W3 Stats'!G8+'W4 Stats'!G8 -> 0 | H8: ='W1 Stats'!H8+'W2 Stats'!H8+'W3 Stats'!H8+'W4 Stats'!H8 -> 0 | I8: ='W1 Stats'!I8+'W2 Stats'!I8+'W3 Stats'!I8+'W4 Stats'!I8 -> 0 | J8: ='W1 Stats'!J8+'W2 Stats'!J8+'W3 Stats'!J8+'W4 Stats'!J8 -> 0 | ... Q8: ='W1 Stats'!Q8+'W2 Stats'!Q8+'W3 Stats'!Q8+'W4 Stats'!Q8 -> 0 | S8: ='Points System'!B41 -> 0 | T8: ='Points System'!C41 -> 0 | U8: ='Points System'!D41 -> 0 | V8: ='Points System'!E41 -> 0 | W8: =SUM(S8:V8) -> 0
B9: ACE B S1lentND1 | C9: ='W1 Stats'!C9+'W2 Stats'!C9+'W3 Stats'!C9+'W4 Stats'!C9 -> 0 | D9: ='W1 Stats'!D9+'W2 Stats'!D9+'W3 Stats'!D9+'W4 Stats'!D9 -> 0 | E9: ='W1 Stats'!E9+'W2 Stats'!E9+'W3 Stats'!E9+'W4 Stats'!E9 -> 0 | F9: ='W1 Stats'!F9+'W2 Stats'!F9+'W3 Stats'!F9+'W4 Stats'!F9 -> 0 | G9: ='W1 Stats'!G9+'W2 Stats'!G9+'W3 Stats'!G9+'W4 Stats'!G9 -> 0 | H9: ='W1 Stats'!H9+'W2 Stats'!H9+'W3 Stats'!H9+'W4 Stats'!H9 -> 0 | I9: ='W1 Stats'!I9+'W2 Stats'!I9+'W3 Stats'!I9+'W4 Stats'!I9 -> 0 | J9: ='W1 Stats'!J9+'W2 Stats'!J9+'W3 Stats'!J9+'W4 Stats'!J9 -> 0 | ... Q9: ='W1 Stats'!Q9+'W2 Stats'!Q9+'W3 Stats'!Q9+'W4 Stats'!Q9 -> 0 | S9: ='Points System'!H41 -> 0 | T9: ='Points System'!I41 -> 0 | U9: ='Points System'!J41 -> 0 | V9: ='Points System'!K41 -> 0 | W9: =SUM(S9:V9) -> 0
B10: DCleak | C10: ='W1 Stats'!C10+'W2 Stats'!C10+'W3 Stats'!C10+'W4 Stats'!C10 -> 0 | D10: ='W1 Stats'!D10+'W2 Stats'!D10+'W3 Stats'!D10+'W4 Stats'!D10 -> 0 | E10: ='W1 Stats'!E10+'W2 Stats'!E10+'W3 Stats'!E10+'W4 Stats'!E10 -> 0 | F10: ='W1 Stats'!F10+'W2 Stats'!F10+'W3 Stats'!F10+'W4 Stats'!F10 -> 0 | G10: ='W1 Stats'!G10+'W2 Stats'!G10+'W3 Stats'!G10+'W4 Stats'!G10 -> 0 | H10: ='W1 Stats'!H10+'W2 Stats'!H10+'W3 Stats'!H10+'W4 Stats'!H10 -> 0 | I10: ='W1 Stats'!I10+'W2 Stats'!I10+'W3 Stats'!I10+'W4 Stats'!I10 -> 0 | J10: ='W1 Stats'!J10+'W2 Stats'!J10+'W3 Stats'!J10+'W4 Stats'!J10 -> 0 | ... Q10: ='W1 Stats'!Q10+'W2 Stats'!Q10+'W3 Stats'!Q10+'W4 Stats'!Q10 -> 0 | S10: ='Points System'!N41 -> 0 | T10: ='Points System'!O41 -> 0 | U10: ='Points System'!P41 -> 0 | V10: ='Points System'!Q41 -> 0 | W10: =SUM(S10:V10) -> 0
B11: ST0P K1LLING ME | C11: ='W1 Stats'!C11+'W2 Stats'!C11+'W3 Stats'!C11+'W4 Stats'!C11 -> 0 | D11: ='W1 Stats'!D11+'W2 Stats'!D11+'W3 Stats'!D11+'W4 Stats'!D11 -> 0 | E11: ='W1 Stats'!E11+'W2 Stats'!E11+'W3 Stats'!E11+'W4 Stats'!E11 -> 0 | F11: ='W1 Stats'!F11+'W2 Stats'!F11+'W3 Stats'!F11+'W4 Stats'!F11 -> 0 | G11: ='W1 Stats'!G11+'W2 Stats'!G11+'W3 Stats'!G11+'W4 Stats'!G11 -> 0 | H11: ='W1 Stats'!H11+'W2 Stats'!H11+'W3 Stats'!H11+'W4 Stats'!H11 -> 0 | I11: ='W1 Stats'!I11+'W2 Stats'!I11+'W3 Stats'!I11+'W4 Stats'!I11 -> 0 | J11: ='W1 Stats'!J11+'W2 Stats'!J11+'W3 Stats'!J11+'W4 Stats'!J11 -> 0 | ... Q11: ='W1 Stats'!Q11+'W2 Stats'!Q11+'W3 Stats'!Q11+'W4 Stats'!Q11 -> 0 | S11: ='Points System'!T41 -> 0 | T11: ='Points System'!U41 -> 0 | U11: ='Points System'!V41 -> 0 | V11: ='Points System'!W41 -> 0 | W11: =SUM(S11:V11) -> 0
B12: oUnique Rose | C12: ='W1 Stats'!C12+'W2 Stats'!C12+'W3 Stats'!C12+'W4 Stats'!C12 -> 0 | D12: ='W1 Stats'!D12+'W2 Stats'!D12+'W3 Stats'!D12+'W4 Stats'!D12 -> 0 | E12: ='W1 Stats'!E12+'W2 Stats'!E12+'W3 Stats'!E12+'W4 Stats'!E12 -> 0 | F12: ='W1 Stats'!F12+'W2 Stats'!F12+'W3 Stats'!F12+'W4 Stats'!F12 -> 0 | G12: ='W1 Stats'!G12+'W2 Stats'!G12+'W3 Stats'!G12+'W4 Stats'!G12 -> 0 | H12: ='W1 Stats'!H12+'W2 Stats'!H12+'W3 Stats'!H12+'W4 Stats'!H12 -> 0 | I12: ='W1 Stats'!I12+'W2 Stats'!I12+'W3 Stats'!I12+'W4 Stats'!I12 -> 0 | J12: ='W1 Stats'!J12+'W2 Stats'!J12+'W3 Stats'!J12+'W4 Stats'!J12 -> 0 | ... Q12: ='W1 Stats'!Q12+'W2 Stats'!Q12+'W3 Stats'!Q12+'W4 Stats'!Q12 -> 0 | S12: ='Points System'!Z41 -> 0 | T12: ='Points System'!AA41 -> 0 | U12: ='Points System'!AB41 -> 0 | V12: ='Points System'!AC41 -> 0 | W12: =SUM(S12:V12) -> 0
B13: NetsPride15 | C13: ='W1 Stats'!C13+'W2 Stats'!C13+'W3 Stats'!C13+'W4 Stats'!C13 -> 1 | D13: ='W1 Stats'!D13+'W2 Stats'!D13+'W3 Stats'!D13+'W4 Stats'!D13 -> 1 | E13: ='W1 Stats'!E13+'W2 Stats'!E13+'W3 Stats'!E13+'W4 Stats'!E13 -> 187 | F13: ='W1 Stats'!F13+'W2 Stats'!F13+'W3 Stats'!F13+'W4 Stats'!F13 -> 217 | G13: ='W1 Stats'!G13+'W2 Stats'!G13+'W3 Stats'!G13+'W4 Stats'!G13 -> 183 | H13: ='W1 Stats'!H13+'W2 Stats'!H13+'W3 Stats'!H13+'W4 Stats'!H13 -> 3 | I13: ='W1 Stats'!I13+'W2 Stats'!I13+'W3 Stats'!I13+'W4 Stats'!I13 -> 1 | J13: ='W1 Stats'!J13+'W2 Stats'!J13+'W3 Stats'!J13+'W4 Stats'!J13 -> -30 | ... Q13: ='W1 Stats'!Q13+'W2 Stats'!Q13+'W3 Stats'!Q13+'W4 Stats'!Q13 -> 1 | S13: ='Points System'!B55 -> 37 | T13: ='Points System'!C55 -> 71 | U13: ='Points System'!D55 -> 89 | V13: ='Points System'!E55 -> 81 | W13: =SUM(S13:V13) -> 278
B14: Saintz The God | C14: ='W1 Stats'!C14+'W2 Stats'!C14+'W3 Stats'!C14+'W4 Stats'!C14 -> 1 | D14: ='W1 Stats'!D14+'W2 Stats'!D14+'W3 Stats'!D14+'W4 Stats'!D14 -> 0 | E14: ='W1 Stats'!E14+'W2 Stats'!E14+'W3 Stats'!E14+'W4 Stats'!E14 -> 218 | F14: ='W1 Stats'!F14+'W2 Stats'!F14+'W3 Stats'!F14+'W4 Stats'!F14 -> 160 | G14: ='W1 Stats'!G14+'W2 Stats'!G14+'W3 Stats'!G14+'W4 Stats'!G14 -> 195 | H14: ='W1 Stats'!H14+'W2 Stats'!H14+'W3 Stats'!H14+'W4 Stats'!H14 -> 15 | I14: ='W1 Stats'!I14+'W2 Stats'!I14+'W3 Stats'!I14+'W4 Stats'!I14 -> 8 | J14: ='W1 Stats'!J14+'W2 Stats'!J14+'W3 Stats'!J14+'W4 Stats'!J14 -> 58 | ... Q14: ='W1 Stats'!Q14+'W2 Stats'!Q14+'W3 Stats'!Q14+'W4 Stats'!Q14 -> 1 | S14: ='Points System'!H55 -> 81 | T14: ='Points System'!I55 -> 215 | U14: ='Points System'!J55 -> 176 | V14: ='Points System'!K55 -> 174 | W14: =SUM(S14:V14) -> 646
B15: Silva | C15: ='W1 Stats'!C15+'W2 Stats'!C15+'W3 Stats'!C15+'W4 Stats'!C15 -> 1 | D15: ='W1 Stats'!D15+'W2 Stats'!D15+'W3 Stats'!D15+'W4 Stats'!D15 -> 4 | E15: ='W1 Stats'!E15+'W2 Stats'!E15+'W3 Stats'!E15+'W4 Stats'!E15 -> 120 | F15: ='W1 Stats'!F15+'W2 Stats'!F15+'W3 Stats'!F15+'W4 Stats'!F15 -> 117 | G15: ='W1 Stats'!G15+'W2 Stats'!G15+'W3 Stats'!G15+'W4 Stats'!G15 -> 75 | H15: ='W1 Stats'!H15+'W2 Stats'!H15+'W3 Stats'!H15+'W4 Stats'!H15 -> 23 | I15: ='W1 Stats'!I15+'W2 Stats'!I15+'W3 Stats'!I15+'W4 Stats'!I15 -> 22 | J15: ='W1 Stats'!J15+'W2 Stats'!J15+'W3 Stats'!J15+'W4 Stats'!J15 -> 3 | ... Q15: ='W1 Stats'!Q15+'W2 Stats'!Q15+'W3 Stats'!Q15+'W4 Stats'!Q15 -> 1 | S15: ='Points System'!N55 -> 169 | T15: ='Points System'!O55 -> 73 | U15: ='Points System'!P55 -> 82 | V15: ='Points System'!Q55 -> 91 | W15: =SUM(S15:V15) -> 415
B16: AJ DaJuiceMayne | C16: ='W1 Stats'!C16+'W2 Stats'!C16+'W3 Stats'!C16+'W4 Stats'!C16 -> 1 | D16: ='W1 Stats'!D16+'W2 Stats'!D16+'W3 Stats'!D16+'W4 Stats'!D16 -> 0 | E16: ='W1 Stats'!E16+'W2 Stats'!E16+'W3 Stats'!E16+'W4 Stats'!E16 -> 160 | F16: ='W1 Stats'!F16+'W2 Stats'!F16+'W3 Stats'!F16+'W4 Stats'!F16 -> 173 | G16: ='W1 Stats'!G16+'W2 Stats'!G16+'W3 Stats'!G16+'W4 Stats'!G16 -> 156 | H16: ='W1 Stats'!H16+'W2 Stats'!H16+'W3 Stats'!H16+'W4 Stats'!H16 -> 4 | I16: ='W1 Stats'!I16+'W2 Stats'!I16+'W3 Stats'!I16+'W4 Stats'!I16 -> 0 | J16: ='W1 Stats'!J16+'W2 Stats'!J16+'W3 Stats'!J16+'W4 Stats'!J16 -> -13 | ... Q16: ='W1 Stats'!Q16+'W2 Stats'!Q16+'W3 Stats'!Q16+'W4 Stats'!Q16 -> 1 | S16: ='Points System'!T55 -> 20 | T16: ='Points System'!U55 -> 45 | U16: ='Points System'!V55 -> 69 | V16: ='Points System'!W55 -> 49 | W16: =SUM(S16:V16) -> 183
B17: El Diablo X230X | C17: ='W1 Stats'!C17+'W2 Stats'!C17+'W3 Stats'!C17+'W4 Stats'!C17 -> 0 | D17: ='W1 Stats'!D17+'W2 Stats'!D17+'W3 Stats'!D17+'W4 Stats'!D17 -> 0 | E17: ='W1 Stats'!E17+'W2 Stats'!E17+'W3 Stats'!E17+'W4 Stats'!E17 -> 0 | F17: ='W1 Stats'!F17+'W2 Stats'!F17+'W3 Stats'!F17+'W4 Stats'!F17 -> 0 | G17: ='W1 Stats'!G17+'W2 Stats'!G17+'W3 Stats'!G17+'W4 Stats'!G17 -> 0 | H17: ='W1 Stats'!H17+'W2 Stats'!H17+'W3 Stats'!H17+'W4 Stats'!H17 -> 0 | I17: ='W1 Stats'!I17+'W2 Stats'!I17+'W3 Stats'!I17+'W4 Stats'!I17 -> 0 | J17: ='W1 Stats'!J17+'W2 Stats'!J17+'W3 Stats'!J17+'W4 Stats'!J17 -> 0 | ... Q17: ='W1 Stats'!Q17+'W2 Stats'!Q17+'W3 Stats'!Q17+'W4 Stats'!Q17 -> 0 | S17: ='Points System'!Z55 -> 0 | T17: ='Points System'!AA55 -> 0 | U17: ='Points System'!AB55 -> 0 | V17: ='Points System'!AC55 -> 0 | W17: =SUM(S17:V17) -> 0
B18: Ming Crusader | C18: ='W1 Stats'!C18+'W2 Stats'!C18+'W3 Stats'!C18+'W4 Stats'!C18 -> 0 | D18: ='W1 Stats'!D18+'W2 Stats'!D18+'W3 Stats'!D18+'W4 Stats'!D18 -> 0 | E18: ='W1 Stats'!E18+'W2 Stats'!E18+'W3 Stats'!E18+'W4 Stats'!E18 -> 0 | F18: ='W1 Stats'!F18+'W2 Stats'!F18+'W3 Stats'!F18+'W4 Stats'!F18 -> 0 | G18: ='W1 Stats'!G18+'W2 Stats'!G18+'W3 Stats'!G18+'W4 Stats'!G18 -> 0 | H18: ='W1 Stats'!H18+'W2 Stats'!H18+'W3 Stats'!H18+'W4 Stats'!H18 -> 0 | I18: ='W1 Stats'!I18+'W2 Stats'!I18+'W3 Stats'!I18+'W4 Stats'!I18 -> 0 | J18: ='W1 Stats'!J18+'W2 Stats'!J18+'W3 Stats'!J18+'W4 Stats'!J18 -> 0 | ... Q18: ='W1 Stats'!Q18+'W2 Stats'!Q18+'W3 Stats'!Q18+'W4 Stats'!Q18 -> 0 | S18: ='Points System'!B69 -> 0 | T18: ='Points System'!C69 -> 0 | U18: ='Points System'!D69 -> 0 | V18: ='Points System'!E69 -> 0 | W18: =SUM(S18:V18) -> 0
B19: Sabasauros Rex | C19: ='W1 Stats'!C19+'W2 Stats'!C19+'W3 Stats'!C19+'W4 Stats'!C19 -> 0 | D19: ='W1 Stats'!D19+'W2 Stats'!D19+'W3 Stats'!D19+'W4 Stats'!D19 -> 0 | E19: ='W1 Stats'!E19+'W2 Stats'!E19+'W3 Stats'!E19+'W4 Stats'!E19 -> 0 | F19: ='W1 Stats'!F19+'W2 Stats'!F19+'W3 Stats'!F19+'W4 Stats'!F19 -> 0 | G19: ='W1 Stats'!G19+'W2 Stats'!G19+'W3 Stats'!G19+'W4 Stats'!G19 -> 0 | H19: ='W1 Stats'!H19+'W2 Stats'!H19+'W3 Stats'!H19+'W4 Stats'!H19 -> 0 | I19: ='W1 Stats'!I19+'W2 Stats'!I19+'W3 Stats'!I19+'W4 Stats'!I19 -> 0 | J19: ='W1 Stats'!J19+'W2 Stats'!J19+'W3 Stats'!J19+'W4 Stats'!J19 -> 0 | ... Q19: ='W1 Stats'!Q19+'W2 Stats'!Q19+'W3 Stats'!Q19+'W4 Stats'!Q19 -> 0 | S19: ='Points System'!H69 -> 0 | T19: ='Points System'!I69 -> 0 | U19: ='Points System'!J69 -> 0 | V19: ='Points System'!K69 -> 0 | W19: =SUM(S19:V19) -> 0
B20: Jeakilla85 | C20: ='W1 Stats'!C20+'W2 Stats'!C20+'W3 Stats'!C20+'W4 Stats'!C20 -> 0 | D20: ='W1 Stats'!D20+'W2 Stats'!D20+'W3 Stats'!D20+'W4 Stats'!D20 -> 0 | E20: ='W1 Stats'!E20+'W2 Stats'!E20+'W3 Stats'!E20+'W4 Stats'!E20 -> 0 | F20: ='W1 Stats'!F20+'W2 Stats'!F20+'W3 Stats'!F20+'W4 Stats'!F20 -> 0 | G20: ='W1 Stats'!G20+'W2 Stats'!G20+'W3 Stats'!G20+'W4 Stats'!G20 -> 0 | H20: ='W1 Stats'!H20+'W2 Stats'!H20+'W3 Stats'!H20+'W4 Stats'!H20 -> 0 | I20: ='W1 Stats'!I20+'W2 Stats'!I20+'W3 Stats'!I20+'W4 Stats'!I20 -> 0 | J20: ='W1 Stats'!J20+'W2 Stats'!J20+'W3 Stats'!J20+'W4 Stats'!J20 -> 0 | ... Q20: ='W1 Stats'!Q20+'W2 Stats'!Q20+'W3 Stats'!Q20+'W4 Stats'!Q20 -> 0 | S20: ='Points System'!N69 -> 0 | T20: ='Points System'!O69 -> 0 | U20: ='Points System'!P69 -> 0 | V20: ='Points System'!Q69 -> 0 | W20: =SUM(S20:V20) -> 0
B21: KDSkill | C21: ='W1 Stats'!C21+'W2 Stats'!C21+'W3 Stats'!C21+'W4 Stats'!C21 -> 0 | D21: ='W1 Stats'!D21+'W2 Stats'!D21+'W3 Stats'!D21+'W4 Stats'!D21 -> 0 | E21: ='W1 Stats'!E21+'W2 Stats'!E21+'W3 Stats'!E21+'W4 Stats'!E21 -> 0 | F21: ='W1 Stats'!F21+'W2 Stats'!F21+'W3 Stats'!F21+'W4 Stats'!F21 -> 0 | G21: ='W1 Stats'!G21+'W2 Stats'!G21+'W3 Stats'!G21+'W4 Stats'!G21 -> 0 | H21: ='W1 Stats'!H21+'W2 Stats'!H21+'W3 Stats'!H21+'W4 Stats'!H21 -> 0 | I21: ='W1 Stats'!I21+'W2 Stats'!I21+'W3 Stats'!I21+'W4 Stats'!I21 -> 0 | J21: ='W1 Stats'!J21+'W2 Stats'!J21+'W3 Stats'!J21+'W4 Stats'!J21 -> 0 | ... Q21: ='W1 Stats'!Q21+'W2 Stats'!Q21+'W3 Stats'!Q21+'W4 Stats'!Q21 -> 0 | S21: ='Points System'!T69 -> 0 | T21: ='Points System'!U69 -> 0 | U21: ='Points System'!V69 -> 0 | V21: ='Points System'!W69 -> 0 | W21: =SUM(S21:V21) -> 0
B22: Myst The Cold | C22: ='W1 Stats'!C22+'W2 Stats'!C22+'W3 Stats'!C22+'W4 Stats'!C22 -> 0 | D22: ='W1 Stats'!D22+'W2 Stats'!D22+'W3 Stats'!D22+'W4 Stats'!D22 -> 0 | E22: ='W1 Stats'!E22+'W2 Stats'!E22+'W3 Stats'!E22+'W4 Stats'!E22 -> 0 | F22: ='W1 Stats'!F22+'W2 Stats'!F22+'W3 Stats'!F22+'W4 Stats'!F22 -> 0 | G22: ='W1 Stats'!G22+'W2 Stats'!G22+'W3 Stats'!G22+'W4 Stats'!G22 -> 0 | H22: ='W1 Stats'!H22+'W2 Stats'!H22+'W3 Stats'!H22+'W4 Stats'!H22 -> 0 | I22: ='W1 Stats'!I22+'W2 Stats'!I22+'W3 Stats'!I22+'W4 Stats'!I22 -> 0 | J22: ='W1 Stats'!J22+'W2 Stats'!J22+'W3 Stats'!J22+'W4 Stats'!J22 -> 0 | ... Q22: ='W1 Stats'!Q22+'W2 Stats'!Q22+'W3 Stats'!Q22+'W4 Stats'!Q22 -> 0 | S22: ='Points System'!Z69 -> 0 | T22: ='Points System'!AA69 -> 0 | U22: ='Points System'!AB69 -> 0 | V22: ='Points System'!AC69 -> 0 | W22: =SUM(S22:V22) -> 0
B23: KING RICKXL | C23: ='W1 Stats'!C23+'W2 Stats'!C23+'W3 Stats'!C23+'W4 Stats'!C23 -> 0 | D23: ='W1 Stats'!D23+'W2 Stats'!D23+'W3 Stats'!D23+'W4 Stats'!D23 -> 0 | E23: ='W1 Stats'!E23+'W2 Stats'!E23+'W3 Stats'!E23+'W4 Stats'!E23 -> 0 | F23: ='W1 Stats'!F23+'W2 Stats'!F23+'W3 Stats'!F23+'W4 Stats'!F23 -> 0 | G23: ='W1 Stats'!G23+'W2 Stats'!G23+'W3 Stats'!G23+'W4 Stats'!G23 -> 0 | H23: ='W1 Stats'!H23+'W2 Stats'!H23+'W3 Stats'!H23+'W4 Stats'!H23 -> 0 | I23: ='W1 Stats'!I23+'W2 Stats'!I23+'W3 Stats'!I23+'W4 Stats'!I23 -> 0 | J23: ='W1 Stats'!J23+'W2 Stats'!J23+'W3 Stats'!J23+'W4 Stats'!J23 -> 0 | ... Q23: ='W1 Stats'!Q23+'W2 Stats'!Q23+'W3 Stats'!Q23+'W4 Stats'!Q23 -> 0 | S23: ='Points System'!B83 -> 0 | T23: ='Points System'!C83 -> 0 | U23: ='Points System'!D83 -> 0 | V23: ='Points System'!E83 -> 0 | W23: =SUM(S23:V23) -> 0
B24: Galvann | C24: ='W1 Stats'!C24+'W2 Stats'!C24+'W3 Stats'!C24+'W4 Stats'!C24 -> 1 | D24: ='W1 Stats'!D24+'W2 Stats'!D24+'W3 Stats'!D24+'W4 Stats'!D24 -> 0 | E24: ='W1 Stats'!E24+'W2 Stats'!E24+'W3 Stats'!E24+'W4 Stats'!E24 -> 168 | F24: ='W1 Stats'!F24+'W2 Stats'!F24+'W3 Stats'!F24+'W4 Stats'!F24 -> 210 | G24: ='W1 Stats'!G24+'W2 Stats'!G24+'W3 Stats'!G24+'W4 Stats'!G24 -> 154 | H24: ='W1 Stats'!H24+'W2 Stats'!H24+'W3 Stats'!H24+'W4 Stats'!H24 -> 12 | I24: ='W1 Stats'!I24+'W2 Stats'!I24+'W3 Stats'!I24+'W4 Stats'!I24 -> 2 | J24: ='W1 Stats'!J24+'W2 Stats'!J24+'W3 Stats'!J24+'W4 Stats'!J24 -> -42 | ... Q24: ='W1 Stats'!Q24+'W2 Stats'!Q24+'W3 Stats'!Q24+'W4 Stats'!Q24 -> 0 | S24: N/A | T24: N/A | U24: N/A | V24: N/A | W24: N/A
B25: imShad | C25: ='W1 Stats'!C25+'W2 Stats'!C25+'W3 Stats'!C25+'W4 Stats'!C25 -> 0 | D25: ='W1 Stats'!D25+'W2 Stats'!D25+'W3 Stats'!D25+'W4 Stats'!D25 -> 0 | E25: ='W1 Stats'!E25+'W2 Stats'!E25+'W3 Stats'!E25+'W4 Stats'!E25 -> 0 | F25: ='W1 Stats'!F25+'W2 Stats'!F25+'W3 Stats'!F25+'W4 Stats'!F25 -> 0 | G25: ='W1 Stats'!G25+'W2 Stats'!G25+'W3 Stats'!G25+'W4 Stats'!G25 -> 0 | H25: ='W1 Stats'!H25+'W2 Stats'!H25+'W3 Stats'!H25+'W4 Stats'!H25 -> 0 | I25: ='W1 Stats'!I25+'W2 Stats'!I25+'W3 Stats'!I25+'W4 Stats'!I25 -> 0 | J25: ='W1 Stats'!J25+'W2 Stats'!J25+'W3 Stats'!J25+'W4 Stats'!J25 -> 0 | ... Q25: ='W1 Stats'!Q25+'W2 Stats'!Q25+'W3 Stats'!Q25+'W4 Stats'!Q25 -> 0 | S25: ='Points System'!H83 -> 0 | T25: ='Points System'!I83 -> 0 | U25: ='Points System'!J83 -> 0 | V25: ='Points System'!K83 -> 0 | W25: =SUM(S25:V25) -> 0
B26: ixGingy | C26: ='W1 Stats'!C26+'W2 Stats'!C26+'W3 Stats'!C26+'W4 Stats'!C26 -> 1 | D26: ='W1 Stats'!D26+'W2 Stats'!D26+'W3 Stats'!D26+'W4 Stats'!D26 -> 0 | E26: ='W1 Stats'!E26+'W2 Stats'!E26+'W3 Stats'!E26+'W4 Stats'!E26 -> 199 | F26: ='W1 Stats'!F26+'W2 Stats'!F26+'W3 Stats'!F26+'W4 Stats'!F26 -> 184 | G26: ='W1 Stats'!G26+'W2 Stats'!G26+'W3 Stats'!G26+'W4 Stats'!G26 -> 183 | H26: ='W1 Stats'!H26+'W2 Stats'!H26+'W3 Stats'!H26+'W4 Stats'!H26 -> 15 | I26: ='W1 Stats'!I26+'W2 Stats'!I26+'W3 Stats'!I26+'W4 Stats'!I26 -> 1 | J26: ='W1 Stats'!J26+'W2 Stats'!J26+'W3 Stats'!J26+'W4 Stats'!J26 -> 15 | ... Q26: ='W1 Stats'!Q26+'W2 Stats'!Q26+'W3 Stats'!Q26+'W4 Stats'!Q26 -> 0 | S26: ='Points System'!N83 -> 2 | T26: ='Points System'!O83 -> 133 | U26: ='Points System'!P83 -> 72 | V26: ='Points System'!Q83 -> 82 | W26: =SUM(S26:V26) -> 289
B27: Ezy08 | C27: ='W1 Stats'!C27+'W2 Stats'!C27+'W3 Stats'!C27+'W4 Stats'!C27 -> 1 | D27: ='W1 Stats'!D27+'W2 Stats'!D27+'W3 Stats'!D27+'W4 Stats'!D27 -> 1 | E27: ='W1 Stats'!E27+'W2 Stats'!E27+'W3 Stats'!E27+'W4 Stats'!E27 -> 167 | F27: ='W1 Stats'!F27+'W2 Stats'!F27+'W3 Stats'!F27+'W4 Stats'!F27 -> 166 | G27: ='W1 Stats'!G27+'W2 Stats'!G27+'W3 Stats'!G27+'W4 Stats'!G27 -> 153 | H27: ='W1 Stats'!H27+'W2 Stats'!H27+'W3 Stats'!H27+'W4 Stats'!H27 -> 11 | I27: ='W1 Stats'!I27+'W2 Stats'!I27+'W3 Stats'!I27+'W4 Stats'!I27 -> 3 | J27: ='W1 Stats'!J27+'W2 Stats'!J27+'W3 Stats'!J27+'W4 Stats'!J27 -> 1 | ... Q27: ='W1 Stats'!Q27+'W2 Stats'!Q27+'W3 Stats'!Q27+'W4 Stats'!Q27 -> 0 | S27: ='Points System'!T83 -> 36 | T27: ='Points System'!U83 -> 84 | U27: ='Points System'!V83 -> 40 | V27: ='Points System'!W83 -> 57 | W27: =SUM(S27:V27) -> 217
B28: Almighty Tycoon | C28: ='W1 Stats'!C28+'W2 Stats'!C28+'W3 Stats'!C28+'W4 Stats'!C28 -> 1 | D28: ='W1 Stats'!D28+'W2 Stats'!D28+'W3 Stats'!D28+'W4 Stats'!D28 -> 3 | E28: ='W1 Stats'!E28+'W2 Stats'!E28+'W3 Stats'!E28+'W4 Stats'!E28 -> 111 | F28: ='W1 Stats'!F28+'W2 Stats'!F28+'W3 Stats'!F28+'W4 Stats'!F28 -> 143 | G28: ='W1 Stats'!G28+'W2 Stats'!G28+'W3 Stats'!G28+'W4 Stats'!G28 -> 83 | H28: ='W1 Stats'!H28+'W2 Stats'!H28+'W3 Stats'!H28+'W4 Stats'!H28 -> 15 | I28: ='W1 Stats'!I28+'W2 Stats'!I28+'W3 Stats'!I28+'W4 Stats'!I28 -> 13 | J28: ='W1 Stats'!J28+'W2 Stats'!J28+'W3 Stats'!J28+'W4 Stats'!J28 -> -32 | ... Q28: ='W1 Stats'!Q28+'W2 Stats'!Q28+'W3 Stats'!Q28+'W4 Stats'!Q28 -> 0 | S28: ='Points System'!Z83 -> 101 | T28: ='Points System'!AA83 -> -29 | U28: ='Points System'!AB83 -> 97 | V28: ='Points System'!AC83 -> 56 | W28: =SUM(S28:V28) -> 225
B29: The Piggies | C29: ='W1 Stats'!C29+'W2 Stats'!C29+'W3 Stats'!C29+'W4 Stats'!C29 -> 0 | D29: ='W1 Stats'!D29+'W2 Stats'!D29+'W3 Stats'!D29+'W4 Stats'!D29 -> 0 | E29: ='W1 Stats'!E29+'W2 Stats'!E29+'W3 Stats'!E29+'W4 Stats'!E29 -> 0 | F29: ='W1 Stats'!F29+'W2 Stats'!F29+'W3 Stats'!F29+'W4 Stats'!F29 -> 0 | G29: ='W1 Stats'!G29+'W2 Stats'!G29+'W3 Stats'!G29+'W4 Stats'!G29 -> 0 | H29: ='W1 Stats'!H29+'W2 Stats'!H29+'W3 Stats'!H29+'W4 Stats'!H29 -> 0 | I29: ='W1 Stats'!I29+'W2 Stats'!I29+'W3 Stats'!I29+'W4 Stats'!I29 -> 0 | J29: ='W1 Stats'!J29+'W2 Stats'!J29+'W3 Stats'!J29+'W4 Stats'!J29 -> 0 | ... Q29: ='W1 Stats'!Q29+'W2 Stats'!Q29+'W3 Stats'!Q29+'W4 Stats'!Q29 -> 0 | S29: ='Points System'!B97 -> 0 | T29: ='Points System'!C97 -> 0 | U29: ='Points System'!D97 -> 0 | V29: ='Points System'!E97 -> 0 | W29: =SUM(S29:V29) -> 0
B30: Invayda Zim | C30: ='W1 Stats'!C30+'W2 Stats'!C30+'W3 Stats'!C30+'W4 Stats'!C30 -> 0 | D30: ='W1 Stats'!D30+'W2 Stats'!D30+'W3 Stats'!D30+'W4 Stats'!D30 -> 0 | E30: ='W1 Stats'!E30+'W2 Stats'!E30+'W3 Stats'!E30+'W4 Stats'!E30 -> 0 | F30: ='W1 Stats'!F30+'W2 Stats'!F30+'W3 Stats'!F30+'W4 Stats'!F30 -> 0 | G30: ='W1 Stats'!G30+'W2 Stats'!G30+'W3 Stats'!G30+'W4 Stats'!G30 -> 0 | H30: ='W1 Stats'!H30+'W2 Stats'!H30+'W3 Stats'!H30+'W4 Stats'!H30 -> 0 | I30: ='W1 Stats'!I30+'W2 Stats'!I30+'W3 Stats'!I30+'W4 Stats'!I30 -> 0 | J30: ='W1 Stats'!J30+'W2 Stats'!J30+'W3 Stats'!J30+'W4 Stats'!J30 -> 0 | ... Q30: ='W1 Stats'!Q30+'W2 Stats'!Q30+'W3 Stats'!Q30+'W4 Stats'!Q30 -> 0 | S30: ='Points System'!H97 -> 0 | T30: ='Points System'!I97 -> 0 | U30: ='Points System'!J97 -> 0 | V30: ='Points System'!K97 -> 0 | W30: =SUM(S30:V30) -> 0
B31: DlGITAL PAIN | C31: ='W1 Stats'!C31+'W2 Stats'!C31+'W3 Stats'!C31+'W4 Stats'!C31 -> 0 | D31: ='W1 Stats'!D31+'W2 Stats'!D31+'W3 Stats'!D31+'W4 Stats'!D31 -> 0 | E31: ='W1 Stats'!E31+'W2 Stats'!E31+'W3 Stats'!E31+'W4 Stats'!E31 -> 0 | F31: ='W1 Stats'!F31+'W2 Stats'!F31+'W3 Stats'!F31+'W4 Stats'!F31 -> 0 | G31: ='W1 Stats'!G31+'W2 Stats'!G31+'W3 Stats'!G31+'W4 Stats'!G31 -> 0 | H31: ='W1 Stats'!H31+'W2 Stats'!H31+'W3 Stats'!H31+'W4 Stats'!H31 -> 0 | I31: ='W1 Stats'!I31+'W2 Stats'!I31+'W3 Stats'!I31+'W4 Stats'!I31 -> 0 | J31: ='W1 Stats'!J31+'W2 Stats'!J31+'W3 Stats'!J31+'W4 Stats'!J31 -> 0 | ... Q31: ='W1 Stats'!Q31+'W2 Stats'!Q31+'W3 Stats'!Q31+'W4 Stats'!Q31 -> 0 | S31: ='Points System'!N97 -> 0 | T31: ='Points System'!O97 -> 0 | U31: ='Points System'!P97 -> 0 | V31: ='Points System'!Q97 -> 0 | W31: =SUM(S31:V31) -> 0
B32: PoisonxPoptart | C32: ='W1 Stats'!C32+'W2 Stats'!C32+'W3 Stats'!C32+'W4 Stats'!C32 -> 0 | D32: ='W1 Stats'!D32+'W2 Stats'!D32+'W3 Stats'!D32+'W4 Stats'!D32 -> 0 | E32: ='W1 Stats'!E32+'W2 Stats'!E32+'W3 Stats'!E32+'W4 Stats'!E32 -> 0 | F32: ='W1 Stats'!F32+'W2 Stats'!F32+'W3 Stats'!F32+'W4 Stats'!F32 -> 0 | G32: ='W1 Stats'!G32+'W2 Stats'!G32+'W3 Stats'!G32+'W4 Stats'!G32 -> 0 | H32: ='W1 Stats'!H32+'W2 Stats'!H32+'W3 Stats'!H32+'W4 Stats'!H32 -> 0 | I32: ='W1 Stats'!I32+'W2 Stats'!I32+'W3 Stats'!I32+'W4 Stats'!I32 -> 0 | J32: ='W1 Stats'!J32+'W2 Stats'!J32+'W3 Stats'!J32+'W4 Stats'!J32 -> 0 | ... Q32: ='W1 Stats'!Q32+'W2 Stats'!Q32+'W3 Stats'!Q32+'W4 Stats'!Q32 -> 0 | S32: ='Points System'!T97 -> 0 | T32: ='Points System'!U97 -> 0 | U32: ='Points System'!V97 -> 0 | V32: ='Points System'!W97 -> 0 | W32: =SUM(S32:V32) -> 0
B33: Mang Canon | C33: ='W1 Stats'!C33+'W2 Stats'!C33+'W3 Stats'!C33+'W4 Stats'!C33 -> 0 | D33: ='W1 Stats'!D33+'W2 Stats'!D33+'W3 Stats'!D33+'W4 Stats'!D33 -> 0 | E33: ='W1 Stats'!E33+'W2 Stats'!E33+'W3 Stats'!E33+'W4 Stats'!E33 -> 0 | F33: ='W1 Stats'!F33+'W2 Stats'!F33+'W3 Stats'!F33+'W4 Stats'!F33 -> 0 | G33: ='W1 Stats'!G33+'W2 Stats'!G33+'W3 Stats'!G33+'W4 Stats'!G33 -> 0 | H33: ='W1 Stats'!H33+'W2 Stats'!H33+'W3 Stats'!H33+'W4 Stats'!H33 -> 0 | I33: ='W1 Stats'!I33+'W2 Stats'!I33+'W3 Stats'!I33+'W4 Stats'!I33 -> 0 | J33: ='W1 Stats'!J33+'W2 Stats'!J33+'W3 Stats'!J33+'W4 Stats'!J33 -> 0 | ... Q33: ='W1 Stats'!Q33+'W2 Stats'!Q33+'W3 Stats'!Q33+'W4 Stats'!Q33 -> 0 | S33: ='Points System'!Z97 -> 0 | T33: ='Points System'!AA97 -> 0 | U33: ='Points System'!AB97 -> 0 | V33: ='Points System'!AC97 -> 0 | W33: =SUM(S33:V33) -> 0

Sheet Points System
A1: TEMPLATE | B1: Runner | C1: Tank | D1: Defender | E1: Hybrid | G1: TEMPLATE | H1: Runner | I1: Tank | J1: Defender | K1: Hybrid | M1: TEMPLATE | N1: Runner | O1: Tank | P1: Defender | Q1: Hybrid | S1: TEMPLATE | T1: Runner | U1: Tank | V1: Defender | W1: Hybrid | Y1: TEMPLATE | Z1: Runner | AA1: Tank | AB1: Defender | AC1: Hybrid
A2: Goals | B2: 15 | E2: 10 | G2: Goals | H2: =B2 -> 15 | I2: =C2 | J2: =D2 | K2: =E2 -> 10 | M2: Goals | N2: =H2 -> 15 | O2: =I2 | P2: =J2 | Q2: =K2 -> 10 | S2: Goals | T2: =N2 -> 15 | U2: =O2 | V2: =P2 | W2: =Q2 -> 10 | Y2: Goals | Z2: =T2 -> 15 | AA2: =U2 | AB2: =V2 | AC2: =W2 -> 10
