Workbook

Sheet Schedule
B1: Sunday | D1: Monday | F1: Tuesday | H1: Wednesday | J1: Thursday | L1: Friday | N1: Saturday
A3: Date | B3: 43604 | D3: 43605 | F3: 43606 | H3: 43607 | J3: 43608 | L3: 43609 | N3: 43610 | P3: Date
A4: 8:00pm est | H4: Mon over Junk 5-3 | P4: 8:00pm est | Q4: Team Name | R4: Abb. | S4: Wins | T4: Losses | U4: Goals | V4: Opp Goals | W4: Goal Eff | X4: Win %
A5: 8:00pm est | H5: Mon over Junk 5-0 | P5: 8:00pm est | Q5: Monstars | R5: Mon | S5: 16 | T5: 4 | U5: 90 | V5: 44 | W5: =SUM(U5/(U5+V5)) -> 0.67164179 | X5: =S5/(S5+T5) -> 0.8
A6: 9:00pm est | B6: Standings to the right of Calendar | F6: MP over Hype 5-3 | H6: Doc over TT 5-1 | J6: MP over Med 5-3 | K6: WDR over Def 5-3 | P6: 9:00pm est | Q6: Defiance | R6: Def | S6: 15 | T6: 5 | U6: 87 | V6: 55 | W6: =SUM(U6/(U6+V6)) -> 0.61267606 | X6: =S6/(S6+T6) -> 0.75
A7: 9:00pm est | F7: MP over Hype 5-2 | H7: Doc over TT 5-2 | J7: MP over Med 5-4 | K7: WDR over Def 5-1 | P7: 9:00pm est | Q7: Hypest | R7: Hype | S7: 13 | T7: 7 | U7: 84 | V7: 47 | W7: =SUM(U7/(U7+V7)) -> 0.64122137 | X7: =S7/(S7+T7) -> 0.65
A8: 10:00pm est | H8: Med over FTL 5-0 | I8: WDR over OTF 5-3 | J8: Hype over Mon 5-1 | P8: 10:00pm est | Q8: Failure to Launch | R8: FTL | S8: 12 | T8: 8 | U8: 71 | V8: 65 | W8: =SUM(U8/(U8+V8)) -> 0.52205882 | X8: =S8/(S8+T8) -> 0.6
A9: 10:00pm est | H9: Med over FTL 5-0 | I9: OTF over WDR 5-2 | J9: Mon over Hype 5-4 | P9: 10:00pm est | Q9: In MuNgO We Trust | R9: MP | S9: 11 | T9: 9 | U9: 80 | V9: 69 | W9: =SUM(U9/(U9+V9)) -> 0.53691275 | X9: =S9/(S9+T9) -> 0.55
A10: 11:00pm est | P10: 11:00pm est | Q10: Mediocre at Best | R10: Med | S10: 10 | T10: 10 | U10: 75 | V10: 63 | W10: =SUM(U10/(U10+V10)) -> 0.54347826 | X10: =S10/(S10+T10) -> 0.5
A11: 11:00pm est | P11: 11:00pm est | Q11: 9th Wonders | R11: WDR | S11: 10 | T11: 10 | U11: 63 | V11: 72 | W11: =SUM(U11/(U11+V11)) -> 0.46666667 | X11: =S11/(S11+T11) -> 0.5
Q12: Silva's Connection | R12: Doc | S12: 8 | T12: 12 | U12: 59 | V12: 77 | W12: =SUM(U12/(U12+V12)) -> 0.43382353 | X12: =S12/(S12+T12) -> 0.4
A13: Date | B13: 43611 | D13: 43612 | F13: 43613 | H13: 43614 | J13: 43615 | L13: 43616 | N13: 43617 | P13: Date | Q13: Junkyard Dogs | R13: Junk | S13: 8 | T13: 12 | U13: 63 | V13: 84 | W13: =SUM(U13/(U13+V13)) -> 0.42857143 | X13: =S13/(S13+T13) -> 0.4
A14: 8:00pm est | H14: WDR over Junk 5-3 | P14: 8:00pm est | Q14: Truthless and the Truthlessettes | R14: TT | S14: 5 | T14: 15 | U14: 40 | V14: 85 | W14: =SUM(U14/(U14+V14)) -> 0.32 | X14: =S14/(S14+T14) -> 0.25
A15: 8:00pm est | H15: WDR over Junk 5-3 | P15: 8:00pm est | Q15: On the Fence | R15: OTF | S15: 2 | T15: 18 | U15: 42 | V15: 93 | W15: =SUM(U15/(U15+V15)) -> 0.31111111 | X15: =S15/(S15+T15) -> 0.1
A16: 9:00pm est | D16: Def over Med 5-1 | H16: Med over Doc 5-3 | I16: Def over TT 5-0 | J16: Junk over MP 5-3 | P16: 9:00pm est | S16: =SUM(S5:S15) -> 110 | T16: =SUM(T5:T15) -> 110 | U16: =SUM(U5:U15) -> 754 | V16: =SUM(V5:V15) -> 754
A17: 9:00pm est | D17: Def over Med 5-3 | H17: Med over Doc 5-1 | I17: Def over TT 5-1 | J17: MP over Junk 5-2 | P17: 9:00pm est | Q17: Color=Rescheduled
A18: 10:00pm est | F18: Doc over OTF 5-2 | H18: Monstars over OTF 5-2 | J18: Hype over WDR 5-1 | K18: FTL over TT 5-2 | P18: 10:00pm est
A19: 10:00pm est | F19: Doc over OTF 5-2 | H19: Monstars over OTF 5-1 | J19: Hype over WDR 5-1 | K19: TT over FTL 5-2 | P19: 10:00pm est
A20: 11:00pm est | P20: 11:00pm est
A21: 11:00pm est | P21: 11:00pm est
A23: Date | B23: 43618 | D23: 43619 | F23: 43620 | H23: 43621 | J23: 43622 | L23: 43623 | N23: 43624 | P23: Date
A24: 8:00pm est | J24: Mon over WDR 5-1 | P24: 8:00pm est
A25: 8:00pm est | J25: Mon over WDR 5-1 | P25: 8:00pm est
A26: 9:00pm est | D26: Med over TT 5-1 | H26: Junk over Med 5-3 | I26: Def over Hype 5-3 | J26: Doc over Junk 5-3 | K26: TT over MP 5-4 | L26: MP over OTF 5-2 | M26: Mon over Doc 5-0 | P26: 9:00pm est
A27: 9:00pm est | D27: Med over TT 5-0 | H27: Med over Junk 5-4 | I27: Hype over Def 5-0 | J27: Junk over Doc 5-4 | K27: MP over TT 5-4 | L27: MP over OTF 5-0 | M27: Mon over Doc 5-0 | P27: 9:00pm est
A28: 10:00pm est | D28: FTL over Def 5-4 | F28: FTL over OTF 5-1 | P28: 10:00pm est
A29: 10:00pm est | D29: Def over FTL 5-2 | F29: FTL over OTF 5-4 | P29: 10:00pm est
A30: 11:00pm est | P30: 11:00pm est
A31: 11:00pm est | P31: 11:00pm est
A33: Date | B33: 43625 | D33: 43626 | F33: 43627 | H33: 43628 | J33: 43629 | L33: 43630 | N33: 43631 | P33: Date
A34: 8:00pm est | P34: 8:00pm est
A35: 8:00pm est | P35: 8:00pm est
A36: 9:00pm est | F36: Def over Junk 5-1 | H36: Med over WDR 5-0 | I36: Hype over Doc 5-0 | J36: Mon over MP 5-3 | K36: WDR over TT 5-0 | P36: 9:00pm est
A37: 9:00pm est | F37: Junk over Def 5-4 | H37: WDR over Med 5-1 | I37: Hype over Doc 5-1 | J37: Mon over MP 5-1 | K37: TT over WDR 5-3 | P37: 9:00pm est
A38: 10:00pm est | D38: Med over OTF 5-1 | F38: FTL over Hype 5-3 | H38: Mon over TT 5-0 | I38: FTL over Junk 5-1 | P38: 10:00pm est
A39: 10:00pm est | D39: Med over OTF 5-3 | F39: FTL over Hype 5-0 | H39: Mon over TT 5-1 | I39: FTL over Junk 5-1 | P39: 10:00pm est
A40: 11:00pm est | P40: 11:00pm est
A41: 11:00pm est | P41: 11:00pm est
A43: Date | B43: 43632 | D43: 43633 | F43: 43634 | H43: 43635 | J43: 43636 | L43: 43637 | N43: 43638 | P43: Date
A44: 8:00pm est | P44: 8:00pm est
...

Sheet Team and Player Stats
A1: AGLA SL19 Rosters and Regular Season Statistics
A2: Team | B2: Player | C2: Games Played | D2: Wins | E2: Minutes | F2: Goals | G2: Kills | H2: Assists | I2: Deaths | J2: Spread | K2: K/D Ratio | L2: Average Life | M2: Medals | N2: Games with Medals | O2: Minutes | P2: Carrier Kills | Q2: Beatdown | R2: Bulltrue | S2: Killjoys | T2: Double Kill | U2: Triple Kill | V2: Overkill | W2: Killtacular | X2: Killtrocity | Y2: Killmanjaro | Z2: Killpocalypse | AA2: Killtastrophe | AB2: Killionaire | AC2: Killing Spree | AD2: Killing Frenzy | AE2: Running Riot | AF2: Rampage | AG2: Extermination | AH2: Sword Spree
A3: Defiance | B3: Trespa5s | C3: =SUM('Game Results'!C246+'Game Results'!C678+'Game Results'!C779+'Game Results'!C804+'Game Results'!C696+'Game Results'!C1049+'Game Results'!C1031+'Game Results'!C1049+'Game Results'!C311+'Game Results'!C329+'Game Results'!C1913+'Game Results'!C1895+'Game Results'!C1625+'Game Results'!C1607+'Game Results'!C257+'Game Results'!C473) -> 14 | D3: =SUM('Game Results'!D246+'Game Results'!D678+'Game Results'!D779+'Game Results'!D804+'Game Results'!D696+'Game Results'!D1049+'Game Results'!D1031+'Game Results'!D1049+'Game Results'!D311+'Game Results'!D329+'Game Results'!D1913+'Game Results'!D1895+'Game Results'!D1625+'Game Results'!D1607+'Game Results'!D257+'Game Results'!D473) -> 8 | E3: =SUM('Game Results'!E246+'Game Results'!E678+'Game Results'!E779+'Game Results'!E804+'Game Results'!E696+'Game Results'!E1049+'Game Results'!E1031+'Game Results'!E1049+'Game Results'!E311+'Game Results'!E329+'Game Results'!E1913+'Game Results'!E1895+'Game Results'!E1625+'Game Results'!E1607+'Game Results'!E257+'Game Results'!E473) -> 419 | F3: =SUM('Game Results'!F246+'Game Results'!F678+'Game Results'!F779+'Game Results'!F804+'Game Results'!F696+'Game Results'!F1049+'Game Results'!F1031+'Game Results'!F1049+'Game Results'!F311+'Game Results'!F329+'Game Results'!F1913+'Game Results'!F1895+'Game Results'!F1625+'Game Results'!F1607+'Game Results'!F257+'Game Results'!F473) -> 4 | G3: =SUM('Game Results'!G246+'Game Results'!G678+'Game Results'!G779+'Game Results'!G804+'Game Results'!G696+'Game Results'!G1049+'Game Results'!G1031+'Game Results'!G1049+'Game Results'!G311+'Game Results'!G329+'Game Results'!G1913+'Game Results'!G1895+'Game Results'!G1625+'Game Results'!G1607+'Game Results'!G257+'Game Results'!G473) -> 1276 | H3: =SUM('Game Results'!H246+'Game Results'!H678+'Game Results'!H779+'Game Results'!H804+'Game Results'!H696+'Game Results'!H1049+'Game Results'!H1031+'Game Results'!H1049+'Game Results'!H311+'Game Results'!H329+'Game Results'!H1913+'Game Results'!H1895+'Game Results'!H1625+'Game Results'!H1607+'Game Results'!H257+'Game Results'!H473) -> 2 | I3: =SUM('Game Results'!I246+'Game Results'!I678+'Game Results'!I779+'Game Results'!I804+'Game Results'!I696+'Game Results'!I1049+'Game Results'!I1031+'Game Results'!I1049+'Game Results'!I311+'Game Results'!I329+'Game Results'!I1913+'Game Results'!I1895+'Game Results'!I1625+'Game Results'!I1607+'Game Results'!I257+'Game Results'!I473) -> 1388 | J3: =SUM('Game Results'!J246+'Game Results'!J678+'Game Results'!J779+'Game Results'!J804+'Game Results'!J696+'Game Results'!J1049+'Game Results'!J1031+'Game Results'!J1049+'Game Results'!J311+'Game Results'!J329+'Game Results'!J1913+'Game Results'!J1895+'Game Results'!J1625+'Game Results'!J1607+'Game Results'!J257+'Game Results'!J473) -> -112 | K3: =SUM(G3/I3) -> 0.91930836 | L3: =SUM('Game Results'!L246+'Game Results'!L678+'Game Results'!L779+'Game Results'!L804+'Game Results'!L696+'Game Results'!L1049+'Game Results'!L1031+'Game Results'!L1049+'Game Results'!L311+'Game Results'!L329+'Game Results'!L1913+'Game Results'!L1895+'Game Results'!L1625+'Game Results'!L1607+'Game Results'!L257+'Game Results'!L473) -> 239 | M3: =SUM('Game Results'!M246+'Game Results'!M678+'Game Results'!M779+'Game Results'!M804+'Game Results'!M696+'Game Results'!M1049+'Game Results'!M1031+'Game Results'!M1049+'Game Results'!M311+'Game Results'!M329+'Game Results'!M1913+'Game Results'!M1895+'Game Results'!M1625+'Game Results'!M1607+'Game Results'!M257+'Game Results'!M473) -> 1527 | N3: =SUM('Game Results'!N246+'Game Results'!N678+'Game Results'!N779+'Game Results'!N804+'Game Results'!N696+'Game Results'!N1049+'Game Results'!N1031+'Game Results'!N1049+'Game Results'!N311+'Game Results'!N329+'Game Results'!N1913+'Game Results'!N1895+'Game Results'!N1625+'Game Results'!N1607+'Game Results'!N257+'Game Results'!N473) -> 13 | O3: =SUM('Game Results'!O246+'Game Results'!O678+'Game Results'!O779+'Game Results'!O804+'Game Results'!O696+'Game Results'!O1049+'Game Results'!O1031+'Game Results'!O1049+'Game Results'!O311+'Game Results'!O329+'Game Results'!O1913+'Game Results'!O1895+'Game Results'!O1625+'Game Results'!O1607+'Game Results'!O257+'Game Results'!O473) -> 419 | P3: =SUM('Game Results'!P246+'Game Results'!P678+'Game Results'!P779+'Game Results'!P804+'Game Results'!P696+'Game Results'!P1049+'Game Results'!P1031+'Game Results'!P1049+'Game Results'!P311+'Game Results'!P329+'Game Results'!P1913+'Game Results'!P1895+'Game Results'!P1625+'Game Results'!P1607+'Game Results'!P257+'Game Results'!P473) -> 29 | Q3: =SUM('Game Results'!Q246+'Game Results'!Q678+'Game Results'!Q779+'Game Results'!Q804+'Game Results'!Q696+'Game Results'!Q1049+'Game Results'!Q1031+'Game Results'!Q1049+'Game Results'!Q311+'Game Results'!Q329+'Game Results'!Q1913+'Game Results'!Q1895+'Game Results'!Q1625+'Game Results'!Q1607+'Game Results'!Q257+'Game Results'!Q473) -> 9 | R3: =SUM('Game Results'!R246+'Game Results'!R678+'Game Results'!R779+'Game Results'!R804+'Game Results'!R696+'Game Results'!R1049+'Game Results'!R1031+'Game Results'!R1049+'Game Results'!R311+'Game Results'!R329+'Game Results'!R1913+'Game Results'!R1895+'Game Results'!R1625+'Game Results'!R1607+'Game Results'!R257+'Game Results'!R473) -> 98 | S3: =SUM('Game Results'!S246+'Game Results'!S678+'Game Results'!S779+'Game Results'!S804+'Game Results'!S696+'Game Results'!S1049+'Game Results'!S1031+'Game Results'!S1049+'Game Results'!S311+'Game Results'!S329+'Game Results'!S1913+'Game Results'!S1895+'Game Results'!S1625+'Game Results'!S1607+'Game Results'!S257+'Game Results'!S473) -> 18 | ... AH3: =SUM('Game Results'!AH246+'Game Results'!AH678+'Game Results'!AH779+'Game Results'!AH804+'Game Results'!AH696+'Game Results'!AH1049+'Game Results'!AH1031+'Game Results'!AH1049+'Game Results'!AH311+'Game Results'!AH329+'Game Results'!AH1913+'Game Results'!AH1895+'Game Results'!AH1625+'Game Results'!AH1607+'Game Results'!AH257+'Game Results'!AH473) -> 0
A4: Defiance | B4: DIGITAL PAIN | C4: =SUM('Game Results'!C247+'Game Results'!C679+'Game Results'!C780+'Game Results'!C805+'Game Results'!C697+'Game Results'!C1050+'Game Results'!C1032+'Game Results'!C1050+'Game Results'!C312+'Game Results'!C330+'Game Results'!C1914+'Game Results'!C1896+'Game Results'!C1626+'Game Results'!C1608+'Game Results'!C258+'Game Results'!C474) -> 16 | D4: =SUM('Game Results'!D247+'Game Results'!D679+'Game Results'!D780+'Game Results'!D805+'Game Results'!D697+'Game Results'!D1050+'Game Results'!D1032+'Game Results'!D1050+'Game Results'!D312+'Game Results'!D330+'Game Results'!D1914+'Game Results'!D1896+'Game Results'!D1626+'Game Results'!D1608+'Game Results'!D258+'Game Results'!D474) -> 10 | E4: =SUM('Game Results'!E247+'Game Results'!E679+'Game Results'!E780+'Game Results'!E805+'Game Results'!E697+'Game Results'!E1050+'Game Results'!E1032+'Game Results'!E1050+'Game Results'!E312+'Game Results'!E330+'Game Results'!E1914+'Game Results'!E1896+'Game Results'!E1626+'Game Results'!E1608+'Game Results'!E258+'Game Results'!E474) -> 454 | F4: =SUM('Game Results'!F247+'Game Results'!F679+'Game Results'!F780+'Game Results'!F805+'Game Results'!F697+'Game Results'!F1050+'Game Results'!F1032+'Game Results'!F1050+'Game Results'!F312+'Game Results'!F330+'Game Results'!F1914+'Game Results'!F1896+'Game Results'!F1626+'Game Results'!F1608+'Game Results'!F258+'Game Results'!F474) -> 5 | G4: =SUM('Game Results'!G247+'Game Results'!G679+'Game Results'!G780+'Game Results'!G805+'Game Results'!G697+'Game Results'!G1050+'Game Results'!G1032+'Game Results'!G1050+'Game Results'!G312+'Game Results'!G330+'Game Results'!G1914+'Game Results'!G1896+'Game Results'!G1626+'Game Results'!G1608+'Game Results'!G258+'Game Results'!G474) -> 1723 | H4: =SUM('Game Results'!H247+'Game Results'!H679+'Game Results'!H780+'Game Results'!H805+'Game Results'!H697+'Game Results'!H1050+'Game Results'!H1032+'Game Results'!H1050+'Game Results'!H312+'Game Results'!H330+'Game Results'!H1914+'Game Results'!H1896+'Game Results'!H1626+'Game Results'!H1608+'Game Results'!H258+'Game Results'!H474) -> 6 | I4: =SUM('Game Results'!I247+'Game Results'!I679+'Game Results'!I780+'Game Results'!I805+'Game Results'!I697+'Game Results'!I1050+'Game Results'!I1032+'Game Results'!I1050+'Game Results'!I312+'Game Results'!I330+'Game Results'!I1914+'Game Results'!I1896+'Game Results'!I1626+'Game Results'!I1608+'Game Results'!I258+'Game Results'!I474) -> 1499 | J4: =SUM('Game Results'!J247+'Game Results'!J679+'Game Results'!J780+'Game Results'!J805+'Game Results'!J697+'Game Results'!J1050+'Game Results'!J1032+'Game Results'!J1050+'Game Results'!J312+'Game Results'!J330+'Game Results'!J1914+'Game Results'!J1896+'Game Results'!J1626+'Game Results'!J1608+'Game Results'!J258+'Game Results'!J474) -> 224 | K4: =SUM(G4/I4) -> 1.149433 | L4: =SUM('Game Results'!L247+'Game Results'!L679+'Game Results'!L780+'Game Results'!L805+'Game Results'!L697+'Game Results'!L1050+'Game Results'!L1032+'Game Results'!L1050+'Game Results'!L312+'Game Results'!L330+'Game Results'!L1914+'Game Results'!L1896+'Game Results'!L1626+'Game Results'!L1608+'Game Results'!L258+'Game Results'!L474) -> 263 | M4: =SUM('Game Results'!M247+'Game Results'!M679+'Game Results'!M780+'Game Results'!M805+'Game Results'!M697+'Game Results'!M1050+'Game Results'!M1032+'Game Results'!M1050+'Game Results'!M312+'Game Results'!M330+'Game Results'!M1914+'Game Results'!M1896+'Game Results'!M1626+'Game Results'!M1608+'Game Results'!M258+'Game Results'!M474) -> 2175 | N4: =SUM('Game Results'!N247+'Game Results'!N679+'Game Results'!N780+'Game Results'!N805+'Game Results'!N697+'Game Results'!N1050+'Game Results'!N1032+'Game Results'!N1050+'Game Results'!N312+'Game Results'!N330+'Game Results'!N1914+'Game Results'!N1896+'Game Results'!N1626+'Game Results'!N1608+'Game Results'!N258+'Game Results'!N474) -> 13 | O4: =SUM('Game Results'!O247+'Game Results'!O679+'Game Results'!O780+'Game Results'!O805+'Game Results'!O697+'Game Results'!O1050+'Game Results'!O1032+'Game Results'!O1050+'Game Results'!O312+'Game Results'!O330+'Game Results'!O1914+'Game Results'!O1896+'Game Results'!O1626+'Game Results'!O1608+'Game Results'!O258+'Game Results'!O474) -> 419 | P4: =SUM('Game Results'!P247+'Game Results'!P679+'Game Results'!P780+'Game Results'!P805+'Game Results'!P697+'Game Results'!P1050+'Game Results'!P1032+'Game Results'!P1050+'Game Results'!P312+'Game Results'!P330+'Game Results'!P1914+'Game Results'!P1896+'Game Results'!P1626+'Game Results'!P1608+'Game Results'!P258+'Game Results'!P474) -> 84 | Q4: =SUM('Game Results'!Q247+'Game Results'!Q679+'Game Results'!Q780+'Game Results'!Q805+'Game Results'!Q697+'Game Results'!Q1050+'Game Results'!Q1032+'Game Results'!Q1050+'Game Results'!Q312+'Game Results'!Q330+'Game Results'!Q1914+'Game Results'!Q1896+'Game Results'!Q1626+'Game Results'!Q1608+'Game Results'!Q258+'Game Results'!Q474) -> 29 | R4: =SUM('Game Results'!R247+'Game Results'!R679+'Game Results'!R780+'Game Results'!R805+'Game Results'!R697+'Game Results'!R1050+'Game Results'!R1032+'Game Results'!R1050+'Game Results'!R312+'Game Results'!R330+'Game Results'!R1914+'Game Results'!R1896+'Game Results'!R1626+'Game Results'!R1608+'Game Results'!R258+'Game Results'!R474) -> 141 | S4: =SUM('Game Results'!S247+'Game Results'!S679+'Game Results'!S780+'Game Results'!S805+'Game Results'!S697+'Game Results'!S1050+'Game Results'!S1032+'Game Results'!S1050+'Game Results'!S312+'Game Results'!S330+'Game Results'!S1914+'Game Results'!S1896+'Game Results'!S1626+'Game Results'!S1608+'Game Results'!S258+'Game Results'!S474) -> 20 | ... AH4: =SUM('Game Results'!AH247+'Game Results'!AH679+'Game Results'!AH780+'Game Results'!AH805+'Game Results'!AH697+'Game Results'!AH1050+'Game Results'!AH1032+'Game Results'!AH1050+'Game Results'!AH312+'Game Results'!AH330+'Game Results'!AH1914+'Game Results'!AH1896+'Game Results'!AH1626+'Game Results'!AH1608+'Game Results'!AH258+'Game Results'!AH474) -> 2
A5: Defiance | B5: Sabasauros Rex | C5: =SUM('Game Results'!C248+'Game Results'!C680+'Game Results'!C781+'Game Results'!C806+'Game Results'!C698+'Game Results'!C1051+'Game Results'!C1033+'Game Results'!C1051+'Game Results'!C313+'Game Results'!C331+'Game Results'!C1915+'Game Results'!C1897+'Game Results'!C1627+'Game Results'!C1609+'Game Results'!C259+'Game Results'!C475) -> 16 | D5: =SUM('Game Results'!D248+'Game Results'!D680+'Game Results'!D781+'Game Results'!D806+'Game Results'!D698+'Game Results'!D1051+'Game Results'!D1033+'Game Results'!D1051+'Game Results'!D313+'Game Results'!D331+'Game Results'!D1915+'Game Results'!D1897+'Game Results'!D1627+'Game Results'!D1609+'Game Results'!D259+'Game Results'!D475) -> 10 | E5: =SUM('Game Results'!E248+'Game Results'!E680+'Game Results'!E781+'Game Results'!E806+'Game Results'!E698+'Game Results'!E1051+'Game Results'!E1033+'Game Results'!E1051+'Game Results'!E313+'Game Results'!E331+'Game Results'!E1915+'Game Results'!E1897+'Game Results'!E1627+'Game Results'!E1609+'Game Results'!E259+'Game Results'!E475) -> 454 | F5: =SUM('Game Results'!F248+'Game Results'!F680+'Game Results'!F781+'Game Results'!F806+'Game Results'!F698+'Game Results'!F1051+'Game Results'!F1033+'Game Results'!F1051+'Game Results'!F313+'Game Results'!F331+'Game Results'!F1915+'Game Results'!F1897+'Game Results'!F1627+'Game Results'!F1609+'Game Results'!F259+'Game Results'!F475) -> 13 | G5: =SUM('Game Results'!G248+'Game Results'!G680+'Game Results'!G781+'Game Results'!G806+'Game Results'!G698+'Game Results'!G1051+'Game Results'!G1033+'Game Results'!G1051+'Game Results'!G313+'Game Results'!G331+'Game Results'!G1915+'Game Results'!G1897+'Game Results'!G1627+'Game Results'!G1609+'Game Results'!G259+'Game Results'!G475) -> 1748 | H5: =SUM('Game Results'!H248+'Game Results'!H680+'Game Results'!H781+'Game Results'!H806+'Game Results'!H698+'Game Results'!H1051+'Game Results'!H1033+'Game Results'!H1051+'Game Results'!H313+'Game Results'!H331+'Game Results'!H1915+'Game Results'!H1897+'Game Results'!H1627+'Game Results'!H1609+'Game Results'!H259+'Game Results'!H475) -> 11 | I5: =SUM('Game Results'!I248+'Game Results'!I680+'Game Results'!I781+'Game Results'!I806+'Game Results'!I698+'Game Results'!I1051+'Game Results'!I1033+'Game Results'!I1051+'Game Results'!I313+'Game Results'!I331+'Game Results'!I1915+'Game Results'!I1897+'Game Results'!I1627+'Game Results'!I1609+'Game Results'!I259+'Game Results'!I475) -> 1684 | J5: =SUM('Game Results'!J248+'Game Results'!J680+'Game Results'!J781+'Game Results'!J806+'Game Results'!J698+'Game Results'!J1051+'Game Results'!J1033+'Game Results'!J1051+'Game Results'!J313+'Game Results'!J331+'Game Results'!J1915+'Game Results'!J1897+'Game Results'!J1627+'Game Results'!J1609+'Game Results'!J259+'Game Results'!J475) -> 64 | K5: =SUM(G5/I5) -> 1.0380048 | L5: =SUM('Game Results'!L248+'Game Results'!L680+'Game Results'!L781+'Game Results'!L806+'Game Results'!L698+'Game Results'!L1051+'Game Results'!L1033+'Game Results'!L1051+'Game Results'!L313+'Game Results'!L331+'Game Results'!L1915+'Game Results'!L1897+'Game Results'!L1627+'Game Results'!L1609+'Game Results'!L259+'Game Results'!L475) -> 226 | M5: =SUM('Game Results'!M248+'Game Results'!M680+'Game Results'!M781+'Game Results'!M806+'Game Results'!M698+'Game Results'!M1051+'Game Results'!M1033+'Game Results'!M1051+'Game Results'!M313+'Game Results'!M331+'Game Results'!M1915+'Game Results'!M1897+'Game Results'!M1627+'Game Results'!M1609+'Game Results'!M259+'Game Results'!M475) -> 2216 | N5: =SUM('Game Results'!N248+'Game Results'!N680+'Game Results'!N781+'Game Results'!N806+'Game Results'!N698+'Game Results'!N1051+'Game Results'!N1033+'Game Results'!N1051+'Game Results'!N313+'Game Results'!N331+'Game Results'!N1915+'Game Results'!N1897+'Game Results'!N1627+'Game Results'!N1609+'Game Results'!N259+'Game Results'!N475) -> 13 | O5: =SUM('Game Results'!O248+'Game Results'!O680+'Game Results'!O781+'Game Results'!O806+'Game Results'!O698+'Game Results'!O1051+'Game Results'!O1033+'Game Results'!O1051+'Game Results'!O313+'Game Results'!O331+'Game Results'!O1915+'Game Results'!O1897+'Game Results'!O1627+'Game Results'!O1609+'Game Results'!O259+'Game Results'!O475) -> 419 | P5: =SUM('Game Results'!P248+'Game Results'!P680+'Game Results'!P781+'Game Results'!P806+'Game Results'!P698+'Game Results'!P1051+'Game Results'!P1033+'Game Results'!P1051+'Game Results'!P313+'Game Results'!P331+'Game Results'!P1915+'Game Results'!P1897+'Game Results'!P1627+'Game Results'!P1609+'Game Results'!P259+'Game Results'!P475) -> 75 | Q5: =SUM('Game Results'!Q248+'Game Results'!Q680+'Game Results'!Q781+'Game Results'!Q806+'Game Results'!Q698+'Game Results'!Q1051+'Game Results'!Q1033+'Game Results'!Q1051+'Game Results'!Q313+'Game Results'!Q331+'Game Results'!Q1915+'Game Results'!Q1897+'Game Results'!Q1627+'Game Results'!Q1609+'Game Results'!Q259+'Game Results'!Q475) -> 25 | R5: =SUM('Game Results'!R248+'Game Results'!R680+'Game Results'!R781+'Game Results'!R806+'Game Results'!R698+'Game Results'!R1051+'Game Results'!R1033+'Game Results'!R1051+'Game Results'!R313+'Game Results'!R331+'Game Results'!R1915+'Game Results'!R1897+'Game Results'!R1627+'Game Results'!R1609+'Game Results'!R259+'Game Results'!R475) -> 128 | S5: =SUM('Game Results'!S248+'Game Results'!S680+'Game Results'!S781+'Game Results'!S806+'Game Results'!S698+'Game Results'!S1051+'Game Results'!S1033+'Game Results'!S1051+'Game Results'!S313+'Game Results'!S331+'Game Results'!S1915+'Game Results'!S1897+'Game Results'!S1627+'Game Results'!S1609+'Game Results'!S259+'Game Results'!S475) -> 27 | ... AH5: =SUM('Game Results'!AH248+'Game Results'!AH680+'Game Results'!AH781+'Game Results'!AH806+'Game Results'!AH698+'Game Results'!AH1051+'Game Results'!AH1033+'Game Results'!AH1051+'Game Results'!AH313+'Game Results'!AH331+'Game Results'!AH1915+'Game Results'!AH1897+'Game Results'!AH1627+'Game Results'!AH1609+'Game Results'!AH259+'Game Results'!AH475) -> 0
A6: Defiance | B6: ThumpingHawk | C6: =SUM('Game Results'!C249+'Game Results'!C681+'Game Results'!C782+'Game Results'!C807+'Game Results'!C699+'Game Results'!C1052+'Game Results'!C1034+'Game Results'!C1052+'Game Results'!C314+'Game Results'!C332+'Game Results'!C1916+'Game Results'!C1898+'Game Results'!C1628+'Game Results'!C1610+'Game Results'!C260+'Game Results'!C476) -> 12 | D6: =SUM('Game Results'!D249+'Game Results'!D681+'Game Results'!D782+'Game Results'!D807+'Game Results'!D699+'Game Results'!D1052+'Game Results'!D1034+'Game Results'!D1052+'Game Results'!D314+'Game Results'!D332+'Game Results'!D1916+'Game Results'!D1898+'Game Results'!D1628+'Game Results'!D1610+'Game Results'!D260+'Game Results'!D476) -> 6 | E6: =SUM('Game Results'!E249+'Game Results'!E681+'Game Results'!E782+'Game Results'!E807+'Game Results'!E699+'Game Results'!E1052+'Game Results'!E1034+'Game Results'!E1052+'Game Results'!E314+'Game Results'!E332+'Game Results'!E1916+'Game Results'!E1898+'Game Results'!E1628+'Game Results'!E1610+'Game Results'!E260+'Game Results'!E476) -> 339 | F6: =SUM('Game Results'!F249+'Game Results'!F681+'Game Results'!F782+'Game Results'!F807+'Game Results'!F699+'Game Results'!F1052+'Game Results'!F1034+'Game Results'!F1052+'Game Results'!F314+'Game Results'!F332+'Game Results'!F1916+'Game Results'!F1898+'Game Results'!F1628+'Game Results'!F1610+'Game Results'!F260+'Game Results'!F476) -> 23 | G6: =SUM('Game Results'!G249+'Game Results'!G681+'Game Results'!G782+'Game Results'!G807+'Game Results'!G699+'Game Results'!G1052+'Game Results'!G1034+'Game Results'!G1052+'Game Results'!G314+'Game Results'!G332+'Game Results'!G1916+'Game Results'!G1898+'Game Results'!G1628+'Game Results'!G1610+'Game Results'!G260+'Game Results'!G476) -> 880 | H6: =SUM('Game Results'!H249+'Game Results'!H681+'Game Results'!H782+'Game Results'!H807+'Game Results'!H699+'Game Results'!H1052+'Game Results'!H1034+'Game Results'!H1052+'Game Results'!H314+'Game Results'!H332+'Game Results'!H1916+'Game Results'!H1898+'Game Results'!H1628+'Game Results'!H1610+'Game Results'!H260+'Game Results'!H476) -> 2 | I6: =SUM('Game Results'!I249+'Game Results'!I681+'Game Results'!I782+'Game Results'!I807+'Game Results'!I699+'Game Results'!I1052+'Game Results'!I1034+'Game Results'!I1052+'Game Results'!I314+'Game Results'!I332+'Game Results'!I1916+'Game Results'!I1898+'Game Results'!I1628+'Game Results'!I1610+'Game Results'!I260+'Game Results'!I476) -> 923 | J6: =SUM('Game Results'!J249+'Game Results'!J681+'Game Results'!J782+'Game Results'!J807+'Game Results'!J699+'Game Results'!J1052+'Game Results'!J1034+'Game Results'!J1052+'Game Results'!J314+'Game Results'!J332+'Game Results'!J1916+'Game Results'!J1898+'Game Results'!J1628+'Game Results'!J1610+'Game Results'!J260+'Game Results'!J476) -> -43 | K6: =SUM(G6/I6) -> 0.95341278 | L6: =SUM('Game Results'!L249+'Game Results'!L681+'Game Results'!L782+'Game Results'!L807+'Game Results'!L699+'Game Results'!L1052+'Game Results'!L1034+'Game Results'!L1052+'Game Results'!L314+'Game Results'!L332+'Game Results'!L1916+'Game Results'!L1898+'Game Results'!L1628+'Game Results'!L1610+'Game Results'!L260+'Game Results'!L476) -> 254 | M6: =SUM('Game Results'!M249+'Game Results'!M681+'Game Results'!M782+'Game Results'!M807+'Game Results'!M699+'Game Results'!M1052+'Game Results'!M1034+'Game Results'!M1052+'Game Results'!M314+'Game Results'!M332+'Game Results'!M1916+'Game Results'!M1898+'Game Results'!M1628+'Game Results'!M1610+'Game Results'!M260+'Game Results'!M476) -> 1128 | N6: =SUM('Game Results'!N249+'Game Results'!N681+'Game Results'!N782+'Game Results'!N807+'Game Results'!N699+'Game Results'!N1052+'Game Results'!N1034+'Game Results'!N1052+'Game Results'!N314+'Game Results'!N332+'Game Results'!N1916+'Game Results'!N1898+'Game Results'!N1628+'Game Results'!N1610+'Game Results'!N260+'Game Results'!N476) -> 9 | O6: =SUM('Game Results'!O249+'Game Results'!O681+'Game Results'!O782+'Game Results'!O807+'Game Results'!O699+'Game Results'!O1052+'Game Results'!O1034+'Game Results'!O1052+'Game Results'!O314+'Game Results'!O332+'Game Results'!O1916+'Game Results'!O1898+'Game Results'!O1628+'Game Results'!O1610+'Game Results'!O260+'Game Results'!O476) -> 304 | P6: =SUM('Game Results'!P249+'Game Results'!P681+'Game Results'!P782+'Game Results'!P807+'Game Results'!P699+'Game Results'!P1052+'Game Results'!P1034+'Game Results'!P1052+'Game Results'!P314+'Game Results'!P332+'Game Results'!P1916+'Game Results'!P1898+'Game Results'!P1628+'Game Results'!P1610+'Game Results'!P260+'Game Results'!P476) -> 37 | Q6: =SUM('Game Results'!Q249+'Game Results'!Q681+'Game Results'!Q782+'Game Results'!Q807+'Game Results'!Q699+'Game Results'!Q1052+'Game Results'!Q1034+'Game Results'!Q1052+'Game Results'!Q314+'Game Results'!Q332+'Game Results'!Q1916+'Game Results'!Q1898+'Game Results'!Q1628+'Game Results'!Q1610+'Game Results'!Q260+'Game Results'!Q476) -> 18 | R6: =SUM('Game Results'!R249+'Game Results'!R681+'Game Results'!R782+'Game Results'!R807+'Game Results'!R699+'Game Results'!R1052+'Game Results'!R1034+'Game Results'!R1052+'Game Results'!R314+'Game Results'!R332+'Game Results'!R1916+'Game Results'!R1898+'Game Results'!R1628+'Game Results'!R1610+'Game Results'!R260+'Game Results'!R476) -> 49 | S6: =SUM('Game Results'!S249+'Game Results'!S681+'Game Results'!S782+'Game Results'!S807+'Game Results'!S699+'Game Results'!S1052+'Game Results'!S1034+'Game Results'!S1052+'Game Results'!S314+'Game Results'!S332+'Game Results'!S1916+'Game Results'!S1898+'Game Results'!S1628+'Game Results'!S1610+'Game Results'!S260+'Game Results'!S476) -> 24 | ... AH6: =SUM('Game Results'!AH249+'Game Results'!AH681+'Game Results'!AH782+'Game Results'!AH807+'Game Results'!AH699+'Game Results'!AH1052+'Game Results'!AH1034+'Game Results'!AH1052+'Game Results'!AH314+'Game Results'!AH332+'Game Results'!AH1916+'Game Results'!AH1898+'Game Results'!AH1628+'Game Results'!AH1610+'Game Results'!AH260+'Game Results'!AH476) -> 0
A7: Defiance | B7: The Eastbrook | C7: =SUM('Game Results'!C250+'Game Results'!C682+'Game Results'!C783+'Game Results'!C808+'Game Results'!C700+'Game Results'!C1053+'Game Results'!C1035+'Game Results'!C1053+'Game Results'!C315+'Game Results'!C333+'Game Results'!C1917+'Game Results'!C1899+'Game Results'!C1629+'Game Results'!C1611+'Game Results'!C261+'Game Results'!C477) -> 6 | D7: =SUM('Game Results'!D250+'Game Results'!D682+'Game Results'!D783+'Game Results'!D808+'Game Results'!D700+'Game Results'!D1053+'Game Results'!D1035+'Game Results'!D1053+'Game Results'!D315+'Game Results'!D333+'Game Results'!D1917+'Game Results'!D1899+'Game Results'!D1629+'Game Results'!D1611+'Game Results'!D261+'Game Results'!D477) -> 6 | E7: =SUM('Game Results'!E250+'Game Results'!E682+'Game Results'!E783+'Game Results'!E808+'Game Results'!E700+'Game Results'!E1053+'Game Results'!E1035+'Game Results'!E1053+'Game Results'!E315+'Game Results'!E333+'Game Results'!E1917+'Game Results'!E1899+'Game Results'!E1629+'Game Results'!E1611+'Game Results'!E261+'Game Results'!E477) -> 150 | F7: =SUM('Game Results'!F250+'Game Results'!F682+'Game Results'!F783+'Game Results'!F808+'Game Results'!F700+'Game Results'!F1053+'Game Results'!F1035+'Game Results'!F1053+'Game Results'!F315+'Game Results'!F333+'Game Results'!F1917+'Game Results'!F1899+'Game Results'!F1629+'Game Results'!F1611+'Game Results'!F261+'Game Results'!F477) -> 21 | G7: =SUM('Game Results'!G250+'Game Results'!G682+'Game Results'!G783+'Game Results'!G808+'Game Results'!G700+'Game Results'!G1053+'Game Results'!G1035+'Game Results'!G1053+'Game Results'!G315+'Game Results'!G333+'Game Results'!G1917+'Game Results'!G1899+'Game Results'!G1629+'Game Results'!G1611+'Game Results'!G261+'Game Results'!G477) -> 371 | H7: =SUM('Game Results'!H250+'Game Results'!H682+'Game Results'!H783+'Game Results'!H808+'Game Results'!H700+'Game Results'!H1053+'Game Results'!H1035+'Game Results'!H1053+'Game Results'!H315+'Game Results'!H333+'Game Results'!H1917+'Game Results'!H1899+'Game Results'!H1629+'Game Results'!H1611+'Game Results'!H261+'Game Results'!H477) -> 3 | I7: =SUM('Game Results'!I250+'Game Results'!I682+'Game Results'!I783+'Game Results'!I808+'Game Results'!I700+'Game Results'!I1053+'Game Results'!I1035+'Game Results'!I1053+'Game Results'!I315+'Game Results'!I333+'Game Results'!I1917+'Game Results'!I1899+'Game Results'!I1629+'Game Results'!I1611+'Game Results'!I261+'Game Results'!I477) -> 424 | J7: =SUM('Game Results'!J250+'Game Results'!J682+'Game Results'!J783+'Game Results'!J808+'Game Results'!J700+'Game Results'!J1053+'Game Results'!J1035+'Game Results'!J1053+'Game Results'!J315+'Game Results'!J333+'Game Results'!J1917+'Game Results'!J1899+'Game Results'!J1629+'Game Results'!J1611+'Game Results'!J261+'Game Results'!J477) -> -53 | K7: =SUM(G7/I7) -> 0.875 | L7: =SUM('Game Results'!L250+'Game Results'!L682+'Game Results'!L783+'Game Results'!L808+'Game Results'!L700+'Game Results'!L1053+'Game Results'!L1035+'Game Results'!L1053+'Game Results'!L315+'Game Results'!L333+'Game Results'!L1917+'Game Results'!L1899+'Game Results'!L1629+'Game Results'!L1611+'Game Results'!L261+'Game Results'!L477) -> 101 | M7: =SUM('Game Results'!M250+'Game Results'!M682+'Game Results'!M783+'Game Results'!M808+'Game Results'!M700+'Game Results'!M1053+'Game Results'!M1035+'Game Results'!M1053+'Game Results'!M315+'Game Results'!M333+'Game Results'!M1917+'Game Results'!M1899+'Game Results'!M1629+'Game Results'!M1611+'Game Results'!M261+'Game Results'!M477) -> 478 | N7: =SUM('Game Results'!N250+'Game Results'!N682+'Game Results'!N783+'Game Results'!N808+'Game Results'!N700+'Game Results'!N1053+'Game Results'!N1035+'Game Results'!N1053+'Game Results'!N315+'Game Results'!N333+'Game Results'!N1917+'Game Results'!N1899+'Game Results'!N1629+'Game Results'!N1611+'Game Results'!N261+'Game Results'!N477) -> 4 | O7: =SUM('Game Results'!O250+'Game Results'!O682+'Game Results'!O783+'Game Results'!O808+'Game Results'!O700+'Game Results'!O1053+'Game Results'!O1035+'Game Results'!O1053+'Game Results'!O315+'Game Results'!O333+'Game Results'!O1917+'Game Results'!O1899+'Game Results'!O1629+'Game Results'!O1611+'Game Results'!O261+'Game Results'!O477) -> 115 | P7: =SUM('Game Results'!P250+'Game Results'!P682+'Game Results'!P783+'Game Results'!P808+'Game Results'!P700+'Game Results'!P1053+'Game Results'!P1035+'Game Results'!P1053+'Game Results'!P315+'Game Results'!P333+'Game Results'!P1917+'Game Results'!P1899+'Game Results'!P1629+'Game Results'!P1611+'Game Results'!P261+'Game Results'!P477) -> 16 | Q7: =SUM('Game Results'!Q250+'Game Results'!Q682+'Game Results'!Q783+'Game Results'!Q808+'Game Results'!Q700+'Game Results'!Q1053+'Game Results'!Q1035+'Game Results'!Q1053+'Game Results'!Q315+'Game Results'!Q333+'Game Results'!Q1917+'Game Results'!Q1899+'Game Results'!Q1629+'Game Results'!Q1611+'Game Results'!Q261+'Game Results'!Q477) -> 16 | R7: =SUM('Game Results'!R250+'Game Results'!R682+'Game Results'!R783+'Game Results'!R808+'Game Results'!R700+'Game Results'!R1053+'Game Results'!R1035+'Game Results'!R1053+'Game Results'!R315+'Game Results'!R333+'Game Results'!R1917+'Game Results'!R1899+'Game Results'!R1629+'Game Results'!R1611+'Game Results'!R261+'Game Results'!R477) -> 4 | S7: =SUM('Game Results'!S250+'Game Results'!S682+'Game Results'!S783+'Game Results'!S808+'Game Results'!S700+'Game Results'!S1053+'Game Results'!S1035+'Game Results'!S1053+'Game Results'!S315+'Game Results'!S333+'Game Results'!S1917+'Game Results'!S1899+'Game Results'!S1629+'Game Results'!S1611+'Game Results'!S261+'Game Results'!S477) -> 6 | ... AH7: =SUM('Game Results'!AH250+'Game Results'!AH682+'Game Results'!AH783+'Game Results'!AH808+'Game Results'!AH700+'Game Results'!AH1053+'Game Results'!AH1035+'Game Results'!AH1053+'Game Results'!AH315+'Game Results'!AH333+'Game Results'!AH1917+'Game Results'!AH1899+'Game Results'!AH1629+'Game Results'!AH1611+'Game Results'!AH261+'Game Results'!AH477) -> 1
A8: Defiance | B8: MASTER CH3IF | C8: =SUM('Game Results'!C251+'Game Results'!C683+'Game Results'!C784+'Game Results'!C809+'Game Results'!C701+'Game Results'!C1054+'Game Results'!C1036+'Game Results'!C1054+'Game Results'!C316+'Game Results'!C334+'Game Results'!C1918+'Game Results'!C1900+'Game Results'!C1630+'Game Results'!C1612+'Game Results'!C262+'Game Results'!C478) -> 0 | D8: =SUM('Game Results'!D251+'Game Results'!D683+'Game Results'!D784+'Game Results'!D809+'Game Results'!D701+'Game Results'!D1054+'Game Results'!D1036+'Game Results'!D1054+'Game Results'!D316+'Game Results'!D334+'Game Results'!D1918+'Game Results'!D1900+'Game Results'!D1630+'Game Results'!D1612+'Game Results'!D262+'Game Results'!D478) -> 0 | E8: =SUM('Game Results'!E251+'Game Results'!E683+'Game Results'!E784+'Game Results'!E809+'Game Results'!E701+'Game Results'!E1054+'Game Results'!E1036+'Game Results'!E1054+'Game Results'!E316+'Game Results'!E334+'Game Results'!E1918+'Game Results'!E1900+'Game Results'!E1630+'Game Results'!E1612+'Game Results'!E262+'Game Results'!E478) -> 0 | F8: =SUM('Game Results'!F251+'Game Results'!F683+'Game Results'!F784+'Game Results'!F809+'Game Results'!F701+'Game Results'!F1054+'Game Results'!F1036+'Game Results'!F1054+'Game Results'!F316+'Game Results'!F334+'Game Results'!F1918+'Game Results'!F1900+'Game Results'!F1630+'Game Results'!F1612+'Game Results'!F262+'Game Results'!F478) -> 0 | G8: =SUM('Game Results'!G251+'Game Results'!G683+'Game Results'!G784+'Game Results'!G809+'Game Results'!G701+'Game Results'!G1054+'Game Results'!G1036+'Game Results'!G1054+'Game Results'!G316+'Game Results'!G334+'Game Results'!G1918+'Game Results'!G1900+'Game Results'!G1630+'Game Results'!G1612+'Game Results'!G262+'Game Results'!G478) -> 0 | H8: =SUM('Game Results'!H251+'Game Results'!H683+'Game Results'!H784+'Game Results'!H809+'Game Results'!H701+'Game Results'!H1054+'Game Results'!H1036+'Game Results'!H1054+'Game Results'!H316+'Game Results'!H334+'Game Results'!H1918+'Game Results'!H1900+'Game Results'!H1630+'Game Results'!H1612+'Game Results'!H262+'Game Results'!H478) -> 0 | I8: =SUM('Game Results'!I251+'Game Results'!I683+'Game Results'!I784+'Game Results'!I809+'Game Results'!I701+'Game Results'!I1054+'Game Results'!I1036+'Game Results'!I1054+'Game Results'!I316+'Game Results'!I334+'Game Results'!I1918+'Game Results'!I1900+'Game Results'!I1630+'Game Results'!I1612+'Game Results'!I262+'Game Results'!I478) -> 0 | J8: =SUM('Game Results'!J251+'Game Results'!J683+'Game Results'!J784+'Game Results'!J809+'Game Results'!J701+'Game Results'!J1054+'Game Results'!J1036+'Game Results'!J1054+'Game Results'!J316+'Game Results'!J334+'Game Results'!J1918+'Game Results'!J1900+'Game Results'!J1630+'Game Results'!J1612+'Game Results'!J262+'Game Results'!J478) -> 0 | K8: =SUM(G8/I8) -> #DIV/0! | L8: =SUM('Game Results'!L251+'Game Results'!L683+'Game Results'!L784+'Game Results'!L809+'Game Results'!L701+'Game Results'!L1054+'Game Results'!L1036+'Game Results'!L1054+'Game Results'!L316+'Game Results'!L334+'Game Results'!L1918+'Game Results'!L1900+'Game Results'!L1630+'Game Results'!L1612+'Game Results'!L262+'Game Results'!L478) -> 0 | M8: =SUM('Game Results'!M251+'Game Results'!M683+'Game Results'!M784+'Game Results'!M809+'Game Results'!M701+'Game Results'!M1054+'Game Results'!M1036+'Game Results'!M1054+'Game Results'!M316+'Game Results'!M334+'Game Results'!M1918+'Game Results'!M1900+'Game Results'!M1630+'Game Results'!M1612+'Game Results'!M262+'Game Results'!M478) -> 0 | N8: =SUM('Game Results'!N251+'Game Results'!N683+'Game Results'!N784+'Game Results'!N809+'Game Results'!N701+'Game Results'!N1054+'Game Results'!N1036+'Game Results'!N1054+'Game Results'!N316+'Game Results'!N334+'Game Results'!N1918+'Game Results'!N1900+'Game Results'!N1630+'Game Results'!N1612+'Game Results'!N262+'Game Results'!N478) -> 0 | O8: =SUM('Game Results'!O251+'Game Results'!O683+'Game Results'!O784+'Game Results'!O809+'Game Results'!O701+'Game Results'!O1054+'Game Results'!O1036+'Game Results'!O1054+'Game Results'!O316+'Game Results'!O334+'Game Results'!O1918+'Game Results'!O1900+'Game Results'!O1630+'Game Results'!O1612+'Game Results'!O262+'Game Results'!O478) -> 0 | P8: =SUM('Game Results'!P251+'Game Results'!P683+'Game Results'!P784+'Game Results'!P809+'Game Results'!P701+'Game Results'!P1054+'Game Results'!P1036+'Game Results'!P1054+'Game Results'!P316+'Game Results'!P334+'Game Results'!P1918+'Game Results'!P1900+'Game Results'!P1630+'Game Results'!P1612+'Game Results'!P262+'Game Results'!P478) -> 1 | Q8: =SUM('Game Results'!Q251+'Game Results'!Q683+'Game Results'!Q784+'Game Results'!Q809+'Game Results'!Q701+'Game Results'!Q1054+'Game Results'!Q1036+'Game Results'!Q1054+'Game Results'!Q316+'Game Results'!Q334+'Game Results'!Q1918+'Game Results'!Q1900+'Game Results'!Q1630+'Game Results'!Q1612+'Game Results'!Q262+'Game Results'!Q478) -> 0 | R8: =SUM('Game Results'!R251+'Game Results'!R683+'Game Results'!R784+'Game Results'!R809+'Game Results'!R701+'Game Results'!R1054+'Game Results'!R1036+'Game Results'!R1054+'Game Results'!R316+'Game Results'!R334+'Game Results'!R1918+'Game Results'!R1900+'Game Results'!R1630+'Game Results'!R1612+'Game Results'!R262+'Game Results'!R478) -> 2 | S8: =SUM('Game Results'!S251+'Game Results'!S683+'Game Results'!S784+'Game Results'!S809+'Game Results'!S701+'Game Results'!S1054+'Game Results'!S1036+'Game Results'!S1054+'Game Results'!S316+'Game Results'!S334+'Game Results'!S1918+'Game Results'!S1900+'Game Results'!S1630+'Game Results'!S1612+'Game Results'!S262+'Game Results'!S478) -> 0 | ... AH8: =SUM('Game Results'!AH251+'Game Results'!AH683+'Game Results'!AH784+'Game Results'!AH809+'Game Results'!AH701+'Game Results'!AH1054+'Game Results'!AH1036+'Game Results'!AH1054+'Game Results'!AH316+'Game Results'!AH334+'Game Results'!AH1918+'Game Results'!AH1900+'Game Results'!AH1630+'Game Results'!AH1612+'Game Results'!AH262+'Game Results'!AH478) -> 0
A9: Totals: | C9: =SUM(C3:C8)/4 -> 16 | D9: =SUM(D3:D8)/4 -> 10 | E9: =SUM(E3:E8)/4 -> 454 | F9: =SUM(F3:F8) -> 66 | G9: =SUM(G3:G8) -> 5998 | H9: =SUM(H3:H8) -> 24 | I9: =SUM(I3:I8) -> 5918 | J9: =SUM(J3:J8) -> 80 | K9: =SUM(G9/I9) -> 1.0135181 | L9: =SUM(L3:L8)/4 -> 270.75 | M9: =SUM(M3:M8) -> 7524 | N9: =SUM(N3:N8)/4 -> 13 | O9: =SUM(O2:O8) -> 1676 | P9: =SUM(P3:P8) -> 242 | Q9: =SUM(Q3:Q8) -> 97 | R9: =SUM(R3:R8) -> 422 | S9: =SUM(S3:S8) -> 95 | T9: =SUM(T3:T8) -> 699 | U9: =SUM(U3:U8) -> 124 | V9: =SUM(V3:V8) -> 30 | W9: =SUM(W3:W8) -> 7 | ... AH9: =SUM(AH3:AH8) -> 3
A10: In MuNgO We Trust | B10: MuNgO PuNgO | C10: =SUM('Game Results'!C23+'Game Results'!C41+'Game Results'!C203+'Game Results'!C527+'Game Results'!C545+'Game Results'!C221+'Game Results'!C887+'Game Results'!C1247+'Game Results'!C1265+'Game Results'!C905+'Game Results'!C923+'Game Results'!C941+'Game Results'!C1661+'Game Results'!C1643) -> 12 | D10: =SUM('Game Results'!D23+'Game Results'!D41+'Game Results'!D203+'Game Results'!D527+'Game Results'!D545+'Game Results'!D221+'Game Results'!D887+'Game Results'!D1247+'Game Results'!D1265+'Game Results'!D905+'Game Results'!D923+'Game Results'!D941+'Game Results'!D1661+'Game Results'!D1643) -> 7 | E10: =SUM('Game Results'!E23+'Game Results'!E41+'Game Results'!E203+'Game Results'!E527+'Game Results'!E545+'Game Results'!E221+'Game Results'!E887+'Game Results'!E1247+'Game Results'!E1265+'Game Results'!E905+'Game Results'!E923+'Game Results'!E941+'Game Results'!E1661+'Game Results'!E1643) -> 392.85 | F10: =SUM('Game Results'!F23+'Game Results'!F41+'Game Results'!F203+'Game Results'!F527+'Game Results'!F545+'Game Results'!F221+'Game Results'!F887+'Game Results'!F1247+'Game Results'!F1265+'Game Results'!F905+'Game Results'!F923+'Game Results'!F941+'Game Results'!F1661+'Game Results'!F1643) -> 0 | G10: =SUM('Game Results'!G23+'Game Results'!G41+'Game Results'!G203+'Game Results'!G527+'Game Results'!G545+'Game Results'!G221+'Game Results'!G887+'Game Results'!G1247+'Game Results'!G1265+'Game Results'!G905+'Game Results'!G923+'Game Results'!G941+'Game Results'!G1661+'Game Results'!G1643) -> 1234 | H10: =SUM('Game Results'!H23+'Game Results'!H41+'Game Results'!H203+'Game Results'!H527+'Game Results'!H545+'Game Results'!H221+'Game Results'!H887+'Game Results'!H1247+'Game Results'!H1265+'Game Results'!H905+'Game Results'!H923+'Game Results'!H941+'Game Results'!H1661+'Game Results'!H1643) -> 3 | I10: =SUM('Game Results'!I23+'Game Results'!I41+'Game Results'!I203+'Game Results'!I527+'Game Results'!I545+'Game Results'!I221+'Game Results'!I887+'Game Results'!I1247+'Game Results'!I1265+'Game Results'!I905+'Game Results'!I923+'Game Results'!I941+'Game Results'!I1661+'Game Results'!I1643) -> 1718 | J10: =SUM('Game Results'!J23+'Game Results'!J41+'Game Results'!J203+'Game Results'!J527+'Game Results'!J545+'Game Results'!J221+'Game Results'!J887+'Game Results'!J1247+'Game Results'!J1265+'Game Results'!J905+'Game Results'!J923+'Game Results'!J941+'Game Results'!J1661+'Game Results'!J1643) -> -484 | K10: =SUM(G10/I10) -> 0.71827707 | L10: =SUM('Game Results'!L23+'Game Results'!L41+'Game Results'!L203+'Game Results'!L527+'Game Results'!L545+'Game Results'!L221+'Game Results'!L887+'Game Results'!L1247+'Game Results'!L1265+'Game Results'!L905+'Game Results'!L923+'Game Results'!L941+'Game Results'!L1661+'Game Results'!L1643) -> 133 | M10: =SUM('Game Results'!M23+'Game Results'!M41+'Game Results'!M203+'Game Results'!M527+'Game Results'!M545+'Game Results'!M221+'Game Results'!M887+'Game Results'!M1247+'Game Results'!M1265+'Game Results'!M905+'Game Results'!M923+'Game Results'!M941+'Game Results'!M1661+'Game Results'!M1643) -> 1551 | N10: =SUM('Game Results'!N23+'Game Results'!N41+'Game Results'!N203+'Game Results'!N527+'Game Results'!N545+'Game Results'!N221+'Game Results'!N887+'Game Results'!N1247+'Game Results'!N1265+'Game Results'!N905+'Game Results'!N923+'Game Results'!N941+'Game Results'!N1661+'Game Results'!N1643) -> 12 | O10: =SUM('Game Results'!O23+'Game Results'!O41+'Game Results'!O203+'Game Results'!O527+'Game Results'!O545+'Game Results'!O221+'Game Results'!O887+'Game Results'!O1247+'Game Results'!O1265+'Game Results'!O905+'Game Results'!O923+'Game Results'!O941+'Game Results'!O1661+'Game Results'!O1643) -> 392.85 | P10: =SUM('Game Results'!P23+'Game Results'!P41+'Game Results'!P203+'Game Results'!P527+'Game Results'!P545+'Game Results'!P221+'Game Results'!P887+'Game Results'!P1247+'Game Results'!P1265+'Game Results'!P905+'Game Results'!P923+'Game Results'!P941+'Game Results'!P1661+'Game Results'!P1643) -> 32 | Q10: =SUM('Game Results'!Q23+'Game Results'!Q41+'Game Results'!Q203+'Game Results'!Q527+'Game Results'!Q545+'Game Results'!Q221+'Game Results'!Q887+'Game Results'!Q1247+'Game Results'!Q1265+'Game Results'!Q905+'Game Results'!Q923+'Game Results'!Q941+'Game Results'!Q1661+'Game Results'!Q1643) -> 22 | R10: =SUM('Game Results'!R23+'Game Results'!R41+'Game Results'!R203+'Game Results'!R527+'Game Results'!R545+'Game Results'!R221+'Game Results'!R887+'Game Results'!R1247+'Game Results'!R1265+'Game Results'!R905+'Game Results'!R923+'Game Results'!R941+'Game Results'!R1661+'Game Results'!R1643) -> 114 | S10: =SUM('Game Results'!S23+'Game Results'!S41+'Game Results'!S203+'Game Results'!S527+'Game Results'!S545+'Game Results'!S221+'Game Results'!S887+'Game Results'!S1247+'Game Results'!S1265+'Game Results'!S905+'Game Results'!S923+'Game Results'!S941+'Game Results'!S1661+'Game Results'!S1643) -> 24 | ... AH10: =SUM('Game Results'!AH23+'Game Results'!AH41+'Game Results'!AH203+'Game Results'!AH527+'Game Results'!AH545+'Game Results'!AH221+'Game Results'!AH887+'Game Results'!AH1247+'Game Results'!AH1265+'Game Results'!AH905+'Game Results'!AH923+'Game Results'!AH941+'Game Results'!AH1661+'Game Results'!AH1643) -> 0
A11: In MuNgO We Trust | B11: Saintz the God | C11: =SUM('Game Results'!C24+'Game Results'!C42+'Game Results'!C204+'Game Results'!C528+'Game Results'!C546+'Game Results'!C222+'Game Results'!C888+'Game Results'!C1248+'Game Results'!C1266+'Game Results'!C906+'Game Results'!C924+'Game Results'!C942+'Game Results'!C1662+'Game Results'!C1644) -> 12 | D11: =SUM('Game Results'!D24+'Game Results'!D42+'Game Results'!D204+'Game Results'!D528+'Game Results'!D546+'Game Results'!D222+'Game Results'!D888+'Game Results'!D1248+'Game Results'!D1266+'Game Results'!D906+'Game Results'!D924+'Game Results'!D942+'Game Results'!D1662+'Game Results'!D1644) -> 7 | E11: =SUM('Game Results'!E24+'Game Results'!E42+'Game Results'!E204+'Game Results'!E528+'Game Results'!E546+'Game Results'!E222+'Game Results'!E888+'Game Results'!E1248+'Game Results'!E1266+'Game Results'!E906+'Game Results'!E924+'Game Results'!E942+'Game Results'!E1662+'Game Results'!E1644) -> 371.5 | F11: =SUM('Game Results'!F24+'Game Results'!F42+'Game Results'!F204+'Game Results'!F528+'Game Results'!F546+'Game Results'!F222+'Game Results'!F888+'Game Results'!F1248+'Game Results'!F1266+'Game Results'!F906+'Game Results'!F924+'Game Results'!F942+'Game Results'!F1662+'Game Results'!F1644) -> 5 | G11: =SUM('Game Results'!G24+'Game Results'!G42+'Game Results'!G204+'Game Results'!G528+'Game Results'!G546+'Game Results'!G222+'Game Results'!G888+'Game Results'!G1248+'Game Results'!G1266+'Game Results'!G906+'Game Results'!G924+'Game Results'!G942+'Game Results'!G1662+'Game Results'!G1644) -> 1527 | H11: =SUM('Game Results'!H24+'Game Results'!H42+'Game Results'!H204+'Game Results'!H528+'Game Results'!H546+'Game Results'!H222+'Game Results'!H888+'Game Results'!H1248+'Game Results'!H1266+'Game Results'!H906+'Game Results'!H924+'Game Results'!H942+'Game Results'!H1662+'Game Results'!H1644) -> 6 | I11: =SUM('Game Results'!I24+'Game Results'!I42+'Game Results'!I204+'Game Results'!I528+'Game Results'!I546+'Game Results'!I222+'Game Results'!I888+'Game Results'!I1248+'Game Results'!I1266+'Game Results'!I906+'Game Results'!I924+'Game Results'!I942+'Game Results'!I1662+'Game Results'!I1644) -> 1261 | J11: =SUM('Game Results'!J24+'Game Results'!J42+'Game Results'!J204+'Game Results'!J528+'Game Results'!J546+'Game Results'!J222+'Game Results'!J888+'Game Results'!J1248+'Game Results'!J1266+'Game Results'!J906+'Game Results'!J924+'Game Results'!J942+'Game Results'!J1662+'Game Results'!J1644) -> 266 | K11: =SUM(G11/I11) -> 1.2109437 | L11: =SUM('Game Results'!L24+'Game Results'!L42+'Game Results'!L204+'Game Results'!L528+'Game Results'!L546+'Game Results'!L222+'Game Results'!L888+'Game Results'!L1248+'Game Results'!L1266+'Game Results'!L906+'Game Results'!L924+'Game Results'!L942+'Game Results'!L1662+'Game Results'!L1644) -> 181 | M11: =SUM('Game Results'!M24+'Game Results'!M42+'Game Results'!M204+'Game Results'!M528+'Game Results'!M546+'Game Results'!M222+'Game Results'!M888+'Game Results'!M1248+'Game Results'!M1266+'Game Results'!M906+'Game Results'!M924+'Game Results'!M942+'Game Results'!M1662+'Game Results'!M1644) -> 2001 | N11: =SUM('Game Results'!N24+'Game Results'!N42+'Game Results'!N204+'Game Results'!N528+'Game Results'!N546+'Game Results'!N222+'Game Results'!N888+'Game Results'!N1248+'Game Results'!N1266+'Game Results'!N906+'Game Results'!N924+'Game Results'!N942+'Game Results'!N1662+'Game Results'!N1644) -> 12 | O11: =SUM('Game Results'!O24+'Game Results'!O42+'Game Results'!O204+'Game Results'!O528+'Game Results'!O546+'Game Results'!O222+'Game Results'!O888+'Game Results'!O1248+'Game Results'!O1266+'Game Results'!O906+'Game Results'!O924+'Game Results'!O942+'Game Results'!O1662+'Game Results'!O1644) -> 371.5 | P11: =SUM('Game Results'!P24+'Game Results'!P42+'Game Results'!P204+'Game Results'!P528+'Game Results'!P546+'Game Results'!P222+'Game Results'!P888+'Game Results'!P1248+'Game Results'!P1266+'Game Results'!P906+'Game Results'!P924+'Game Results'!P942+'Game Results'!P1662+'Game Results'!P1644) -> 53 | Q11: =SUM('Game Results'!Q24+'Game Results'!Q42+'Game Results'!Q204+'Game Results'!Q528+'Game Results'!Q546+'Game Results'!Q222+'Game Results'!Q888+'Game Results'!Q1248+'Game Results'!Q1266+'Game Results'!Q906+'Game Results'!Q924+'Game Results'!Q942+'Game Results'!Q1662+'Game Results'!Q1644) -> 24 | R11: =SUM('Game Results'!R24+'Game Results'!R42+'Game Results'!R204+'Game Results'!R528+'Game Results'!R546+'Game Results'!R222+'Game Results'!R888+'Game Results'!R1248+'Game Results'!R1266+'Game Results'!R906+'Game Results'!R924+'Game Results'!R942+'Game Results'!R1662+'Game Results'!R1644) -> 125 | S11: =SUM('Game Results'!S24+'Game Results'!S42+'Game Results'!S204+'Game Results'!S528+'Game Results'!S546+'Game Results'!S222+'Game Results'!S888+'Game Results'!S1248+'Game Results'!S1266+'Game Results'!S906+'Game Results'!S924+'Game Results'!S942+'Game Results'!S1662+'Game Results'!S1644) -> 22 | ... AH11: =SUM('Game Results'!AH24+'Game Results'!AH42+'Game Results'!AH204+'Game Results'!AH528+'Game Results'!AH546+'Game Results'!AH222+'Game Results'!AH888+'Game Results'!AH1248+'Game Results'!AH1266+'Game Results'!AH906+'Game Results'!AH924+'Game Results'!AH942+'Game Results'!AH1662+'Game Results'!AH1644) -> 1
A12: In MuNgO We Trust | B12: The Corn Ninja | C12: =SUM('Game Results'!C25+'Game Results'!C43+'Game Results'!C205+'Game Results'!C529+'Game Results'!C547+'Game Results'!C223+'Game Results'!C889+'Game Results'!C1249+'Game Results'!C1267+'Game Results'!C907+'Game Results'!C925+'Game Results'!C943+'Game Results'!C1663+'Game Results'!C1645) -> 13 | D12: =SUM('Game Results'!D25+'Game Results'!D43+'Game Results'!D205+'Game Results'!D529+'Game Results'!D547+'Game Results'!D223+'Game Results'!D889+'Game Results'!D1249+'Game Results'!D1267+'Game Results'!D907+'Game Results'!D925+'Game Results'!D943+'Game Results'!D1663+'Game Results'!D1645) -> 7 | E12: =SUM('Game Results'!E25+'Game Results'!E43+'Game Results'!E205+'Game Results'!E529+'Game Results'!E547+'Game Results'!E223+'Game Results'!E889+'Game Results'!E1249+'Game Results'!E1267+'Game Results'!E907+'Game Results'!E925+'Game Results'!E943+'Game Results'!E1663+'Game Results'!E1645) -> 439.96667 | F12: =SUM('Game Results'!F25+'Game Results'!F43+'Game Results'!F205+'Game Results'!F529+'Game Results'!F547+'Game Results'!F223+'Game Results'!F889+'Game Results'!F1249+'Game Results'!F1267+'Game Results'!F907+'Game Results'!F925+'Game Results'!F943+'Game Results'!F1663+'Game Results'!F1645) -> 42 | G12: =SUM('Game Results'!G25+'Game Results'!G43+'Game Results'!G205+'Game Results'!G529+'Game Results'!G547+'Game Results'!G223+'Game Results'!G889+'Game Results'!G1249+'Game Results'!G1267+'Game Results'!G907+'Game Results'!G925+'Game Results'!G943+'Game Results'!G1663+'Game Results'!G1645) -> 969 | H12: =SUM('Game Results'!H25+'Game Results'!H43+'Game Results'!H205+'Game Results'!H529+'Game Results'!H547+'Game Results'!H223+'Game Results'!H889+'Game Results'!H1249+'Game Results'!H1267+'Game Results'!H907+'Game Results'!H925+'Game Results'!H943+'Game Results'!H1663+'Game Results'!H1645) -> 4 | I12: =SUM('Game Results'!I25+'Game Results'!I43+'Game Results'!I205+'Game Results'!I529+'Game Results'!I547+'Game Results'!I223+'Game Results'!I889+'Game Results'!I1249+'Game Results'!I1267+'Game Results'!I907+'Game Results'!I925+'Game Results'!I943+'Game Results'!I1663+'Game Results'!I1645) -> 1039 | J12: =SUM('Game Results'!J25+'Game Results'!J43+'Game Results'!J205+'Game Results'!J529+'Game Results'!J547+'Game Results'!J223+'Game Results'!J889+'Game Results'!J1249+'Game Results'!J1267+'Game Results'!J907+'Game Results'!J925+'Game Results'!J943+'Game Results'!J1663+'Game Results'!J1645) -> -70 | K12: =SUM(G12/I12) -> 0.93262753 | L12: =SUM('Game Results'!L25+'Game Results'!L43+'Game Results'!L205+'Game Results'!L529+'Game Results'!L547+'Game Results'!L223+'Game Results'!L889+'Game Results'!L1249+'Game Results'!L1267+'Game Results'!L907+'Game Results'!L925+'Game Results'!L943+'Game Results'!L1663+'Game Results'!L1645) -> 295 | M12: =SUM('Game Results'!M25+'Game Results'!M43+'Game Results'!M205+'Game Results'!M529+'Game Results'!M547+'Game Results'!M223+'Game Results'!M889+'Game Results'!M1249+'Game Results'!M1267+'Game Results'!M907+'Game Results'!M925+'Game Results'!M943+'Game Results'!M1663+'Game Results'!M1645) -> 1224 | N12: =SUM('Game Results'!N25+'Game Results'!N43+'Game Results'!N205+'Game Results'!N529+'Game Results'!N547+'Game Results'!N223+'Game Results'!N889+'Game Results'!N1249+'Game Results'!N1267+'Game Results'!N907+'Game Results'!N925+'Game Results'!N943+'Game Results'!N1663+'Game Results'!N1645) -> 13 | O12: =SUM('Game Results'!O25+'Game Results'!O43+'Game Results'!O205+'Game Results'!O529+'Game Results'!O547+'Game Results'!O223+'Game Results'!O889+'Game Results'!O1249+'Game Results'!O1267+'Game Results'!O907+'Game Results'!O925+'Game Results'!O943+'Game Results'!O1663+'Game Results'!O1645) -> 439.96667 | P12: =SUM('Game Results'!P25+'Game Results'!P43+'Game Results'!P205+'Game Results'!P529+'Game Results'!P547+'Game Results'!P223+'Game Results'!P889+'Game Results'!P1249+'Game Results'!P1267+'Game Results'!P907+'Game Results'!P925+'Game Results'!P943+'Game Results'!P1663+'Game Results'!P1645) -> 59 | Q12: =SUM('Game Results'!Q25+'Game Results'!Q43+'Game Results'!Q205+'Game Results'!Q529+'Game Results'!Q547+'Game Results'!Q223+'Game Results'!Q889+'Game Results'!Q1249+'Game Results'!Q1267+'Game Results'!Q907+'Game Results'!Q925+'Game Results'!Q943+'Game Results'!Q1663+'Game Results'!Q1645) -> 13 | R12: =SUM('Game Results'!R25+'Game Results'!R43+'Game Results'!R205+'Game Results'!R529+'Game Results'!R547+'Game Results'!R223+'Game Results'!R889+'Game Results'!R1249+'Game Results'!R1267+'Game Results'!R907+'Game Results'!R925+'Game Results'!R943+'Game Results'!R1663+'Game Results'!R1645) -> 31 | S12: =SUM('Game Results'!S25+'Game Results'!S43+'Game Results'!S205+'Game Results'!S529+'Game Results'!S547+'Game Results'!S223+'Game Results'!S889+'Game Results'!S1249+'Game Results'!S1267+'Game Results'!S907+'Game Results'!S925+'Game Results'!S943+'Game Results'!S1663+'Game Results'!S1645) -> 30 | ... AH12: =SUM('Game Results'!AH25+'Game Results'!AH43+'Game Results'!AH205+'Game Results'!AH529+'Game Results'!AH547+'Game Results'!AH223+'Game Results'!AH889+'Game Results'!AH1249+'Game Results'!AH1267+'Game Results'!AH907+'Game Results'!AH925+'Game Results'!AH943+'Game Results'!AH1663+'Game Results'!AH1645) -> 0
