Workbook

Sheet Individual Stats
A1: Team | B1: Player | C1: Games | D1: Wins | E1: Losses | F1: Goals | G1: Kills | H1: Assists | I1: Deaths | J1: Time | K1: K-D | L1: (K-D)/minute | M1: Stops | N1: Doubles | O1: Triples | P1: Over+ | Q1: Sprees | R1: Exterm | S1: Sword Spree | T1: AVG Life
A2: Don't Be A Gonk Scet | B2: The Scet | C2: =sum(D2:E2) -> 18 | D2: 7 | E2: 11 | F2: =sum(DBAGS!C3,DBAGS!T3,DBAGS!C11,DBAGS!T11,DBAGS!C19,DBAGS!T19,DBAGS!C27,DBAGS!T27,DBAGS!C35,DBAGS!T35,DBAGS!C43,DBAGS!T43,DBAGS!C51,DBAGS!T51,DBAGS!C60,DBAGS!T60,DBAGS!C69,DBAGS!T69,DBAGS!C79,DBAGS!T79) -> 46 | G2: =sum(DBAGS!D3,DBAGS!U3,DBAGS!D11,DBAGS!U11,DBAGS!D19,DBAGS!U19,DBAGS!D27,DBAGS!U27,DBAGS!D35,DBAGS!U35,DBAGS!D43,DBAGS!U43,DBAGS!D51,DBAGS!U51,DBAGS!D60,DBAGS!U60,DBAGS!D69,DBAGS!U69,DBAGS!D79,DBAGS!U79) -> 1044 | H2: =sum(DBAGS!E3,DBAGS!V3,DBAGS!E11,DBAGS!V11,DBAGS!E19,DBAGS!V19,DBAGS!E27,DBAGS!V27,DBAGS!E35,DBAGS!V35,DBAGS!E43,DBAGS!V43,DBAGS!E51,DBAGS!V51,DBAGS!E60,DBAGS!V60,DBAGS!E69,DBAGS!V69,DBAGS!E79,DBAGS!V79) -> 7 | I2: =sum(DBAGS!F3,DBAGS!W3,DBAGS!F11,DBAGS!W11,DBAGS!F19,DBAGS!W19,DBAGS!F27,DBAGS!W27,DBAGS!F35,DBAGS!W35,DBAGS!F43,DBAGS!W43,DBAGS!F51,DBAGS!W51,DBAGS!F60,DBAGS!W60,DBAGS!F69,DBAGS!W69,DBAGS!F79,DBAGS!W79) -> 1117 | J2: =sum(DBAGS!G3,DBAGS!X3,DBAGS!G11,DBAGS!X11,DBAGS!G19,DBAGS!X19,DBAGS!G27,DBAGS!X27,DBAGS!G35,DBAGS!X35,DBAGS!G43,DBAGS!X43,DBAGS!G51,DBAGS!X51,DBAGS!G60,DBAGS!X60,DBAGS!G69,DBAGS!X69,DBAGS!G79,DBAGS!X79) -> 0.33775463 | K2: =sum(DBAGS!H3,DBAGS!Y3,DBAGS!H11,DBAGS!Y11,DBAGS!H19,DBAGS!Y19,DBAGS!H27,DBAGS!Y27,DBAGS!H35,DBAGS!Y35,DBAGS!H43,DBAGS!Y43,DBAGS!H51,DBAGS!Y51,DBAGS!H60,DBAGS!Y60,DBAGS!H69,DBAGS!Y69,DBAGS!H79,DBAGS!Y79) -> -73 | L2: =K2/(HOUR(J2)*60+(MINUTE(J2)+((SECOND(J2)/60)))) -> -0.15009252 | M2: =sum(DBAGS!J3,DBAGS!AA3,DBAGS!J11,DBAGS!AA11,DBAGS!J19,DBAGS!AA19,DBAGS!J27,DBAGS!AA27,DBAGS!J35,DBAGS!AA35,DBAGS!J43,DBAGS!AA43,DBAGS!J51,DBAGS!AA51,DBAGS!J60,DBAGS!AA60,DBAGS!J69,DBAGS!AA69,DBAGS!J79,DBAGS!AA79) -> 53 | N2: =sum(DBAGS!K3,DBAGS!AB3,DBAGS!K11,DBAGS!AB11,DBAGS!K19,DBAGS!AB19,DBAGS!K27,DBAGS!AB27,DBAGS!K35,DBAGS!AB35,DBAGS!K43,DBAGS!AB43,DBAGS!K51,DBAGS!AB51,DBAGS!K60,DBAGS!AB60,DBAGS!K69,DBAGS!AB69,DBAGS!K79,DBAGS!AB79) -> 104 | O2: =sum(DBAGS!L3,DBAGS!AC3,DBAGS!L11,DBAGS!AC11,DBAGS!L19,DBAGS!AC19,DBAGS!L27,DBAGS!AC27,DBAGS!L35,DBAGS!AC35,DBAGS!L43,DBAGS!AC43,DBAGS!L51,DBAGS!AC51,DBAGS!L60,DBAGS!AC60,DBAGS!L69,DBAGS!AC69,DBAGS!L79,DBAGS!AC79) -> 10 | P2: =sum(DBAGS!M3,DBAGS!AD3,DBAGS!M11,DBAGS!AD11,DBAGS!M19,DBAGS!AD19,DBAGS!M27,DBAGS!AD27,DBAGS!M35,DBAGS!AD35,DBAGS!M43,DBAGS!AD43,DBAGS!M51,DBAGS!AD51,DBAGS!M60,DBAGS!AD60,DBAGS!M69,DBAGS!AD69,DBAGS!M79,DBAGS!AD79) -> 3 | Q2: =sum(DBAGS!N3,DBAGS!AE3,DBAGS!N11,DBAGS!AE11,DBAGS!N19,DBAGS!AE19,DBAGS!N27,DBAGS!AE27,DBAGS!N35,DBAGS!AE35,DBAGS!N43,DBAGS!AE43,DBAGS!N51,DBAGS!AE51,DBAGS!N60,DBAGS!AE60,DBAGS!N69,DBAGS!AE69,DBAGS!N79,DBAGS!AE79) -> 25 | R2: =sum(DBAGS!O3,DBAGS!AF3,DBAGS!O11,DBAGS!AF11,DBAGS!O19,DBAGS!AF19,DBAGS!O27,DBAGS!AF27,DBAGS!O35,DBAGS!AF35,DBAGS!O43,DBAGS!AF43,DBAGS!O51,DBAGS!AF51,DBAGS!O60,DBAGS!AF60,DBAGS!O69,DBAGS!AF69,DBAGS!O79,DBAGS!AF79) -> 0 | S2: =sum(DBAGS!P3,DBAGS!AG3,DBAGS!P11,DBAGS!AG11,DBAGS!P19,DBAGS!AG19,DBAGS!P27,DBAGS!AG27,DBAGS!P35,DBAGS!AG35,DBAGS!P43,DBAGS!AG43,DBAGS!P51,DBAGS!AG51,DBAGS!P60,DBAGS!AG60,DBAGS!P69,DBAGS!AG69,DBAGS!P79,DBAGS!AG79) -> 0 | T2: =J2/I2 -> 0.00030237657
A3: Don't Be A Gonk Scet | B3: Galvann | C3: =sum(D3:E3) -> 16 | D3: 7 | E3: 9 | F3: =sum(DBAGS!C4,DBAGS!T4,DBAGS!C12,DBAGS!T12,DBAGS!C20,DBAGS!T20,DBAGS!C28,DBAGS!T28,DBAGS!C36,DBAGS!T36,DBAGS!C44,DBAGS!T44,DBAGS!C52,DBAGS!T52,DBAGS!C61,DBAGS!T61,DBAGS!C70,DBAGS!T70,DBAGS!C80,DBAGS!T80) -> 9 | G3: =sum(DBAGS!D4,DBAGS!U4,DBAGS!D12,DBAGS!U12,DBAGS!D20,DBAGS!U20,DBAGS!D28,DBAGS!U28,DBAGS!D36,DBAGS!U36,DBAGS!D44,DBAGS!U44,DBAGS!D52,DBAGS!U52,DBAGS!D61,DBAGS!U61,DBAGS!D70,DBAGS!U70,DBAGS!D80,DBAGS!U80) -> 2144 | H3: =sum(DBAGS!E4,DBAGS!V4,DBAGS!E12,DBAGS!V12,DBAGS!E20,DBAGS!V20,DBAGS!E28,DBAGS!V28,DBAGS!E36,DBAGS!V36,DBAGS!E44,DBAGS!V44,DBAGS!E52,DBAGS!V52,DBAGS!E61,DBAGS!V61,DBAGS!E70,DBAGS!V70,DBAGS!E80,DBAGS!V80) -> 8 | I3: =sum(DBAGS!F4,DBAGS!W4,DBAGS!F12,DBAGS!W12,DBAGS!F20,DBAGS!W20,DBAGS!F28,DBAGS!W28,DBAGS!F36,DBAGS!W36,DBAGS!F44,DBAGS!W44,DBAGS!F52,DBAGS!W52,DBAGS!F61,DBAGS!W61,DBAGS!F70,DBAGS!W70,DBAGS!F80,DBAGS!W80) -> 1729 | J3: =sum(DBAGS!G4,DBAGS!X4,DBAGS!G12,DBAGS!X12,DBAGS!G20,DBAGS!X20,DBAGS!G28,DBAGS!X28,DBAGS!G36,DBAGS!X36,DBAGS!G44,DBAGS!X44,DBAGS!G52,DBAGS!X52,DBAGS!G61,DBAGS!X61,DBAGS!G70,DBAGS!X70,DBAGS!G80,DBAGS!X80) -> 0.31231481 | K3: =sum(DBAGS!H4,DBAGS!Y4,DBAGS!H12,DBAGS!Y12,DBAGS!H20,DBAGS!Y20,DBAGS!H28,DBAGS!Y28,DBAGS!H36,DBAGS!Y36,DBAGS!H44,DBAGS!Y44,DBAGS!H52,DBAGS!Y52,DBAGS!H61,DBAGS!Y61,DBAGS!H70,DBAGS!Y70,DBAGS!H80,DBAGS!Y80) -> 415 | L3: =K3/(HOUR(J3)*60+(MINUTE(J3)+((SECOND(J3)/60)))) -> 0.92276905 | M3: =sum(DBAGS!J4,DBAGS!AA4,DBAGS!J12,DBAGS!AA12,DBAGS!J20,DBAGS!AA20,DBAGS!J28,DBAGS!AA28,DBAGS!J36,DBAGS!AA36,DBAGS!J44,DBAGS!AA44,DBAGS!J52,DBAGS!AA52,DBAGS!J61,DBAGS!AA61,DBAGS!J70,DBAGS!AA70,DBAGS!J80,DBAGS!AA80) -> 75 | N3: =sum(DBAGS!K4,DBAGS!AB4,DBAGS!K12,DBAGS!AB12,DBAGS!K20,DBAGS!AB20,DBAGS!K28,DBAGS!AB28,DBAGS!K36,DBAGS!AB36,DBAGS!K44,DBAGS!AB44,DBAGS!K52,DBAGS!AB52,DBAGS!K61,DBAGS!AB61,DBAGS!K70,DBAGS!AB70,DBAGS!K80,DBAGS!AB80) -> 387 | O3: =sum(DBAGS!L4,DBAGS!AC4,DBAGS!L12,DBAGS!AC12,DBAGS!L20,DBAGS!AC20,DBAGS!L28,DBAGS!AC28,DBAGS!L36,DBAGS!AC36,DBAGS!L44,DBAGS!AC44,DBAGS!L52,DBAGS!AC52,DBAGS!L61,DBAGS!AC61,DBAGS!L70,DBAGS!AC70,DBAGS!L80,DBAGS!AC80) -> 101 | P3: =sum(DBAGS!M4,DBAGS!AD4,DBAGS!M12,DBAGS!AD12,DBAGS!M20,DBAGS!AD20,DBAGS!M28,DBAGS!AD28,DBAGS!M36,DBAGS!AD36,DBAGS!M44,DBAGS!AD44,DBAGS!M52,DBAGS!AD52,DBAGS!M61,DBAGS!AD61,DBAGS!M70,DBAGS!AD70,DBAGS!M80,DBAGS!AD80) -> 43 | Q3: =sum(DBAGS!N4,DBAGS!AE4,DBAGS!N12,DBAGS!AE12,DBAGS!N20,DBAGS!AE20,DBAGS!N28,DBAGS!AE28,DBAGS!N36,DBAGS!AE36,DBAGS!N44,DBAGS!AE44,DBAGS!N52,DBAGS!AE52,DBAGS!N61,DBAGS!AE61,DBAGS!N70,DBAGS!AE70,DBAGS!N80,DBAGS!AE80) -> 67 | R3: =sum(DBAGS!O4,DBAGS!AF4,DBAGS!O12,DBAGS!AF12,DBAGS!O20,DBAGS!AF20,DBAGS!O28,DBAGS!AF28,DBAGS!O36,DBAGS!AF36,DBAGS!O44,DBAGS!AF44,DBAGS!O52,DBAGS!AF52,DBAGS!O61,DBAGS!AF61,DBAGS!O70,DBAGS!AF70,DBAGS!O80,DBAGS!AF80) -> 4 | S3: =sum(DBAGS!P4,DBAGS!AG4,DBAGS!P12,DBAGS!AG12,DBAGS!P20,DBAGS!AG20,DBAGS!P28,DBAGS!AG28,DBAGS!P36,DBAGS!AG36,DBAGS!P44,DBAGS!AG44,DBAGS!P52,DBAGS!AG52,DBAGS!P61,DBAGS!AG61,DBAGS!P70,DBAGS!AG70,DBAGS!P80,DBAGS!AG80) -> 0 | T3: =J3/I3 -> 0.00018063321
A4: Don't Be A Gonk Scet | B4: Its Rainin MenZ | C4: =sum(D4:E4) -> 12 | D4: 6 | E4: 6 | F4: =sum(DBAGS!C5,DBAGS!T5,DBAGS!C13,DBAGS!T13,DBAGS!C21,DBAGS!T21,DBAGS!C29,DBAGS!T29,DBAGS!C37,DBAGS!T37,DBAGS!C45,DBAGS!T45,DBAGS!C53,DBAGS!T53,DBAGS!C62,DBAGS!T62,DBAGS!C71,DBAGS!T71,DBAGS!C81,DBAGS!T81) -> 1 | G4: =sum(DBAGS!D5,DBAGS!U5,DBAGS!D13,DBAGS!U13,DBAGS!D21,DBAGS!U21,DBAGS!D29,DBAGS!U29,DBAGS!D37,DBAGS!U37,DBAGS!D45,DBAGS!U45,DBAGS!D53,DBAGS!U53,DBAGS!D62,DBAGS!U62,DBAGS!D71,DBAGS!U71,DBAGS!D81,DBAGS!U81) -> 1049 | H4: =sum(DBAGS!E5,DBAGS!V5,DBAGS!E13,DBAGS!V13,DBAGS!E21,DBAGS!V21,DBAGS!E29,DBAGS!V29,DBAGS!E37,DBAGS!V37,DBAGS!E45,DBAGS!V45,DBAGS!E53,DBAGS!V53,DBAGS!E62,DBAGS!V62,DBAGS!E71,DBAGS!V71,DBAGS!E81,DBAGS!V81) -> 6 | I4: =sum(DBAGS!F5,DBAGS!W5,DBAGS!F13,DBAGS!W13,DBAGS!F21,DBAGS!W21,DBAGS!F29,DBAGS!W29,DBAGS!F37,DBAGS!W37,DBAGS!F45,DBAGS!W45,DBAGS!F53,DBAGS!W53,DBAGS!F62,DBAGS!W62,DBAGS!F71,DBAGS!W71,DBAGS!F81,DBAGS!W81) -> 1083 | J4: =sum(DBAGS!G5,DBAGS!X5,DBAGS!G13,DBAGS!X13,DBAGS!G21,DBAGS!X21,DBAGS!G29,DBAGS!X29,DBAGS!G37,DBAGS!X37,DBAGS!G45,DBAGS!X45,DBAGS!G53,DBAGS!X53,DBAGS!G62,DBAGS!X62,DBAGS!G71,DBAGS!X71,DBAGS!G81,DBAGS!X81) -> 0.2434375 | K4: =sum(DBAGS!H5,DBAGS!Y5,DBAGS!H13,DBAGS!Y13,DBAGS!H21,DBAGS!Y21,DBAGS!H29,DBAGS!Y29,DBAGS!H37,DBAGS!Y37,DBAGS!H45,DBAGS!Y45,DBAGS!H53,DBAGS!Y53,DBAGS!H62,DBAGS!Y62,DBAGS!H71,DBAGS!Y71,DBAGS!H81,DBAGS!Y81) -> -34 | L4: =K4/(HOUR(J4)*60+(MINUTE(J4)+((SECOND(J4)/60)))) -> -0.096990444 | M4: =sum(DBAGS!J5,DBAGS!AA5,DBAGS!J13,DBAGS!AA13,DBAGS!J21,DBAGS!AA21,DBAGS!J29,DBAGS!AA29,DBAGS!J37,DBAGS!AA37,DBAGS!J45,DBAGS!AA45,DBAGS!J53,DBAGS!AA53,DBAGS!J62,DBAGS!AA62,DBAGS!J71,DBAGS!AA71,DBAGS!J81,DBAGS!AA81) -> 27 | N4: =sum(DBAGS!K5,DBAGS!AB5,DBAGS!K13,DBAGS!AB13,DBAGS!K21,DBAGS!AB21,DBAGS!K29,DBAGS!AB29,DBAGS!K37,DBAGS!AB37,DBAGS!K45,DBAGS!AB45,DBAGS!K53,DBAGS!AB53,DBAGS!K62,DBAGS!AB62,DBAGS!K71,DBAGS!AB71,DBAGS!K81,DBAGS!AB81) -> 123 | O4: =sum(DBAGS!L5,DBAGS!AC5,DBAGS!L13,DBAGS!AC13,DBAGS!L21,DBAGS!AC21,DBAGS!L29,DBAGS!AC29,DBAGS!L37,DBAGS!AC37,DBAGS!L45,DBAGS!AC45,DBAGS!L53,DBAGS!AC53,DBAGS!L62,DBAGS!AC62,DBAGS!L71,DBAGS!AC71,DBAGS!L81,DBAGS!AC81) -> 27 | P4: =sum(DBAGS!M5,DBAGS!AD5,DBAGS!M13,DBAGS!AD13,DBAGS!M21,DBAGS!AD21,DBAGS!M29,DBAGS!AD29,DBAGS!M37,DBAGS!AD37,DBAGS!M45,DBAGS!AD45,DBAGS!M53,DBAGS!AD53,DBAGS!M62,DBAGS!AD62,DBAGS!M71,DBAGS!AD71,DBAGS!M81,DBAGS!AD81) -> 9 | Q4: =sum(DBAGS!N5,DBAGS!AE5,DBAGS!N13,DBAGS!AE13,DBAGS!N21,DBAGS!AE21,DBAGS!N29,DBAGS!AE29,DBAGS!N37,DBAGS!AE37,DBAGS!N45,DBAGS!AE45,DBAGS!N53,DBAGS!AE53,DBAGS!N62,DBAGS!AE62,DBAGS!N71,DBAGS!AE71,DBAGS!N81,DBAGS!AE81) -> 13 | R4: =sum(DBAGS!O5,DBAGS!AF5,DBAGS!O13,DBAGS!AF13,DBAGS!O21,DBAGS!AF21,DBAGS!O29,DBAGS!AF29,DBAGS!O37,DBAGS!AF37,DBAGS!O45,DBAGS!AF45,DBAGS!O53,DBAGS!AF53,DBAGS!O62,DBAGS!AF62,DBAGS!O71,DBAGS!AF71,DBAGS!O81,DBAGS!AF81) -> 1 | S4: =sum(DBAGS!P5,DBAGS!AG5,DBAGS!P13,DBAGS!AG13,DBAGS!P21,DBAGS!AG21,DBAGS!P29,DBAGS!AG29,DBAGS!P37,DBAGS!AG37,DBAGS!P45,DBAGS!AG45,DBAGS!P53,DBAGS!AG53,DBAGS!P62,DBAGS!AG62,DBAGS!P71,DBAGS!AG71,DBAGS!P81,DBAGS!AG81) -> 0 | T4: =J4/I4 -> 0.0002247807
A5: Don't Be A Gonk Scet | B5: BCN19 | C5: =sum(D5:E5) -> 2 | D5: 1 | E5: 1 | F5: =sum(DBAGS!C6,DBAGS!T6,DBAGS!C14,DBAGS!T14,DBAGS!C22,DBAGS!T22,DBAGS!C30,DBAGS!T30,DBAGS!C38,DBAGS!T38,DBAGS!C46,DBAGS!T46,DBAGS!C54,DBAGS!T54,DBAGS!C63,DBAGS!T63,DBAGS!C72,DBAGS!T72,DBAGS!C82,DBAGS!T82) -> 0 | G5: =sum(DBAGS!D6,DBAGS!U6,DBAGS!D14,DBAGS!U14,DBAGS!D22,DBAGS!U22,DBAGS!D30,DBAGS!U30,DBAGS!D38,DBAGS!U38,DBAGS!D46,DBAGS!U46,DBAGS!D54,DBAGS!U54,DBAGS!D63,DBAGS!U63,DBAGS!D72,DBAGS!U72,DBAGS!D82,DBAGS!U82) -> 122 | H5: =sum(DBAGS!E6,DBAGS!V6,DBAGS!E14,DBAGS!V14,DBAGS!E22,DBAGS!V22,DBAGS!E30,DBAGS!V30,DBAGS!E38,DBAGS!V38,DBAGS!E46,DBAGS!V46,DBAGS!E54,DBAGS!V54,DBAGS!E63,DBAGS!V63,DBAGS!E72,DBAGS!V72,DBAGS!E82,DBAGS!V82) -> 0 | I5: =sum(DBAGS!F6,DBAGS!W6,DBAGS!F14,DBAGS!W14,DBAGS!F22,DBAGS!W22,DBAGS!F30,DBAGS!W30,DBAGS!F38,DBAGS!W38,DBAGS!F46,DBAGS!W46,DBAGS!F54,DBAGS!W54,DBAGS!F63,DBAGS!W63,DBAGS!F72,DBAGS!W72,DBAGS!F82,DBAGS!W82) -> 144 | J5: =sum(DBAGS!G6,DBAGS!X6,DBAGS!G14,DBAGS!X14,DBAGS!G22,DBAGS!X22,DBAGS!G30,DBAGS!X30,DBAGS!G38,DBAGS!X38,DBAGS!G46,DBAGS!X46,DBAGS!G54,DBAGS!X54,DBAGS!G63,DBAGS!X63,DBAGS!G72,DBAGS!X72,DBAGS!G82,DBAGS!X82) -> 0.030231481 | K5: =sum(DBAGS!H6,DBAGS!Y6,DBAGS!H14,DBAGS!Y14,DBAGS!H22,DBAGS!Y22,DBAGS!H30,DBAGS!Y30,DBAGS!H38,DBAGS!Y38,DBAGS!H46,DBAGS!Y46,DBAGS!H54,DBAGS!Y54,DBAGS!H63,DBAGS!Y63,DBAGS!H72,DBAGS!Y72,DBAGS!H82,DBAGS!Y82) -> -22 | L5: =K5/(HOUR(J5)*60+(MINUTE(J5)+((SECOND(J5)/60)))) -> -0.50535988 | M5: =sum(DBAGS!J6,DBAGS!AA6,DBAGS!J14,DBAGS!AA14,DBAGS!J22,DBAGS!AA22,DBAGS!J30,DBAGS!AA30,DBAGS!J38,DBAGS!AA38,DBAGS!J46,DBAGS!AA46,DBAGS!J54,DBAGS!AA54,DBAGS!J63,DBAGS!AA63,DBAGS!J72,DBAGS!AA72,DBAGS!J82,DBAGS!AA82) -> 3 | N5: =sum(DBAGS!K6,DBAGS!AB6,DBAGS!K14,DBAGS!AB14,DBAGS!K22,DBAGS!AB22,DBAGS!K30,DBAGS!AB30,DBAGS!K38,DBAGS!AB38,DBAGS!K46,DBAGS!AB46,DBAGS!K54,DBAGS!AB54,DBAGS!K63,DBAGS!AB63,DBAGS!K72,DBAGS!AB72,DBAGS!K82,DBAGS!AB82) -> 14 | O5: =sum(DBAGS!L6,DBAGS!AC6,DBAGS!L14,DBAGS!AC14,DBAGS!L22,DBAGS!AC22,DBAGS!L30,DBAGS!AC30,DBAGS!L38,DBAGS!AC38,DBAGS!L46,DBAGS!AC46,DBAGS!L54,DBAGS!AC54,DBAGS!L63,DBAGS!AC63,DBAGS!L72,DBAGS!AC72,DBAGS!L82,DBAGS!AC82) -> 4 | P5: =sum(DBAGS!M6,DBAGS!AD6,DBAGS!M14,DBAGS!AD14,DBAGS!M22,DBAGS!AD22,DBAGS!M30,DBAGS!AD30,DBAGS!M38,DBAGS!AD38,DBAGS!M46,DBAGS!AD46,DBAGS!M54,DBAGS!AD54,DBAGS!M63,DBAGS!AD63,DBAGS!M72,DBAGS!AD72,DBAGS!M82,DBAGS!AD82) -> 3 | Q5: =sum(DBAGS!N6,DBAGS!AE6,DBAGS!N14,DBAGS!AE14,DBAGS!N22,DBAGS!AE22,DBAGS!N30,DBAGS!AE30,DBAGS!N38,DBAGS!AE38,DBAGS!N46,DBAGS!AE46,DBAGS!N54,DBAGS!AE54,DBAGS!N63,DBAGS!AE63,DBAGS!N72,DBAGS!AE72,DBAGS!N82,DBAGS!AE82) -> 4 | R5: =sum(DBAGS!O6,DBAGS!AF6,DBAGS!O14,DBAGS!AF14,DBAGS!O22,DBAGS!AF22,DBAGS!O30,DBAGS!AF30,DBAGS!O38,DBAGS!AF38,DBAGS!O46,DBAGS!AF46,DBAGS!O54,DBAGS!AF54,DBAGS!O63,DBAGS!AF63,DBAGS!O72,DBAGS!AF72,DBAGS!O82,DBAGS!AF82) -> 0 | S5: =sum(DBAGS!P6,DBAGS!AG6,DBAGS!P14,DBAGS!AG14,DBAGS!P22,DBAGS!AG22,DBAGS!P30,DBAGS!AG30,DBAGS!P38,DBAGS!AG38,DBAGS!P46,DBAGS!AG46,DBAGS!P54,DBAGS!AG54,DBAGS!P63,DBAGS!AG63,DBAGS!P72,DBAGS!AG72,DBAGS!P82,DBAGS!AG82) -> 0 | T5: =J5/I5 -> 0.00020994084
A6: Don't Be A Gonk Scet | B6: nkotb4evah | C6: =sum(D6:E6) -> 16 | D6: 6 | E6: 10 | F6: =sum(DBAGS!C7,DBAGS!T7,DBAGS!C15,DBAGS!T15,DBAGS!C23,DBAGS!T23,DBAGS!C31,DBAGS!T31,DBAGS!C39,DBAGS!T39,DBAGS!C47,DBAGS!T47,DBAGS!C55,DBAGS!T55,DBAGS!C64,DBAGS!T64,DBAGS!C73,DBAGS!T73,DBAGS!C83,DBAGS!T83) -> 3 | G6: =sum(DBAGS!D7,DBAGS!U7,DBAGS!D15,DBAGS!U15,DBAGS!D23,DBAGS!U23,DBAGS!D31,DBAGS!U31,DBAGS!D39,DBAGS!U39,DBAGS!D47,DBAGS!U47,DBAGS!D55,DBAGS!U55,DBAGS!D64,DBAGS!U64,DBAGS!D73,DBAGS!U73,DBAGS!D83,DBAGS!U83) -> 1776 | H6: =sum(DBAGS!E7,DBAGS!V7,DBAGS!E15,DBAGS!V15,DBAGS!E23,DBAGS!V23,DBAGS!E31,DBAGS!V31,DBAGS!E39,DBAGS!V39,DBAGS!E47,DBAGS!V47,DBAGS!E55,DBAGS!V55,DBAGS!E64,DBAGS!V64,DBAGS!E73,DBAGS!V73,DBAGS!E83,DBAGS!V83) -> 12 | I6: =sum(DBAGS!F7,DBAGS!W7,DBAGS!F15,DBAGS!W15,DBAGS!F23,DBAGS!W23,DBAGS!F31,DBAGS!W31,DBAGS!F39,DBAGS!W39,DBAGS!F47,DBAGS!W47,DBAGS!F55,DBAGS!W55,DBAGS!F64,DBAGS!W64,DBAGS!F73,DBAGS!W73,DBAGS!F83,DBAGS!W83) -> 1962 | J6: =sum(DBAGS!G7,DBAGS!X7,DBAGS!G15,DBAGS!X15,DBAGS!G23,DBAGS!X23,DBAGS!G31,DBAGS!X31,DBAGS!G39,DBAGS!X39,DBAGS!G47,DBAGS!X47,DBAGS!G55,DBAGS!X55,DBAGS!G64,DBAGS!X64,DBAGS!G73,DBAGS!X73,DBAGS!G83,DBAGS!X83) -> 0.30752315 | K6: =sum(DBAGS!H7,DBAGS!Y7,DBAGS!H15,DBAGS!Y15,DBAGS!H23,DBAGS!Y23,DBAGS!H31,DBAGS!Y31,DBAGS!H39,DBAGS!Y39,DBAGS!H47,DBAGS!Y47,DBAGS!H55,DBAGS!Y55,DBAGS!H64,DBAGS!Y64,DBAGS!H73,DBAGS!Y73,DBAGS!H83,DBAGS!Y83) -> -186 | L6: =K6/(HOUR(J6)*60+(MINUTE(J6)+((SECOND(J6)/60)))) -> -0.42002258 | M6: =sum(DBAGS!J7,DBAGS!AA7,DBAGS!J15,DBAGS!AA15,DBAGS!J23,DBAGS!AA23,DBAGS!J31,DBAGS!AA31,DBAGS!J39,DBAGS!AA39,DBAGS!J47,DBAGS!AA47,DBAGS!J55,DBAGS!AA55,DBAGS!J64,DBAGS!AA64,DBAGS!J73,DBAGS!AA73,DBAGS!J83,DBAGS!AA83) -> 54 | N6: =sum(DBAGS!K7,DBAGS!AB7,DBAGS!K15,DBAGS!AB15,DBAGS!K23,DBAGS!AB23,DBAGS!K31,DBAGS!AB31,DBAGS!K39,DBAGS!AB39,DBAGS!K47,DBAGS!AB47,DBAGS!K55,DBAGS!AB55,DBAGS!K64,DBAGS!AB64,DBAGS!K73,DBAGS!AB73,DBAGS!K83,DBAGS!AB83) -> 285 | O6: =sum(DBAGS!L7,DBAGS!AC7,DBAGS!L15,DBAGS!AC15,DBAGS!L23,DBAGS!AC23,DBAGS!L31,DBAGS!AC31,DBAGS!L39,DBAGS!AC39,DBAGS!L47,DBAGS!AC47,DBAGS!L55,DBAGS!AC55,DBAGS!L64,DBAGS!AC64,DBAGS!L73,DBAGS!AC73,DBAGS!L83,DBAGS!AC83) -> 62 | P6: =sum(DBAGS!M7,DBAGS!AD7,DBAGS!M15,DBAGS!AD15,DBAGS!M23,DBAGS!AD23,DBAGS!M31,DBAGS!AD31,DBAGS!M39,DBAGS!AD39,DBAGS!M47,DBAGS!AD47,DBAGS!M55,DBAGS!AD55,DBAGS!M64,DBAGS!AD64,DBAGS!M73,DBAGS!AD73,DBAGS!M83,DBAGS!AD83) -> 17 | Q6: =sum(DBAGS!N7,DBAGS!AE7,DBAGS!N15,DBAGS!AE15,DBAGS!N23,DBAGS!AE23,DBAGS!N31,DBAGS!AE31,DBAGS!N39,DBAGS!AE39,DBAGS!N47,DBAGS!AE47,DBAGS!N55,DBAGS!AE55,DBAGS!N64,DBAGS!AE64,DBAGS!N73,DBAGS!AE73,DBAGS!N83,DBAGS!AE83) -> 26 | R6: =sum(DBAGS!O7,DBAGS!AF7,DBAGS!O15,DBAGS!AF15,DBAGS!O23,DBAGS!AF23,DBAGS!O31,DBAGS!AF31,DBAGS!O39,DBAGS!AF39,DBAGS!O47,DBAGS!AF47,DBAGS!O55,DBAGS!AF55,DBAGS!O64,DBAGS!AF64,DBAGS!O73,DBAGS!AF73,DBAGS!O83,DBAGS!AF83) -> 1 | S6: =sum(DBAGS!P7,DBAGS!AG7,DBAGS!P15,DBAGS!AG15,DBAGS!P23,DBAGS!AG23,DBAGS!P31,DBAGS!AG31,DBAGS!P39,DBAGS!AG39,DBAGS!P47,DBAGS!AG47,DBAGS!P55,DBAGS!AG55,DBAGS!P64,DBAGS!AG64,DBAGS!P73,DBAGS!AG73,DBAGS!P83,DBAGS!AG83) -> 0 | T6: =J6/I6 -> 0.00015673963
B7: Zeg (Sub) | C7: =sum(D7:E7) -> 6 | D7: 1 | E7: 5 | F7: =sum(DBAGS!C56,DBAGS!T56,DBAGS!C65,DBAGS!T65) -> 1 | G7: =sum(DBAGS!D56,DBAGS!U56,DBAGS!D65,DBAGS!U65) -> 420 | H7: =sum(DBAGS!E56,DBAGS!V56,DBAGS!E65,DBAGS!V65) -> 0 | I7: =sum(DBAGS!F56,DBAGS!W56,DBAGS!F65,DBAGS!W65) -> 399 | J7: =sum(DBAGS!G56,DBAGS!X56,DBAGS!G65,DBAGS!X65) -> 0.068877315 | K7: =sum(DBAGS!H56,DBAGS!Y56,DBAGS!H65,DBAGS!Y65) -> 21 | L7: =K7/(HOUR(J7)*60+(MINUTE(J7)+((SECOND(J7)/60)))) -> 0.21172912 | M7: =sum(DBAGS!J56,DBAGS!AA56,DBAGS!J65,DBAGS!AA65) -> 11 | N7: =sum(DBAGS!K56,DBAGS!AB56,DBAGS!K65,DBAGS!AB65) -> 63 | O7: =sum(DBAGS!L56,DBAGS!AC56,DBAGS!L65,DBAGS!AC65) -> 7 | P7: =sum(DBAGS!M56,DBAGS!AD56,DBAGS!M65,DBAGS!AD65) -> 4 | Q7: =sum(DBAGS!N56,DBAGS!AE56,DBAGS!N65,DBAGS!AE65) -> 7 | R7: =sum(DBAGS!O56,DBAGS!AF56,DBAGS!O65,DBAGS!AF65) -> 0 | S7: =sum(DBAGS!P56,DBAGS!AG56,DBAGS!P65,DBAGS!AG65) -> 0 | T7: =J7/I7 -> 0.00017262485
B8: AJ (Sub) | C8: 2 | D8: 0 | E8: 2 | F8: =sum(DBAGS!C9,DBAGS!T9,DBAGS!C17,DBAGS!T17,DBAGS!C25,DBAGS!T25,DBAGS!C33,DBAGS!T33,DBAGS!C41,DBAGS!T41,DBAGS!C49,DBAGS!T49,DBAGS!C57,DBAGS!T57,DBAGS!C66,DBAGS!T66,DBAGS!C75,DBAGS!T75,DBAGS!C85,DBAGS!T85) -> 3 | G8: =sum(DBAGS!D9,DBAGS!U9,DBAGS!D17,DBAGS!U17,DBAGS!D25,DBAGS!U25,DBAGS!D33,DBAGS!U33,DBAGS!D41,DBAGS!U41,DBAGS!D49,DBAGS!U49,DBAGS!D57,DBAGS!U57,DBAGS!D66,DBAGS!U66,DBAGS!D75,DBAGS!U75,DBAGS!D85,DBAGS!U85) -> 157 | H8: =sum(DBAGS!E9,DBAGS!V9,DBAGS!E17,DBAGS!V17,DBAGS!E25,DBAGS!V25,DBAGS!E33,DBAGS!V33,DBAGS!E41,DBAGS!V41,DBAGS!E49,DBAGS!V49,DBAGS!E57,DBAGS!V57,DBAGS!E66,DBAGS!V66,DBAGS!E75,DBAGS!V75,DBAGS!E85,DBAGS!V85) -> 1 | I8: =sum(DBAGS!F9,DBAGS!W9,DBAGS!F17,DBAGS!W17,DBAGS!F25,DBAGS!W25,DBAGS!F33,DBAGS!W33,DBAGS!F41,DBAGS!W41,DBAGS!F49,DBAGS!W49,DBAGS!F57,DBAGS!W57,DBAGS!F66,DBAGS!W66,DBAGS!F75,DBAGS!W75,DBAGS!F85,DBAGS!W85) -> 161 | J8: =sum(DBAGS!G9,DBAGS!X9,DBAGS!G17,DBAGS!X17,DBAGS!G25,DBAGS!X25,DBAGS!G33,DBAGS!X33,DBAGS!G41,DBAGS!X41,DBAGS!G49,DBAGS!X49,DBAGS!G57,DBAGS!X57,DBAGS!G66,DBAGS!X66,DBAGS!G75,DBAGS!X75,DBAGS!G85,DBAGS!X85) -> 0.025439815 | K8: =sum(DBAGS!H9,DBAGS!Y9,DBAGS!H17,DBAGS!Y17,DBAGS!H25,DBAGS!Y25,DBAGS!H33,DBAGS!Y33,DBAGS!H41,DBAGS!Y41,DBAGS!H49,DBAGS!Y49,DBAGS!H57,DBAGS!Y57,DBAGS!H66,DBAGS!Y66,DBAGS!H75,DBAGS!Y75,DBAGS!H85,DBAGS!Y85) -> -4 | L8: =K8/(HOUR(J8)*60+(MINUTE(J8)+((SECOND(J8)/60)))) -> -0.10919017 | M8: =sum(DBAGS!J9,DBAGS!AA9,DBAGS!J17,DBAGS!AA17,DBAGS!J25,DBAGS!AA25,DBAGS!J33,DBAGS!AA33,DBAGS!J41,DBAGS!AA41,DBAGS!J49,DBAGS!AA49,DBAGS!J57,DBAGS!AA57,DBAGS!J66,DBAGS!AA66,DBAGS!J75,DBAGS!AA75,DBAGS!J85,DBAGS!AA85) -> 10 | N8: =sum(DBAGS!K9,DBAGS!AB9,DBAGS!K17,DBAGS!AB17,DBAGS!K25,DBAGS!AB25,DBAGS!K33,DBAGS!AB33,DBAGS!K41,DBAGS!AB41,DBAGS!K49,DBAGS!AB49,DBAGS!K57,DBAGS!AB57,DBAGS!K66,DBAGS!AB66,DBAGS!K75,DBAGS!AB75,DBAGS!K85,DBAGS!AB85) -> 22 | O8: =sum(DBAGS!L9,DBAGS!AC9,DBAGS!L17,DBAGS!AC17,DBAGS!L25,DBAGS!AC25,DBAGS!L33,DBAGS!AC33,DBAGS!L41,DBAGS!AC41,DBAGS!L49,DBAGS!AC49,DBAGS!L57,DBAGS!AC57,DBAGS!L66,DBAGS!AC66,DBAGS!L75,DBAGS!AC75,DBAGS!L85,DBAGS!AC85) -> 5 | P8: =sum(DBAGS!M9,DBAGS!AD9,DBAGS!M17,DBAGS!AD17,DBAGS!M25,DBAGS!AD25,DBAGS!M33,DBAGS!AD33,DBAGS!M41,DBAGS!AD41,DBAGS!M49,DBAGS!AD49,DBAGS!M57,DBAGS!AD57,DBAGS!M66,DBAGS!AD66,DBAGS!M75,DBAGS!AD75,DBAGS!M85,DBAGS!AD85) -> 2 | Q8: =sum(DBAGS!N9,DBAGS!AE9,DBAGS!N17,DBAGS!AE17,DBAGS!N25,DBAGS!AE25,DBAGS!N33,DBAGS!AE33,DBAGS!N41,DBAGS!AE41,DBAGS!N49,DBAGS!AE49,DBAGS!N57,DBAGS!AE57,DBAGS!N66,DBAGS!AE66,DBAGS!N75,DBAGS!AE75,DBAGS!N85,DBAGS!AE85) -> 3 | R8: =sum(DBAGS!O9,DBAGS!AF9,DBAGS!O17,DBAGS!AF17,DBAGS!O25,DBAGS!AF25,DBAGS!O33,DBAGS!AF33,DBAGS!O41,DBAGS!AF41,DBAGS!O49,DBAGS!AF49,DBAGS!O57,DBAGS!AF57,DBAGS!O66,DBAGS!AF66,DBAGS!O75,DBAGS!AF75,DBAGS!O85,DBAGS!AF85) -> 0 | S8: =sum(DBAGS!P9,DBAGS!AG9,DBAGS!P17,DBAGS!AG17,DBAGS!P25,DBAGS!AG25,DBAGS!P33,DBAGS!AG33,DBAGS!P41,DBAGS!AG41,DBAGS!P49,DBAGS!AG49,DBAGS!P57,DBAGS!AG57,DBAGS!P66,DBAGS!AG66,DBAGS!P75,DBAGS!AG75,DBAGS!P85,DBAGS!AG85) -> 0 | T8: =J8/I8 -> 0.00015801127
A10: Only in Dreams | B10: its bck | C10: =sum(D10:E10) -> 18 | D10: 12 | E10: 6 | F10: =sum(OID!C3,OID!T3,OID!C11,OID!T11,OID!C19,OID!T19,OID!C27,OID!T27,OID!C35,OID!T35,OID!C43,OID!T43,OID!C51,OID!T51,OID!C59,OID!T59,OID!C67,OID!T67,OID!C75,OID!T75) -> 56 | G10: =sum(OID!D3,OID!U3,OID!D11,OID!U11,OID!D19,OID!U19,OID!D27,OID!U27,OID!D35,OID!U35,OID!D43,OID!U43,OID!D51,OID!U51,OID!D59,OID!U59,OID!D67,OID!U67,OID!D75,OID!U75) -> 1144 | H10: =sum(OID!E3,OID!V3,OID!E11,OID!V11,OID!E19,OID!V19,OID!E27,OID!V27,OID!E35,OID!V35,OID!E43,OID!V43,OID!E51,OID!V51,OID!E59,OID!V59,OID!E67,OID!V67,OID!E75,OID!V75) -> 8 | I10: =sum(OID!F3,OID!W3,OID!F11,OID!W11,OID!F19,OID!W19,OID!F27,OID!W27,OID!F35,OID!W35,OID!F43,OID!W43,OID!F51,OID!W51,OID!F59,OID!W59,OID!F67,OID!W67,OID!F75,OID!W75) -> 1278 | J10: =sum(OID!G3,OID!X3,OID!G11,OID!X11,OID!G19,OID!X19,OID!G27,OID!X27,OID!G35,OID!X35,OID!G43,OID!X43,OID!G51,OID!X51,OID!G59,OID!X59,OID!G67,OID!X67,OID!G75,OID!X75) -> 0.39974537 | K10: =sum(OID!H3,OID!Y3,OID!H11,OID!Y11,OID!H19,OID!Y19,OID!H27,OID!Y27,OID!H35,OID!Y35,OID!H43,OID!Y43,OID!H51,OID!Y51,OID!H59,OID!Y59,OID!H67,OID!Y67,OID!H75,OID!Y75) -> -134 | L10: =K10/(HOUR(J10)*60+(MINUTE(J10)+((SECOND(J10)/60)))) -> -0.23278708 | M10: =sum(OID!J3,OID!AA3,OID!J11,OID!AA11,OID!J19,OID!AA19,OID!J27,OID!AA27,OID!J35,OID!AA35,OID!J43,OID!AA43,OID!J51,OID!AA51,OID!J59,OID!AA59,OID!J67,OID!AA67,OID!J75,OID!AA75) -> 80 | N10: =sum(OID!K3,OID!AB3,OID!K11,OID!AB11,OID!K19,OID!AB19,OID!K27,OID!AB27,OID!K35,OID!AB35,OID!K43,OID!AB43,OID!K51,OID!AB51,OID!K59,OID!AB59,OID!K67,OID!AB67,OID!K75,OID!AB75) -> 110 | O10: =sum(OID!L3,OID!AC3,OID!L11,OID!AC11,OID!L19,OID!AC19,OID!L27,OID!AC27,OID!L35,OID!AC35,OID!L43,OID!AC43,OID!L51,OID!AC51,OID!L59,OID!AC59,OID!L67,OID!AC67,OID!L75,OID!AC75) -> 18 | P10: =sum(OID!M3,OID!AD3,OID!M11,OID!AD11,OID!M19,OID!AD19,OID!M27,OID!AD27,OID!M35,OID!AD35,OID!M43,OID!AD43,OID!M51,OID!AD51,OID!M59,OID!AD59,OID!M67,OID!AD67,OID!M75,OID!AD75) -> 6 | Q10: =sum(OID!N3,OID!AE3,OID!N11,OID!AE11,OID!N19,OID!AE19,OID!N27,OID!AE27,OID!N35,OID!AE35,OID!N43,OID!AE43,OID!N51,OID!AE51,OID!N59,OID!AE59,OID!N67,OID!AE67,OID!N75,OID!AE75) -> 29 | R10: =sum(OID!O3,OID!AF3,OID!O11,OID!AF11,OID!O19,OID!AF19,OID!O27,OID!AF27,OID!O35,OID!AF35,OID!O43,OID!AF43,OID!O51,OID!AF51,OID!O59,OID!AF59,OID!O67,OID!AF67,OID!O75,OID!AF75) -> 0 | S10: =sum(OID!P3,OID!AG3,OID!P11,OID!AG11,OID!P19,OID!AG19,OID!P27,OID!AG27,OID!P35,OID!AG35,OID!P43,OID!AG43,OID!P51,OID!AG51,OID!P59,OID!AG59,OID!P67,OID!AG67,OID!P75,OID!AG75) -> 0 | T10: =J10/I10 -> 0.0003127898
A11: Only in Dreams | B11: Dhmon (From MM) | C11: =sum(D11:E11) -> 18 | D11: 12 | E11: 6 | F11: =sum(OID!C4,OID!T4,OID!C12,OID!T12,OID!C20,OID!T20,OID!C28,OID!T28,OID!C36,OID!T36,OID!C44,OID!T44,OID!C52,OID!T52,OID!C60,OID!T60,OID!C68,OID!T68,OID!C76,OID!T76) -> 13 | G11: =sum(OID!D4,OID!U4,OID!D12,OID!U12,OID!D20,OID!U20,OID!D28,OID!U28,OID!D36,OID!U36,OID!D44,OID!U44,OID!D52,OID!U52,OID!D60,OID!U60,OID!D68,OID!U68,OID!D76,OID!U76) -> 2333 | H11: =sum(OID!E4,OID!V4,OID!E12,OID!V12,OID!E20,OID!V20,OID!E28,OID!V28,OID!E36,OID!V36,OID!E44,OID!V44,OID!E52,OID!V52,OID!E60,OID!V60,OID!E68,OID!V68,OID!E76,OID!V76) -> 12 | I11: =sum(OID!F4,OID!W4,OID!F12,OID!W12,OID!F20,OID!W20,OID!F28,OID!W28,OID!F36,OID!W36,OID!F44,OID!W44,OID!F52,OID!W52,OID!F60,OID!W60,OID!F68,OID!W68,OID!F76,OID!W76) -> 2129 | J11: =sum(OID!G4,OID!X4,OID!G12,OID!X12,OID!G20,OID!X20,OID!G28,OID!X28,OID!G36,OID!X36,OID!G44,OID!X44,OID!G52,OID!X52,OID!G60,OID!X60,OID!G68,OID!X68,OID!G76,OID!X76) -> 0.39974537 | K11: =sum(OID!H4,OID!Y4,OID!H12,OID!Y12,OID!H20,OID!Y20,OID!H28,OID!Y28,OID!H36,OID!Y36,OID!H44,OID!Y44,OID!H52,OID!Y52,OID!H60,OID!Y60,OID!H68,OID!Y68,OID!H76,OID!Y76) -> 204 | L11: =K11/(HOUR(J11)*60+(MINUTE(J11)+((SECOND(J11)/60)))) -> 0.35439226 | M11: =sum(OID!J4,OID!AA4,OID!J12,OID!AA12,OID!J20,OID!AA20,OID!J28,OID!AA28,OID!J36,OID!AA36,OID!J44,OID!AA44,OID!J52,OID!AA52,OID!J60,OID!AA60,OID!J68,OID!AA68,OID!J76,OID!AA76) -> 70 | N11: =sum(OID!K4,OID!AB4,OID!K12,OID!AB12,OID!K20,OID!AB20,OID!K28,OID!AB28,OID!K36,OID!AB36,OID!K44,OID!AB44,OID!K52,OID!AB52,OID!K60,OID!AB60,OID!K68,OID!AB68,OID!K76,OID!AB76) -> 376 | O11: =sum(OID!L4,OID!AC4,OID!L12,OID!AC12,OID!L20,OID!AC20,OID!L28,OID!AC28,OID!L36,OID!AC36,OID!L44,OID!AC44,OID!L52,OID!AC52,OID!L60,OID!AC60,OID!L68,OID!AC68,OID!L76,OID!AC76) -> 79 | P11: =sum(OID!M4,OID!AD4,OID!M12,OID!AD12,OID!M20,OID!AD20,OID!M28,OID!AD28,OID!M36,OID!AD36,OID!M44,OID!AD44,OID!M52,OID!AD52,OID!M60,OID!AD60,OID!M68,OID!AD68,OID!M76,OID!AD76) -> 32 | Q11: =sum(OID!N4,OID!AE4,OID!N12,OID!AE12,OID!N20,OID!AE20,OID!N28,OID!AE28,OID!N36,OID!AE36,OID!N44,OID!AE44,OID!N52,OID!AE52,OID!N60,OID!AE60,OID!N68,OID!AE68,OID!N76,OID!AE76) -> 58 | R11: =sum(OID!O4,OID!AF4,OID!O12,OID!AF12,OID!O20,OID!AF20,OID!O28,OID!AF28,OID!O36,OID!AF36,OID!O44,OID!AF44,OID!O52,OID!AF52,OID!O60,OID!AF60,OID!O68,OID!AF68,OID!O76,OID!AF76) -> 2 | S11: =sum(OID!P4,OID!AG4,OID!P12,OID!AG12,OID!P20,OID!AG20,OID!P28,OID!AG28,OID!P36,OID!AG36,OID!P44,OID!AG44,OID!P52,OID!AG52,OID!P60,OID!AG60,OID!P68,OID!AG68,OID!P76,OID!AG76) -> 0 | T11: =J11/I11 -> 0.00018776203
A12: Only in Dreams | B12: GodSnipezX (From PIE) | C12: =sum(D12:E12) -> 18 | D12: 12 | E12: 6 | F12: =sum(OID!C5,OID!T5,OID!C13,OID!T13,OID!C21,OID!T21,OID!C29,OID!T29,OID!C37,OID!T37,OID!C45,OID!T45,OID!C53,OID!T53,OID!C61,OID!T61,OID!C69,OID!T69,OID!C77,OID!T77) -> 5 | G12: =sum(OID!D5,OID!U5,OID!D13,OID!U13,OID!D21,OID!U21,OID!D29,OID!U29,OID!D37,OID!U37,OID!D45,OID!U45,OID!D53,OID!U53,OID!D61,OID!U61,OID!D69,OID!U69,OID!D77,OID!U77) -> 2134 | H12: =sum(OID!E5,OID!V5,OID!E13,OID!V13,OID!E21,OID!V21,OID!E29,OID!V29,OID!E37,OID!V37,OID!E45,OID!V45,OID!E53,OID!V53,OID!E61,OID!V61,OID!E69,OID!V69,OID!E77,OID!V77) -> 12 | I12: =sum(OID!F5,OID!W5,OID!F13,OID!W13,OID!F21,OID!W21,OID!F29,OID!W29,OID!F37,OID!W37,OID!F45,OID!W45,OID!F53,OID!W53,OID!F61,OID!W61,OID!F69,OID!W69,OID!F77,OID!W77) -> 1919 | J12: =sum(OID!G5,OID!X5,OID!G13,OID!X13,OID!G21,OID!X21,OID!G29,OID!X29,OID!G37,OID!X37,OID!G45,OID!X45,OID!G53,OID!X53,OID!G61,OID!X61,OID!G69,OID!X69,OID!G77,OID!X77) -> 0.39974537 | K12: =sum(OID!H5,OID!Y5,OID!H13,OID!Y13,OID!H21,OID!Y21,OID!H29,OID!Y29,OID!H37,OID!Y37,OID!H45,OID!Y45,OID!H53,OID!Y53,OID!H61,OID!Y61,OID!H69,OID!Y69,OID!H77,OID!Y77) -> 215 | L12: =K12/(HOUR(J12)*60+(MINUTE(J12)+((SECOND(J12)/60)))) -> 0.37350165 | M12: =sum(OID!J5,OID!AA5,OID!J13,OID!AA13,OID!J21,OID!AA21,OID!J29,OID!AA29,OID!J37,OID!AA37,OID!J45,OID!AA45,OID!J53,OID!AA53,OID!J61,OID!AA61,OID!J69,OID!AA69,OID!J77,OID!AA77) -> 70 | N12: =sum(OID!K5,OID!AB5,OID!K13,OID!AB13,OID!K21,OID!AB21,OID!K29,OID!AB29,OID!K37,OID!AB37,OID!K45,OID!AB45,OID!K53,OID!AB53,OID!K61,OID!AB61,OID!K69,OID!AB69,OID!K77,OID!AB77) -> 324 | O12: =sum(OID!L5,OID!AC5,OID!L13,OID!AC13,OID!L21,OID!AC21,OID!L29,OID!AC29,OID!L37,OID!AC37,OID!L45,OID!AC45,OID!L53,OID!AC53,OID!L61,OID!AC61,OID!L69,OID!AC69,OID!L77,OID!AC77) -> 84 | P12: =sum(OID!M5,OID!AD5,OID!M13,OID!AD13,OID!M21,OID!AD21,OID!M29,OID!AD29,OID!M37,OID!AD37,OID!M45,OID!AD45,OID!M53,OID!AD53,OID!M61,OID!AD61,OID!M69,OID!AD69,OID!M77,OID!AD77) -> 27 | Q12: =sum(OID!N5,OID!AE5,OID!N13,OID!AE13,OID!N21,OID!AE21,OID!N29,OID!AE29,OID!N37,OID!AE37,OID!N45,OID!AE45,OID!N53,OID!AE53,OID!N61,OID!AE61,OID!N69,OID!AE69,OID!N77,OID!AE77) -> 66 | R12: =sum(OID!O5,OID!AF5,OID!O13,OID!AF13,OID!O21,OID!AF21,OID!O29,OID!AF29,OID!O37,OID!AF37,OID!O45,OID!AF45,OID!O53,OID!AF53,OID!O61,OID!AF61,OID!O69,OID!AF69,OID!O77,OID!AF77) -> 1 | S12: =sum(OID!P5,OID!AG5,OID!P13,OID!AG13,OID!P21,OID!AG21,OID!P29,OID!AG29,OID!P37,OID!AG37,OID!P45,OID!AG45,OID!P53,OID!AG53,OID!P61,OID!AG61,OID!P69,OID!AG69,OID!P77,OID!AG77) -> 0 | T12: =J12/I12 -> 0.00020830921
A13: Only in Dreams | B13: SaltyPeterBread | C13: =sum(D13:E13) -> 13 | D13: 9 | E13: 4 | F13: =sum(OID!C6,OID!T6,OID!C14,OID!T14,OID!C22,OID!T22,OID!C30,OID!T30,OID!C38,OID!T38,OID!C46,OID!T46,OID!C54,OID!T54,OID!C62,OID!T62,OID!C70,OID!T70,OID!C78,OID!T78) -> 2 | G13: =sum(OID!D6,OID!U6,OID!D14,OID!U14,OID!D22,OID!U22,OID!D30,OID!U30,OID!D38,OID!U38,OID!D46,OID!U46,OID!D54,OID!U54,OID!D62,OID!U62,OID!D70,OID!U70,OID!D78,OID!U78) -> 1333 | H13: =sum(OID!E6,OID!V6,OID!E14,OID!V14,OID!E22,OID!V22,OID!E30,OID!V30,OID!E38,OID!V38,OID!E46,OID!V46,OID!E54,OID!V54,OID!E62,OID!V62,OID!E70,OID!V70,OID!E78,OID!V78) -> 2 | I13: =sum(OID!F6,OID!W6,OID!F14,OID!W14,OID!F22,OID!W22,OID!F30,OID!W30,OID!F38,OID!W38,OID!F46,OID!W46,OID!F54,OID!W54,OID!F62,OID!W62,OID!F70,OID!W70,OID!F78,OID!W78) -> 1381 | J13: =sum(OID!G6,OID!X6,OID!G14,OID!X14,OID!G22,OID!X22,OID!G30,OID!X30,OID!G38,OID!X38,OID!G46,OID!X46,OID!G54,OID!X54,OID!G62,OID!X62,OID!G70,OID!X70,OID!G78,OID!X78) -> 0.24648148 | K13: =sum(OID!H6,OID!Y6,OID!H14,OID!Y14,OID!H22,OID!Y22,OID!H30,OID!Y30,OID!H38,OID!Y38,OID!H46,OID!Y46,OID!H54,OID!Y54,OID!H62,OID!Y62,OID!H70,OID!Y70,OID!H78,OID!Y78) -> -48 | L13: =K13/(HOUR(J13)*60+(MINUTE(J13)+((SECOND(J13)/60)))) -> -0.13523666 | M13: =sum(OID!J6,OID!AA6,OID!J14,OID!AA14,OID!J22,OID!AA22,OID!J30,OID!AA30,OID!J38,OID!AA38,OID!J46,OID!AA46,OID!J54,OID!AA54,OID!J62,OID!AA62,OID!J70,OID!AA70,OID!J78,OID!AA78) -> 25 | N13: =sum(OID!K6,OID!AB6,OID!K14,OID!AB14,OID!K22,OID!AB22,OID!K30,OID!AB30,OID!K38,OID!AB38,OID!K46,OID!AB46,OID!K54,OID!AB54,OID!K62,OID!AB62,OID!K70,OID!AB70,OID!K78,OID!AB78) -> 210 | O13: =sum(OID!L6,OID!AC6,OID!L14,OID!AC14,OID!L22,OID!AC22,OID!L30,OID!AC30,OID!L38,OID!AC38,OID!L46,OID!AC46,OID!L54,OID!AC54,OID!L62,OID!AC62,OID!L70,OID!AC70,OID!L78,OID!AC78) -> 42 | P13: =sum(OID!M6,OID!AD6,OID!M14,OID!AD14,OID!M22,OID!AD22,OID!M30,OID!AD30,OID!M38,OID!AD38,OID!M46,OID!AD46,OID!M54,OID!AD54,OID!M62,OID!AD62,OID!M70,OID!AD70,OID!M78,OID!AD78) -> 18 | Q13: =sum(OID!N6,OID!AE6,OID!N14,OID!AE14,OID!N22,OID!AE22,OID!N30,OID!AE30,OID!N38,OID!AE38,OID!N46,OID!AE46,OID!N54,OID!AE54,OID!N62,OID!AE62,OID!N70,OID!AE70,OID!N78,OID!AE78) -> 24 | R13: =sum(OID!O6,OID!AF6,OID!O14,OID!AF14,OID!O22,OID!AF22,OID!O30,OID!AF30,OID!O38,OID!AF38,OID!O46,OID!AF46,OID!O54,OID!AF54,OID!O62,OID!AF62,OID!O70,OID!AF70,OID!O78,OID!AF78) -> 1 | S13: =sum(OID!P6,OID!AG6,OID!P14,OID!AG14,OID!P22,OID!AG22,OID!P30,OID!AG30,OID!P38,OID!AG38,OID!P46,OID!AG46,OID!P54,OID!AG54,OID!P62,OID!AG62,OID!P70,OID!AG70,OID!P78,OID!AG78) -> 0 | T13: =J13/I13 -> 0.00017848044
A14: Only in Dreams | B14: cxrnchip | C14: =sum(D14:E14) -> 5 | D14: 3 | E14: 2 | F14: =sum(OID!C7,OID!T7,OID!C15,OID!T15,OID!C23,OID!T23,OID!C31,OID!T31,OID!C39,OID!T39,OID!C47,OID!T47,OID!C55,OID!T55,OID!C63,OID!T63,OID!C71,OID!T71,OID!C79,OID!T79) -> 5 | G14: =sum(OID!D7,OID!U7,OID!D15,OID!U15,OID!D23,OID!U23,OID!D31,OID!U31,OID!D39,OID!U39,OID!D47,OID!U47,OID!D55,OID!U55,OID!D63,OID!U63,OID!D71,OID!U71,OID!D79,OID!U79) -> 667 | H14: =sum(OID!E7,OID!V7,OID!E15,OID!V15,OID!E23,OID!V23,OID!E31,OID!V31,OID!E39,OID!V39,OID!E47,OID!V47,OID!E55,OID!V55,OID!E63,OID!V63,OID!E71,OID!V71,OID!E79,OID!V79) -> 2 | I14: =sum(OID!F7,OID!W7,OID!F15,OID!W15,OID!F23,OID!W23,OID!F31,OID!W31,OID!F39,OID!W39,OID!F47,OID!W47,OID!F55,OID!W55,OID!F63,OID!W63,OID!F71,OID!W71,OID!F79,OID!W79) -> 702 | J14: =sum(OID!G7,OID!X7,OID!G15,OID!X15,OID!G23,OID!X23,OID!G31,OID!X31,OID!G39,OID!X39,OID!G47,OID!X47,OID!G55,OID!X55,OID!G63,OID!X63,OID!G71,OID!X71,OID!G79,OID!X79) -> 0.15326389 | K14: =sum(OID!H7,OID!Y7,OID!H15,OID!Y15,OID!H23,OID!Y23,OID!H31,OID!Y31,OID!H39,OID!Y39,OID!H47,OID!Y47,OID!H55,OID!Y55,OID!H63,OID!Y63,OID!H71,OID!Y71,OID!H79,OID!Y79) -> -35 | L14: =K14/(HOUR(J14)*60+(MINUTE(J14)+((SECOND(J14)/60)))) -> -0.15858632 | M14: =sum(OID!J7,OID!AA7,OID!J15,OID!AA15,OID!J23,OID!AA23,OID!J31,OID!AA31,OID!J39,OID!AA39,OID!J47,OID!AA47,OID!J55,OID!AA55,OID!J63,OID!AA63,OID!J71,OID!AA71,OID!J79,OID!AA79) -> 24 | N14: =sum(OID!K7,OID!AB7,OID!K15,OID!AB15,OID!K23,OID!AB23,OID!K31,OID!AB31,OID!K39,OID!AB39,OID!K47,OID!AB47,OID!K55,OID!AB55,OID!K63,OID!AB63,OID!K71,OID!AB71,OID!K79,OID!AB79) -> 77 | O14: =sum(OID!L7,OID!AC7,OID!L15,OID!AC15,OID!L23,OID!AC23,OID!L31,OID!AC31,OID!L39,OID!AC39,OID!L47,OID!AC47,OID!L55,OID!AC55,OID!L63,OID!AC63,OID!L71,OID!AC71,OID!L79,OID!AC79) -> 23 | P14: =sum(OID!M7,OID!AD7,OID!M15,OID!AD15,OID!M23,OID!AD23,OID!M31,OID!AD31,OID!M39,OID!AD39,OID!M47,OID!AD47,OID!M55,OID!AD55,OID!M63,OID!AD63,OID!M71,OID!AD71,OID!M79,OID!AD79) -> 11 | Q14: =sum(OID!N7,OID!AE7,OID!N15,OID!AE15,OID!N23,OID!AE23,OID!N31,OID!AE31,OID!N39,OID!AE39,OID!N47,OID!AE47,OID!N55,OID!AE55,OID!N63,OID!AE63,OID!N71,OID!AE71,OID!N79,OID!AE79) -> 12 | R14: =sum(OID!O7,OID!AF7,OID!O15,OID!AF15,OID!O23,OID!AF23,OID!O31,OID!AF31,OID!O39,OID!AF39,OID!O47,OID!AF47,OID!O55,OID!AF55,OID!O63,OID!AF63,OID!O71,OID!AF71,OID!O79,OID!AF79) -> 0 | S14: =sum(OID!P7,OID!AG7,OID!P15,OID!AG15,OID!P23,OID!AG23,OID!P31,OID!AG31,OID!P39,OID!AG39,OID!P47,OID!AG47,OID!P55,OID!AG55,OID!P63,OID!AG63,OID!P71,OID!AG71,OID!P79,OID!AG79) -> 1 | T14: =J14/I14 -> 0.00021832463
A16: Bridge For Host | B16: Xerack Pls | C16: =sum(D16:E16) -> 18 | D16: 10 | E16: 8 | F16: =sum(BFH!C3,BFH!T3,BFH!C11,BFH!T11,BFH!C19,BFH!T19,BFH!C27,BFH!T27,BFH!C35,BFH!T35,BFH!C43,BFH!T43,BFH!C51,BFH!T51,BFH!C59,BFH!T59,BFH!C67,BFH!T67,BFH!C75,BFH!T75) -> 59 | G16: =sum(BFH!D3,BFH!U3,BFH!D11,BFH!U11,BFH!D19,BFH!U19,BFH!D27,BFH!U27,BFH!D35,BFH!U35,BFH!D43,BFH!U43,BFH!D51,BFH!U51,BFH!D59,BFH!U59,BFH!D67,BFH!U67,BFH!D75,BFH!U75) -> 1044 | H16: =sum(BFH!E3,BFH!V3,BFH!E11,BFH!V11,BFH!E19,BFH!V19,BFH!E27,BFH!V27,BFH!E35,BFH!V35,BFH!E43,BFH!V43,BFH!E51,BFH!V51,BFH!E59,BFH!V59,BFH!E67,BFH!V67,BFH!E75,BFH!V75) -> 9 | I16: =sum(BFH!F3,BFH!W3,BFH!F11,BFH!W11,BFH!F19,BFH!W19,BFH!F27,BFH!W27,BFH!F35,BFH!W35,BFH!F43,BFH!W43,BFH!F51,BFH!W51,BFH!F59,BFH!W59,BFH!F67,BFH!W67,BFH!F75,BFH!W75) -> 1028 | J16: =sum(BFH!G3,BFH!X3,BFH!G11,BFH!X11,BFH!G19,BFH!X19,BFH!G27,BFH!X27,BFH!G35,BFH!X35,BFH!G43,BFH!X43,BFH!G51,BFH!X51,BFH!G59,BFH!X59,BFH!G67,BFH!X67,BFH!G75,BFH!X75) -> 0.38283565 | K16: =sum(BFH!H3,BFH!Y3,BFH!H11,BFH!Y11,BFH!H19,BFH!Y19,BFH!H27,BFH!Y27,BFH!H35,BFH!Y35,BFH!H43,BFH!Y43,BFH!H51,BFH!Y51,BFH!H59,BFH!Y59,BFH!H67,BFH!Y67,BFH!H75,BFH!Y75) -> 16 | L16: =K16/(HOUR(J16)*60+(MINUTE(J16)+((SECOND(J16)/60)))) -> 0.029023188 | M16: =sum(BFH!J3,BFH!AA3,BFH!J11,BFH!AA11,BFH!J19,BFH!AA19,BFH!J27,BFH!AA27,BFH!J35,BFH!AA35,BFH!J43,BFH!AA43,BFH!J51,BFH!AA51,BFH!J59,BFH!AA59,BFH!J67,BFH!AA67,BFH!J75,BFH!AA75) -> 52 | N16: =sum(BFH!K3,BFH!AB3,BFH!K11,BFH!AB11,BFH!K19,BFH!AB19,BFH!K27,BFH!AB27,BFH!K35,BFH!AB35,BFH!K43,BFH!AB43,BFH!K51,BFH!AB51,BFH!K59,BFH!AB59,BFH!K67,BFH!AB67,BFH!K75,BFH!AB75) -> 103 | O16: =sum(BFH!L3,BFH!AC3,BFH!L11,BFH!AC11,BFH!L19,BFH!AC19,BFH!L27,BFH!AC27,BFH!L35,BFH!AC35,BFH!L43,BFH!AC43,BFH!L51,BFH!AC51,BFH!L59,BFH!AC59,BFH!L67,BFH!AC67,BFH!L75,BFH!AC75) -> 10 | P16: =sum(BFH!M3,BFH!AD3,BFH!M11,BFH!AD11,BFH!M19,BFH!AD19,BFH!M27,BFH!AD27,BFH!M35,BFH!AD35,BFH!M43,BFH!AD43,BFH!M51,BFH!AD51,BFH!M59,BFH!AD59,BFH!M67,BFH!AD67,BFH!M75,BFH!AD75) -> 4 | Q16: =sum(BFH!N3,BFH!AE3,BFH!N11,BFH!AE11,BFH!N19,BFH!AE19,BFH!N27,BFH!AE27,BFH!N35,BFH!AE35,BFH!N43,BFH!AE43,BFH!N51,BFH!AE51,BFH!N59,BFH!AE59,BFH!N67,BFH!AE67,BFH!N75,BFH!AE75) -> 23 | R16: =sum(BFH!O3,BFH!AF3,BFH!O11,BFH!AF11,BFH!O19,BFH!AF19,BFH!O27,BFH!AF27,BFH!O35,BFH!AF35,BFH!O43,BFH!AF43,BFH!O51,BFH!AF51,BFH!O59,BFH!AF59,BFH!O67,BFH!AF67,BFH!O75,BFH!AF75) -> 1 | S16: =sum(BFH!P3,BFH!AG3,BFH!P11,BFH!AG11,BFH!P19,BFH!AG19,BFH!P27,BFH!AG27,BFH!P35,BFH!AG35,BFH!P43,BFH!AG43,BFH!P51,BFH!AG51,BFH!P59,BFH!AG59,BFH!P67,BFH!AG67,BFH!P75,BFH!AG75) -> 1 | T16: =J16/I16 -> 0.00037240822
A17: Bridge For Host | B17: Ace B S1entND1 | C17: =sum(D17:E17) -> 18 | D17: 10 | E17: 8 | F17: =sum(BFH!C4,BFH!T4,BFH!C12,BFH!T12,BFH!C20,BFH!T20,BFH!C28,BFH!T28,BFH!C36,BFH!T36,BFH!C44,BFH!T44,BFH!C52,BFH!T52,BFH!C60,BFH!T60,BFH!C68,BFH!T68,BFH!C76,BFH!T76) -> 5 | G17: =sum(BFH!D4,BFH!U4,BFH!D12,BFH!U12,BFH!D20,BFH!U20,BFH!D28,BFH!U28,BFH!D36,BFH!U36,BFH!D44,BFH!U44,BFH!D52,BFH!U52,BFH!D60,BFH!U60,BFH!D68,BFH!U68,BFH!D76,BFH!U76) -> 2272 | H17: =sum(BFH!E4,BFH!V4,BFH!E12,BFH!V12,BFH!E20,BFH!V20,BFH!E28,BFH!V28,BFH!E36,BFH!V36,BFH!E44,BFH!V44,BFH!E52,BFH!V52,BFH!E60,BFH!V60,BFH!E68,BFH!V68,BFH!E76,BFH!V76) -> 6 | I17: =sum(BFH!F4,BFH!W4,BFH!F12,BFH!W12,BFH!F20,BFH!W20,BFH!F28,BFH!W28,BFH!F36,BFH!W36,BFH!F44,BFH!W44,BFH!F52,BFH!W52,BFH!F60,BFH!W60,BFH!F68,BFH!W68,BFH!F76,BFH!W76) -> 1980 | J17: =sum(BFH!G4,BFH!X4,BFH!G12,BFH!X12,BFH!G20,BFH!X20,BFH!G28,BFH!X28,BFH!G36,BFH!X36,BFH!G44,BFH!X44,BFH!G52,BFH!X52,BFH!G60,BFH!X60,BFH!G68,BFH!X68,BFH!G76,BFH!X76) -> 0.38283565 | K17: =sum(BFH!H4,BFH!Y4,BFH!H12,BFH!Y12,BFH!H20,BFH!Y20,BFH!H28,BFH!Y28,BFH!H36,BFH!Y36,BFH!H44,BFH!Y44,BFH!H52,BFH!Y52,BFH!H60,BFH!Y60,BFH!H68,BFH!Y68,BFH!H76,BFH!Y76) -> 292 | L17: =K17/(HOUR(J17)*60+(MINUTE(J17)+((SECOND(J17)/60)))) -> 0.52967319 | M17: =sum(BFH!J4,BFH!AA4,BFH!J12,BFH!AA12,BFH!J20,BFH!AA20,BFH!J28,BFH!AA28,BFH!J36,BFH!AA36,BFH!J44,BFH!AA44,BFH!J52,BFH!AA52,BFH!J60,BFH!AA60,BFH!J68,BFH!AA68,BFH!J76,BFH!AA76) -> 54 | N17: =sum(BFH!K4,BFH!AB4,BFH!K12,BFH!AB12,BFH!K20,BFH!AB20,BFH!K28,BFH!AB28,BFH!K36,BFH!AB36,BFH!K44,BFH!AB44,BFH!K52,BFH!AB52,BFH!K60,BFH!AB60,BFH!K68,BFH!AB68,BFH!K76,BFH!AB76) -> 357 | O17: =sum(BFH!L4,BFH!AC4,BFH!L12,BFH!AC12,BFH!L20,BFH!AC20,BFH!L28,BFH!AC28,BFH!L36,BFH!AC36,BFH!L44,BFH!AC44,BFH!L52,BFH!AC52,BFH!L60,BFH!AC60,BFH!L68,BFH!AC68,BFH!L76,BFH!AC76) -> 72 | P17: =sum(BFH!M4,BFH!AD4,BFH!M12,BFH!AD12,BFH!M20,BFH!AD20,BFH!M28,BFH!AD28,BFH!M36,BFH!AD36,BFH!M44,BFH!AD44,BFH!M52,BFH!AD52,BFH!M60,BFH!AD60,BFH!M68,BFH!AD68,BFH!M76,BFH!AD76) -> 65 | Q17: =sum(BFH!N4,BFH!AE4,BFH!N12,BFH!AE12,BFH!N20,BFH!AE20,BFH!N28,BFH!AE28,BFH!N36,BFH!AE36,BFH!N44,BFH!AE44,BFH!N52,BFH!AE52,BFH!N60,BFH!AE60,BFH!N68,BFH!AE68,BFH!N76,BFH!AE76) -> 61 | R17: =sum(BFH!O4,BFH!AF4,BFH!O12,BFH!AF12,BFH!O20,BFH!AF20,BFH!O28,BFH!AF28,BFH!O36,BFH!AF36,BFH!O44,BFH!AF44,BFH!O52,BFH!AF52,BFH!O60,BFH!AF60,BFH!O68,BFH!AF68,BFH!O76,BFH!AF76) -> 3 | S17: =sum(BFH!P4,BFH!AG4,BFH!P12,BFH!AG12,BFH!P20,BFH!AG20,BFH!P28,BFH!AG28,BFH!P36,BFH!AG36,BFH!P44,BFH!AG44,BFH!P52,BFH!AG52,BFH!P60,BFH!AG60,BFH!P68,BFH!AG68,BFH!P76,BFH!AG76) -> 0 | T17: =J17/I17 -> 0.00019335134
A18: Bridge For Host | B18: Rage More Nerd | C18: =sum(D18:E18) -> 18 | D18: 10 | E18: 8 | F18: =sum(BFH!C5,BFH!T5,BFH!C13,BFH!T13,BFH!C21,BFH!T21,BFH!C29,BFH!T29,BFH!C37,BFH!T37,BFH!C45,BFH!T45,BFH!C53,BFH!T53,BFH!C61,BFH!T61,BFH!C69,BFH!T69,BFH!C77,BFH!T77) -> 5 | G18: =sum(BFH!D5,BFH!U5,BFH!D13,BFH!U13,BFH!D21,BFH!U21,BFH!D29,BFH!U29,BFH!D37,BFH!U37,BFH!D45,BFH!U45,BFH!D53,BFH!U53,BFH!D61,BFH!U61,BFH!D69,BFH!U69,BFH!D77,BFH!U77) -> 1887 | H18: =sum(BFH!E5,BFH!V5,BFH!E13,BFH!V13,BFH!E21,BFH!V21,BFH!E29,BFH!V29,BFH!E37,BFH!V37,BFH!E45,BFH!V45,BFH!E53,BFH!V53,BFH!E61,BFH!V61,BFH!E69,BFH!V69,BFH!E77,BFH!V77) -> 12 | I18: =sum(BFH!F5,BFH!W5,BFH!F13,BFH!W13,BFH!F21,BFH!W21,BFH!F29,BFH!W29,BFH!F37,BFH!W37,BFH!F45,BFH!W45,BFH!F53,BFH!W53,BFH!F61,BFH!W61,BFH!F69,BFH!W69,BFH!F77,BFH!W77) -> 1906 | J18: =sum(BFH!G5,BFH!X5,BFH!G13,BFH!X13,BFH!G21,BFH!X21,BFH!G29,BFH!X29,BFH!G37,BFH!X37,BFH!G45,BFH!X45,BFH!G53,BFH!X53,BFH!G61,BFH!X61,BFH!G69,BFH!X69,BFH!G77,BFH!X77) -> 0.38283565 | K18: =sum(BFH!H5,BFH!Y5,BFH!H13,BFH!Y13,BFH!H21,BFH!Y21,BFH!H29,BFH!Y29,BFH!H37,BFH!Y37,BFH!H45,BFH!Y45,BFH!H53,BFH!Y53,BFH!H61,BFH!Y61,BFH!H69,BFH!Y69,BFH!H77,BFH!Y77) -> -19 | L18: =K18/(HOUR(J18)*60+(MINUTE(J18)+((SECOND(J18)/60)))) -> -0.034465036 | M18: =sum(BFH!J5,BFH!AA5,BFH!J13,BFH!AA13,BFH!J21,BFH!AA21,BFH!J29,BFH!AA29,BFH!J37,BFH!AA37,BFH!J45,BFH!AA45,BFH!J53,BFH!AA53,BFH!J61,BFH!AA61,BFH!J69,BFH!AA69,BFH!J77,BFH!AA77) -> 51 | N18: =sum(BFH!K5,BFH!AB5,BFH!K13,BFH!AB13,BFH!K21,BFH!AB21,BFH!K29,BFH!AB29,BFH!K37,BFH!AB37,BFH!K45,BFH!AB45,BFH!K53,BFH!AB53,BFH!K61,BFH!AB61,BFH!K69,BFH!AB69,BFH!K77,BFH!AB77) -> 285 | O18: =sum(BFH!L5,BFH!AC5,BFH!L13,BFH!AC13,BFH!L21,BFH!AC21,BFH!L29,BFH!AC29,BFH!L37,BFH!AC37,BFH!L45,BFH!AC45,BFH!L53,BFH!AC53,BFH!L61,BFH!AC61,BFH!L69,BFH!AC69,BFH!L77,BFH!AC77) -> 58 | P18: =sum(BFH!M5,BFH!AD5,BFH!M13,BFH!AD13,BFH!M21,BFH!AD21,BFH!M29,BFH!AD29,BFH!M37,BFH!AD37,BFH!M45,BFH!AD45,BFH!M53,BFH!AD53,BFH!M61,BFH!AD61,BFH!M69,BFH!AD69,BFH!M77,BFH!AD77) -> 21 | Q18: =sum(BFH!N5,BFH!AE5,BFH!N13,BFH!AE13,BFH!N21,BFH!AE21,BFH!N29,BFH!AE29,BFH!N37,BFH!AE37,BFH!N45,BFH!AE45,BFH!N53,BFH!AE53,BFH!N61,BFH!AE61,BFH!N69,BFH!AE69,BFH!N77,BFH!AE77) -> 48 | R18: =sum(BFH!O5,BFH!AF5,BFH!O13,BFH!AF13,BFH!O21,BFH!AF21,BFH!O29,BFH!AF29,BFH!O37,BFH!AF37,BFH!O45,BFH!AF45,BFH!O53,BFH!AF53,BFH!O61,BFH!AF61,BFH!O69,BFH!AF69,BFH!O77,BFH!AF77) -> 3 | S18: =sum(BFH!P5,BFH!AG5,BFH!P13,BFH!AG13,BFH!P21,BFH!AG21,BFH!P29,BFH!AG29,BFH!P37,BFH!AG37,BFH!P45,BFH!AG45,BFH!P53,BFH!AG53,BFH!P61,BFH!AG61,BFH!P69,BFH!AG69,BFH!P77,BFH!AG77) -> 0 | T18: =J18/I18 -> 0.00020085816
A19: Bridge For Host | B19: Tad Neptune | C19: =sum(D19:E19) -> 17 | D19: 10 | E19: 7 | F19: =sum(BFH!C6,BFH!T6,BFH!C14,BFH!T14,BFH!C22,BFH!T22,BFH!C30,BFH!T30,BFH!C38,BFH!T38,BFH!C46,BFH!T46,BFH!C54,BFH!T54,BFH!C62,BFH!T62,BFH!C70,BFH!T70,BFH!C78,BFH!T78) -> 5 | G19: =sum(BFH!D6,BFH!U6,BFH!D14,BFH!U14,BFH!D22,BFH!U22,BFH!D30,BFH!U30,BFH!D38,BFH!U38,BFH!D46,BFH!U46,BFH!D54,BFH!U54,BFH!D62,BFH!U62,BFH!D70,BFH!U70,BFH!D78,BFH!U78) -> 1637 | H19: =sum(BFH!E6,BFH!V6,BFH!E14,BFH!V14,BFH!E22,BFH!V22,BFH!E30,BFH!V30,BFH!E38,BFH!V38,BFH!E46,BFH!V46,BFH!E54,BFH!V54,BFH!E62,BFH!V62,BFH!E70,BFH!V70,BFH!E78,BFH!V78) -> 2 | I19: =sum(BFH!F6,BFH!W6,BFH!F14,BFH!W14,BFH!F22,BFH!W22,BFH!F30,BFH!W30,BFH!F38,BFH!W38,BFH!F46,BFH!W46,BFH!F54,BFH!W54,BFH!F62,BFH!W62,BFH!F70,BFH!W70,BFH!F78,BFH!W78) -> 1842 | J19: =sum(BFH!G6,BFH!X6,BFH!G14,BFH!X14,BFH!G22,BFH!X22,BFH!G30,BFH!X30,BFH!G38,BFH!X38,BFH!G46,BFH!X46,BFH!G54,BFH!X54,BFH!G62,BFH!X62,BFH!G70,BFH!X70,BFH!G78,BFH!X78) -> 0.34828704 | K19: =sum(BFH!H6,BFH!Y6,BFH!H14,BFH!Y14,BFH!H22,BFH!Y22,BFH!H30,BFH!Y30,BFH!H38,BFH!Y38,BFH!H46,BFH!Y46,BFH!H54,BFH!Y54,BFH!H62,BFH!Y62,BFH!H70,BFH!Y70,BFH!H78,BFH!Y78) -> -205 | L19: =K19/(HOUR(J19)*60+(MINUTE(J19)+((SECOND(J19)/60)))) -> -0.40874651 | M19: =sum(BFH!J6,BFH!AA6,BFH!J14,BFH!AA14,BFH!J22,BFH!AA22,BFH!J30,BFH!AA30,BFH!J38,BFH!AA38,BFH!J46,BFH!AA46,BFH!J54,BFH!AA54,BFH!J62,BFH!AA62,BFH!J70,BFH!AA70,BFH!J78,BFH!AA78) -> 47 | N19: =sum(BFH!K6,BFH!AB6,BFH!K14,BFH!AB14,BFH!K22,BFH!AB22,BFH!K30,BFH!AB30,BFH!K38,BFH!AB38,BFH!K46,BFH!AB46,BFH!K54,BFH!AB54,BFH!K62,BFH!AB62,BFH!K70,BFH!AB70,BFH!K78,BFH!AB78) -> 229 | O19: =sum(BFH!L6,BFH!AC6,BFH!L14,BFH!AC14,BFH!L22,BFH!AC22,BFH!L30,BFH!AC30,BFH!L38,BFH!AC38,BFH!L46,BFH!AC46,BFH!L54,BFH!AC54,BFH!L62,BFH!AC62,BFH!L70,BFH!AC70,BFH!L78,BFH!AC78) -> 48 | P19: =sum(BFH!M6,BFH!AD6,BFH!M14,BFH!AD14,BFH!M22,BFH!AD22,BFH!M30,BFH!AD30,BFH!M38,BFH!AD38,BFH!M46,BFH!AD46,BFH!M54,BFH!AD54,BFH!M62,BFH!AD62,BFH!M70,BFH!AD70,BFH!M78,BFH!AD78) -> 12 | Q19: =sum(BFH!N6,BFH!AE6,BFH!N14,BFH!AE14,BFH!N22,BFH!AE22,BFH!N30,BFH!AE30,BFH!N38,BFH!AE38,BFH!N46,BFH!AE46,BFH!N54,BFH!AE54,BFH!N62,BFH!AE62,BFH!N70,BFH!AE70,BFH!N78,BFH!AE78) -> 23 | R19: =sum(BFH!O6,BFH!AF6,BFH!O14,BFH!AF14,BFH!O22,BFH!AF22,BFH!O30,BFH!AF30,BFH!O38,BFH!AF38,BFH!O46,BFH!AF46,BFH!O54,BFH!AF54,BFH!O62,BFH!AF62,BFH!O70,BFH!AF70,BFH!O78,BFH!AF78) -> 1 | S19: =sum(BFH!P6,BFH!AG6,BFH!P14,BFH!AG14,BFH!P22,BFH!AG22,BFH!P30,BFH!AG30,BFH!P38,BFH!AG38,BFH!P46,BFH!AG46,BFH!P54,BFH!AG54,BFH!P62,BFH!AG62,BFH!P70,BFH!AG70,BFH!P78,BFH!AG78) -> 1 | T19: =J19/I19 -> 0.00018908091
A20: Bridge For Host | B20: Myst The Cold | C20: =sum(D20:E20) -> 1 | D20: 0 | E20: 1 | F20: =sum(BFH!C7,BFH!T7,BFH!C15,BFH!T15,BFH!C23,BFH!T23,BFH!C31,BFH!T31,BFH!C39,BFH!T39,BFH!C47,BFH!T47,BFH!C55,BFH!T55,BFH!C63,BFH!T63,BFH!C71,BFH!T71,BFH!C79,BFH!T79) -> 0 | G20: =sum(BFH!D7,BFH!U7,BFH!D15,BFH!U15,BFH!D23,BFH!U23,BFH!D31,BFH!U31,BFH!D39,BFH!U39,BFH!D47,BFH!U47,BFH!D55,BFH!U55,BFH!D63,BFH!U63,BFH!D71,BFH!U71,BFH!D79,BFH!U79) -> 110 | H20: =sum(BFH!E7,BFH!V7,BFH!E15,BFH!V15,BFH!E23,BFH!V23,BFH!E31,BFH!V31,BFH!E39,BFH!V39,BFH!E47,BFH!V47,BFH!E55,BFH!V55,BFH!E63,BFH!V63,BFH!E71,BFH!V71,BFH!E79,BFH!V79) -> 1 | I20: =sum(BFH!F7,BFH!W7,BFH!F15,BFH!W15,BFH!F23,BFH!W23,BFH!F31,BFH!W31,BFH!F39,BFH!W39,BFH!F47,BFH!W47,BFH!F55,BFH!W55,BFH!F63,BFH!W63,BFH!F71,BFH!W71,BFH!F79,BFH!W79) -> 150 | J20: =sum(BFH!G7,BFH!X7,BFH!G15,BFH!X15,BFH!G23,BFH!X23,BFH!G31,BFH!X31,BFH!G39,BFH!X39,BFH!G47,BFH!X47,BFH!G55,BFH!X55,BFH!G63,BFH!X63,BFH!G71,BFH!X71,BFH!G79,BFH!X79) -> 0.034548611 | K20: =sum(BFH!H7,BFH!Y7,BFH!H15,BFH!Y15,BFH!H23,BFH!Y23,BFH!H31,BFH!Y31,BFH!H39,BFH!Y39,BFH!H47,BFH!Y47,BFH!H55,BFH!Y55,BFH!H63,BFH!Y63,BFH!H71,BFH!Y71,BFH!H79,BFH!Y79) -> -40 | L20: =K20/(HOUR(J20)*60+(MINUTE(J20)+((SECOND(J20)/60)))) -> -0.8040201 | M20: =sum(BFH!J7,BFH!AA7,BFH!J15,BFH!AA15,BFH!J23,BFH!AA23,BFH!J31,BFH!AA31,BFH!J39,BFH!AA39,BFH!J47,BFH!AA47,BFH!J55,BFH!AA55,BFH!J63,BFH!AA63,BFH!J71,BFH!AA71,BFH!J79,BFH!AA79) -> 4 | N20: =sum(BFH!K7,BFH!AB7,BFH!K15,BFH!AB15,BFH!K23,BFH!AB23,BFH!K31,BFH!AB31,BFH!K39,BFH!AB39,BFH!K47,BFH!AB47,BFH!K55,BFH!AB55,BFH!K63,BFH!AB63,BFH!K71,BFH!AB71,BFH!K79,BFH!AB79) -> 9 | O20: =sum(BFH!L7,BFH!AC7,BFH!L15,BFH!AC15,BFH!L23,BFH!AC23,BFH!L31,BFH!AC31,BFH!L39,BFH!AC39,BFH!L47,BFH!AC47,BFH!L55,BFH!AC55,BFH!L63,BFH!AC63,BFH!L71,BFH!AC71,BFH!L79,BFH!AC79) -> 1 | P20: =sum(BFH!M7,BFH!AD7,BFH!M15,BFH!AD15,BFH!M23,BFH!AD23,BFH!M31,BFH!AD31,BFH!M39,BFH!AD39,BFH!M47,BFH!AD47,BFH!M55,BFH!AD55,BFH!M63,BFH!AD63,BFH!M71,BFH!AD71,BFH!M79,BFH!AD79) -> 0 | Q20: =sum(BFH!N7,BFH!AE7,BFH!N15,BFH!AE15,BFH!N23,BFH!AE23,BFH!N31,BFH!AE31,BFH!N39,BFH!AE39,BFH!N47,BFH!AE47,BFH!N55,BFH!AE55,BFH!N63,BFH!AE63,BFH!N71,BFH!AE71,BFH!N79,BFH!AE79) -> 3 | R20: =sum(BFH!O7,BFH!AF7,BFH!O15,BFH!AF15,BFH!O23,BFH!AF23,BFH!O31,BFH!AF31,BFH!O39,BFH!AF39,BFH!O47,BFH!AF47,BFH!O55,BFH!AF55,BFH!O63,BFH!AF63,BFH!O71,BFH!AF71,BFH!O79,BFH!AF79) -> 0 | S20: =sum(BFH!P7,BFH!AG7,BFH!P15,BFH!AG15,BFH!P23,BFH!AG23,BFH!P31,BFH!AG31,BFH!P39,BFH!AG39,BFH!P47,BFH!AG47,BFH!P55,BFH!AG55,BFH!P63,BFH!AG63,BFH!P71,BFH!AG71,BFH!P79,BFH!AG79) -> 0 | T20: =J20/I20 -> 0.00023032407
A22: Chaos of the Missing Pens | B22: DCleak | C22: =sum(D22:E22) -> 16 | D22: 3 | E22: 13 | F22: =sum(CMP!C3,CMP!T3,CMP!C11,CMP!T11,CMP!C19,CMP!T19,CMP!C27,CMP!T27,CMP!C35,CMP!T35,CMP!C43,CMP!T43,CMP!C51,CMP!T51,CMP!C59,CMP!T59,CMP!C68,CMP!T68,CMP!C76,CMP!T76) -> 13 | G22: =sum(CMP!D3,CMP!U3,CMP!D11,CMP!U11,CMP!D19,CMP!U19,CMP!D27,CMP!U27,CMP!D35,CMP!U35,CMP!D43,CMP!U43,CMP!D51,CMP!U51,CMP!D59,CMP!U59,CMP!D68,CMP!U68,CMP!D76,CMP!U76) -> 1089 | H22: =sum(CMP!E3,CMP!V3,CMP!E11,CMP!V11,CMP!E19,CMP!V19,CMP!E27,CMP!V27,CMP!E35,CMP!V35,CMP!E43,CMP!V43,CMP!E51,CMP!V51,CMP!E59,CMP!V59,CMP!E68,CMP!V68,CMP!E76,CMP!V76) -> 7 | I22: =sum(CMP!F3,CMP!W3,CMP!F11,CMP!W11,CMP!F19,CMP!W19,CMP!F27,CMP!W27,CMP!F35,CMP!W35,CMP!F43,CMP!W43,CMP!F51,CMP!W51,CMP!F59,CMP!W59,CMP!F68,CMP!W68,CMP!F76,CMP!W76) -> 1298 | J22: =sum(CMP!G3,CMP!X3,CMP!G11,CMP!X11,CMP!G19,CMP!X19,CMP!G27,CMP!X27,CMP!G35,CMP!X35,CMP!G43,CMP!X43,CMP!G51,CMP!X51,CMP!G59,CMP!X59,CMP!G68,CMP!X68,CMP!G76,CMP!X76) -> 0.2590162 | K22: =sum(CMP!H3,CMP!Y3,CMP!H11,CMP!Y11,CMP!H19,CMP!Y19,CMP!H27,CMP!Y27,CMP!H35,CMP!Y35,CMP!H43,CMP!Y43,CMP!H51,CMP!Y51,CMP!H59,CMP!Y59,CMP!H68,CMP!Y68,CMP!H76,CMP!Y76) -> -209 | L22: =K22/(HOUR(J22)*60+(MINUTE(J22)+((SECOND(J22)/60)))) -> -0.56034675 | M22: =sum(CMP!J3,CMP!AA3,CMP!J11,CMP!AA11,CMP!J19,CMP!AA19,CMP!J27,CMP!AA27,CMP!J35,CMP!AA35,CMP!J43,CMP!AA43,CMP!J51,CMP!AA51,CMP!J59,CMP!AA59,CMP!J68,CMP!AA68,CMP!J76,CMP!AA76) -> 74 | N22: =sum(CMP!K3,CMP!AB3,CMP!K11,CMP!AB11,CMP!K19,CMP!AB19,CMP!K27,CMP!AB27,CMP!K35,CMP!AB35,CMP!K43,CMP!AB43,CMP!K51,CMP!AB51,CMP!K59,CMP!AB59,CMP!K68,CMP!AB68,CMP!K76,CMP!AB76) -> 152 | O22: =sum(CMP!L3,CMP!AC3,CMP!L11,CMP!AC11,CMP!L19,CMP!AC19,CMP!L27,CMP!AC27,CMP!L35,CMP!AC35,CMP!L43,CMP!AC43,CMP!L51,CMP!AC51,CMP!L59,CMP!AC59,CMP!L68,CMP!AC68,CMP!L76,CMP!AC76) -> 23 | P22: =sum(CMP!M3,CMP!AD3,CMP!M11,CMP!AD11,CMP!M19,CMP!AD19,CMP!M27,CMP!AD27,CMP!M35,CMP!AD35,CMP!M43,CMP!AD43,CMP!M51,CMP!AD51,CMP!M59,CMP!AD59,CMP!M68,CMP!AD68,CMP!M76,CMP!AD76) -> 3 | Q22: =sum(CMP!N3,CMP!AE3,CMP!N11,CMP!AE11,CMP!N19,CMP!AE19,CMP!N27,CMP!AE27,CMP!N35,CMP!AE35,CMP!N43,CMP!AE43,CMP!N51,CMP!AE51,CMP!N59,CMP!AE59,CMP!N68,CMP!AE68,CMP!N76,CMP!AE76) -> 20 | R22: =sum(CMP!O3,CMP!AF3,CMP!O11,CMP!AF11,CMP!O19,CMP!AF19,CMP!O27,CMP!AF27,CMP!O35,CMP!AF35,CMP!O43,CMP!AF43,CMP!O51,CMP!AF51,CMP!O59,CMP!AF59,CMP!O68,CMP!AF68,CMP!O76,CMP!AF76) -> 0 | S22: =sum(CMP!P3,CMP!AG3,CMP!P11,CMP!AG11,CMP!P19,CMP!AG19,CMP!P27,CMP!AG27,CMP!P35,CMP!AG35,CMP!P43,CMP!AG43,CMP!P51,CMP!AG51,CMP!P59,CMP!AG59,CMP!P68,CMP!AG68,CMP!P76,CMP!AG76) -> 0 | T22: =J22/I22 -> 0.00019955023
A23: Chaos of the Missing Pens | B23: Invayda Zim | C23: =sum(D23:E23) -> 14 | D23: 3 | E23: 11 | F23: =sum(CMP!C4,CMP!T4,CMP!C12,CMP!T12,CMP!C20,CMP!T20,CMP!C28,CMP!T28,CMP!C36,CMP!T36,CMP!C44,CMP!T44,CMP!C52,CMP!T52,CMP!C60,CMP!T60,CMP!C69,CMP!T69,CMP!C77,CMP!T77) -> 15 | G23: =sum(CMP!D4,CMP!U4,CMP!D12,CMP!U12,CMP!D20,CMP!U20,CMP!D28,CMP!U28,CMP!D36,CMP!U36,CMP!D44,CMP!U44,CMP!D52,CMP!U52,CMP!D60,CMP!U60,CMP!D69,CMP!U69,CMP!D77,CMP!U77) -> 1125 | H23: =sum(CMP!E4,CMP!V4,CMP!E12,CMP!V12,CMP!E20,CMP!V20,CMP!E28,CMP!V28,CMP!E36,CMP!V36,CMP!E44,CMP!V44,CMP!E52,CMP!V52,CMP!E60,CMP!V60,CMP!E69,CMP!V69,CMP!E77,CMP!V77) -> 7 | I23: =sum(CMP!F4,CMP!W4,CMP!F12,CMP!W12,CMP!F20,CMP!W20,CMP!F28,CMP!W28,CMP!F36,CMP!W36,CMP!F44,CMP!W44,CMP!F52,CMP!W52,CMP!F60,CMP!W60,CMP!F69,CMP!W69,CMP!F77,CMP!W77) -> 1123 | J23: =sum(CMP!G4,CMP!X4,CMP!G12,CMP!X12,CMP!G20,CMP!X20,CMP!G28,CMP!X28,CMP!G36,CMP!X36,CMP!G44,CMP!X44,CMP!G52,CMP!X52,CMP!G60,CMP!X60,CMP!G69,CMP!X69,CMP!G77,CMP!X77) -> 0.23439815 | K23: =sum(CMP!H4,CMP!Y4,CMP!H12,CMP!Y12,CMP!H20,CMP!Y20,CMP!H28,CMP!Y28,CMP!H36,CMP!Y36,CMP!H44,CMP!Y44,CMP!H52,CMP!Y52,CMP!H60,CMP!Y60,CMP!H69,CMP!Y69,CMP!H77,CMP!Y77) -> 2 | L23: =K23/(HOUR(J23)*60+(MINUTE(J23)+((SECOND(J23)/60)))) -> 0.0059253407 | M23: =sum(CMP!J4,CMP!AA4,CMP!J12,CMP!AA12,CMP!J20,CMP!AA20,CMP!J28,CMP!AA28,CMP!J36,CMP!AA36,CMP!J44,CMP!AA44,CMP!J52,CMP!AA52,CMP!J60,CMP!AA60,CMP!J69,CMP!AA69,CMP!J77,CMP!AA77) -> 54 | N23: =sum(CMP!K4,CMP!AB4,CMP!K12,CMP!AB12,CMP!K20,CMP!AB20,CMP!K28,CMP!AB28,CMP!K36,CMP!AB36,CMP!K44,CMP!AB44,CMP!K52,CMP!AB52,CMP!K60,CMP!AB60,CMP!K69,CMP!AB69,CMP!K77,CMP!AB77) -> 176 | O23: =sum(CMP!L4,CMP!AC4,CMP!L12,CMP!AC12,CMP!L20,CMP!AC20,CMP!L28,CMP!AC28,CMP!L36,CMP!AC36,CMP!L44,CMP!AC44,CMP!L52,CMP!AC52,CMP!L60,CMP!AC60,CMP!L69,CMP!AC69,CMP!L77,CMP!AC77) -> 22 | P23: =sum(CMP!M4,CMP!AD4,CMP!M12,CMP!AD12,CMP!M20,CMP!AD20,CMP!M28,CMP!AD28,CMP!M36,CMP!AD36,CMP!M44,CMP!AD44,CMP!M52,CMP!AD52,CMP!M60,CMP!AD60,CMP!M69,CMP!AD69,CMP!M77,CMP!AD77) -> 6 | Q23: =sum(CMP!N4,CMP!AE4,CMP!N12,CMP!AE12,CMP!N20,CMP!AE20,CMP!N28,CMP!AE28,CMP!N36,CMP!AE36,CMP!N44,CMP!AE44,CMP!N52,CMP!AE52,CMP!N60,CMP!AE60,CMP!N69,CMP!AE69,CMP!N77,CMP!AE77) -> 23 | R23: =sum(CMP!O4,CMP!AF4,CMP!O12,CMP!AF12,CMP!O20,CMP!AF20,CMP!O28,CMP!AF28,CMP!O36,CMP!AF36,CMP!O44,CMP!AF44,CMP!O52,CMP!AF52,CMP!O60,CMP!AF60,CMP!O69,CMP!AF69,CMP!O77,CMP!AF77) -> 0 | S23: =sum(CMP!P4,CMP!AG4,CMP!P12,CMP!AG12,CMP!P20,CMP!AG20,CMP!P28,CMP!AG28,CMP!P36,CMP!AG36,CMP!P44,CMP!AG44,CMP!P52,CMP!AG52,CMP!P60,CMP!AG60,CMP!P69,CMP!AG69,CMP!P77,CMP!AG77) -> 0 | T23: =J23/I23 -> 0.00020872498
A24: Chaos of the Missing Pens | B24: Grunt Padre | C24: =sum(D24:E24) -> 15 | D24: 3 | E24: 12 | F24: =sum(CMP!C5,CMP!T5,CMP!C13,CMP!T13,CMP!C21,CMP!T21,CMP!C29,CMP!T29,CMP!C37,CMP!T37,CMP!C45,CMP!T45,CMP!C53,CMP!T53,CMP!C61,CMP!T61,CMP!C70,CMP!T70,CMP!C78,CMP!T78) -> 3 | G24: =sum(CMP!D5,CMP!U5,CMP!D13,CMP!U13,CMP!D21,CMP!U21,CMP!D29,CMP!U29,CMP!D37,CMP!U37,CMP!D45,CMP!U45,CMP!D53,CMP!U53,CMP!D61,CMP!U61,CMP!D70,CMP!U70,CMP!D78,CMP!U78) -> 1166 | H24: =sum(CMP!E5,CMP!V5,CMP!E13,CMP!V13,CMP!E21,CMP!V21,CMP!E29,CMP!V29,CMP!E37,CMP!V37,CMP!E45,CMP!V45,CMP!E53,CMP!V53,CMP!E61,CMP!V61,CMP!E70,CMP!V70,CMP!E78,CMP!V78) -> 5 | I24: =sum(CMP!F5,CMP!W5,CMP!F13,CMP!W13,CMP!F21,CMP!W21,CMP!F29,CMP!W29,CMP!F37,CMP!W37,CMP!F45,CMP!W45,CMP!F53,CMP!W53,CMP!F61,CMP!W61,CMP!F70,CMP!W70,CMP!F78,CMP!W78) -> 1480 | J24: =sum(CMP!G5,CMP!X5,CMP!G13,CMP!X13,CMP!G21,CMP!X21,CMP!G29,CMP!X29,CMP!G37,CMP!X37,CMP!G45,CMP!X45,CMP!G53,CMP!X53,CMP!G61,CMP!X61,CMP!G70,CMP!X70,CMP!G78,CMP!X78) -> 0.24631944 | K24: =sum(CMP!H5,CMP!Y5,CMP!H13,CMP!Y13,CMP!H21,CMP!Y21,CMP!H29,CMP!Y29,CMP!H37,CMP!Y37,CMP!H45,CMP!Y45,CMP!H53,CMP!Y53,CMP!H61,CMP!Y61,CMP!H70,CMP!Y70,CMP!H78,CMP!Y78) -> -314 | L24: =K24/(HOUR(J24)*60+(MINUTE(J24)+((SECOND(J24)/60)))) -> -0.88525515 | M24: =sum(CMP!J5,CMP!AA5,CMP!J13,CMP!AA13,CMP!J21,CMP!AA21,CMP!J29,CMP!AA29,CMP!J37,CMP!AA37,CMP!J45,CMP!AA45,CMP!J53,CMP!AA53,CMP!J61,CMP!AA61,CMP!J70,CMP!AA70,CMP!J78,CMP!AA78) -> 35 | N24: =sum(CMP!K5,CMP!AB5,CMP!K13,CMP!AB13,CMP!K21,CMP!AB21,CMP!K29,CMP!AB29,CMP!K37,CMP!AB37,CMP!K45,CMP!AB45,CMP!K53,CMP!AB53,CMP!K61,CMP!AB61,CMP!K70,CMP!AB70,CMP!K78,CMP!AB78) -> 173 | O24: =sum(CMP!L5,CMP!AC5,CMP!L13,CMP!AC13,CMP!L21,CMP!AC21,CMP!L29,CMP!AC29,CMP!L37,CMP!AC37,CMP!L45,CMP!AC45,CMP!L53,CMP!AC53,CMP!L61,CMP!AC61,CMP!L70,CMP!AC70,CMP!L78,CMP!AC78) -> 50 | P24: =sum(CMP!M5,CMP!AD5,CMP!M13,CMP!AD13,CMP!M21,CMP!AD21,CMP!M29,CMP!AD29,CMP!M37,CMP!AD37,CMP!M45,CMP!AD45,CMP!M53,CMP!AD53,CMP!M61,CMP!AD61,CMP!M70,CMP!AD70,CMP!M78,CMP!AD78) -> 13 | Q24: =sum(CMP!N5,CMP!AE5,CMP!N13,CMP!AE13,CMP!N21,CMP!AE21,CMP!N29,CMP!AE29,CMP!N37,CMP!AE37,CMP!N45,CMP!AE45,CMP!N53,CMP!AE53,CMP!N61,CMP!AE61,CMP!N70,CMP!AE70,CMP!N78,CMP!AE78) -> 16 | R24: =sum(CMP!O5,CMP!AF5,CMP!O13,CMP!AF13,CMP!O21,CMP!AF21,CMP!O29,CMP!AF29,CMP!O37,CMP!AF37,CMP!O45,CMP!AF45,CMP!O53,CMP!AF53,CMP!O61,CMP!AF61,CMP!O70,CMP!AF70,CMP!O78,CMP!AF78) -> 1 | S24: =sum(CMP!P5,CMP!AG5,CMP!P13,CMP!AG13,CMP!P21,CMP!AG21,CMP!P29,CMP!AG29,CMP!P37,CMP!AG37,CMP!P45,CMP!AG45,CMP!P53,CMP!AG53,CMP!P61,CMP!AG61,CMP!P70,CMP!AG70,CMP!P78,CMP!AG78) -> 0 | T24: =J24/I24 -> 0.00016643206
A25: Chaos of the Missing Pens | B25: Nihilus | C25: =sum(D25:E25) -> 15 | D25: 3 | E25: 12 | F25: =sum(CMP!C6,CMP!T6,CMP!C14,CMP!T14,CMP!C22,CMP!T22,CMP!C30,CMP!T30,CMP!C38,CMP!T38,CMP!C46,CMP!T46,CMP!C54,CMP!T54,CMP!C62,CMP!T62,CMP!C71,CMP!T71,CMP!C79,CMP!T79) -> 2 | G25: =sum(CMP!D6,CMP!U6,CMP!D14,CMP!U14,CMP!D22,CMP!U22,CMP!D30,CMP!U30,CMP!D38,CMP!U38,CMP!D46,CMP!U46,CMP!D54,CMP!U54,CMP!D62,CMP!U62,CMP!D71,CMP!U71,CMP!D79,CMP!U79) -> 1117 | H25: =sum(CMP!E6,CMP!V6,CMP!E14,CMP!V14,CMP!E22,CMP!V22,CMP!E30,CMP!V30,CMP!E38,CMP!V38,CMP!E46,CMP!V46,CMP!E54,CMP!V54,CMP!E62,CMP!V62,CMP!E71,CMP!V71,CMP!E79,CMP!V79) -> 9 | I25: =sum(CMP!F6,CMP!W6,CMP!F14,CMP!W14,CMP!F22,CMP!W22,CMP!F30,CMP!W30,CMP!F38,CMP!W38,CMP!F46,CMP!W46,CMP!F54,CMP!W54,CMP!F62,CMP!W62,CMP!F71,CMP!W71,CMP!F79,CMP!W79) -> 1140 | J25: =sum(CMP!G6,CMP!X6,CMP!G14,CMP!X14,CMP!G22,CMP!X22,CMP!G30,CMP!X30,CMP!G38,CMP!X38,CMP!G46,CMP!X46,CMP!G54,CMP!X54,CMP!G62,CMP!X62,CMP!G71,CMP!X71,CMP!G79,CMP!X79) -> 0.24709491 | K25: =sum(CMP!H6,CMP!Y6,CMP!H14,CMP!Y14,CMP!H22,CMP!Y22,CMP!H30,CMP!Y30,CMP!H38,CMP!Y38,CMP!H46,CMP!Y46,CMP!H54,CMP!Y54,CMP!H62,CMP!Y62,CMP!H71,CMP!Y71,CMP!H79,CMP!Y79) -> -23 | L25: =K25/(HOUR(J25)*60+(MINUTE(J25)+((SECOND(J25)/60)))) -> -0.06464003 | M25: =sum(CMP!J6,CMP!AA6,CMP!J14,CMP!AA14,CMP!J22,CMP!AA22,CMP!J30,CMP!AA30,CMP!J38,CMP!AA38,CMP!J46,CMP!AA46,CMP!J54,CMP!AA54,CMP!J62,CMP!AA62,CMP!J71,CMP!AA71,CMP!J79,CMP!AA79) -> 34 | N25: =sum(CMP!K6,CMP!AB6,CMP!K14,CMP!AB14,CMP!K22,CMP!AB22,CMP!K30,CMP!AB30,CMP!K38,CMP!AB38,CMP!K46,CMP!AB46,CMP!K54,CMP!AB54,CMP!K62,CMP!AB62,CMP!K71,CMP!AB71,CMP!K79,CMP!AB79) -> 147 | O25: =sum(CMP!L6,CMP!AC6,CMP!L14,CMP!AC14,CMP!L22,CMP!AC22,CMP!L30,CMP!AC30,CMP!L38,CMP!AC38,CMP!L46,CMP!AC46,CMP!L54,CMP!AC54,CMP!L62,CMP!AC62,CMP!L71,CMP!AC71,CMP!L79,CMP!AC79) -> 22 | P25: =sum(CMP!M6,CMP!AD6,CMP!M14,CMP!AD14,CMP!M22,CMP!AD22,CMP!M30,CMP!AD30,CMP!M38,CMP!AD38,CMP!M46,CMP!AD46,CMP!M54,CMP!AD54,CMP!M62,CMP!AD62,CMP!M71,CMP!AD71,CMP!M79,CMP!AD79) -> 5 | Q25: =sum(CMP!N6,CMP!AE6,CMP!N14,CMP!AE14,CMP!N22,CMP!AE22,CMP!N30,CMP!AE30,CMP!N38,CMP!AE38,CMP!N46,CMP!AE46,CMP!N54,CMP!AE54,CMP!N62,CMP!AE62,CMP!N71,CMP!AE71,CMP!N79,CMP!AE79) -> 25 | R25: =sum(CMP!O6,CMP!AF6,CMP!O14,CMP!AF14,CMP!O22,CMP!AF22,CMP!O30,CMP!AF30,CMP!O38,CMP!AF38,CMP!O46,CMP!AF46,CMP!O54,CMP!AF54,CMP!O62,CMP!AF62,CMP!O71,CMP!AF71,CMP!O79,CMP!AF79) -> 1 | S25: =sum(CMP!P6,CMP!AG6,CMP!P14,CMP!AG14,CMP!P22,CMP!AG22,CMP!P30,CMP!AG30,CMP!P38,CMP!AG38,CMP!P46,CMP!AG46,CMP!P54,CMP!AG54,CMP!P62,CMP!AG62,CMP!P71,CMP!AG71,CMP!P79,CMP!AG79) -> 0 | T25: =J25/I25 -> 0.00021674992
A26: Chaos of the Missing Pens | B26: Beam1n1 | C26: =sum(D26:E26) -> 2 | D26: 0 | E26: 2 | F26: =sum(CMP!C7,CMP!T7,CMP!C15,CMP!T15,CMP!C23,CMP!T23,CMP!C31,CMP!T31,CMP!C39,CMP!T39,CMP!C47,CMP!T47,CMP!C55,CMP!T55,CMP!C63,CMP!T63,CMP!C72,CMP!T72,CMP!C80,CMP!T80) -> 0 | G26: =sum(CMP!D7,CMP!U7,CMP!D15,CMP!U15,CMP!D23,CMP!U23,CMP!D31,CMP!U31,CMP!D39,CMP!U39,CMP!D47,CMP!U47,CMP!D55,CMP!U55,CMP!D63,CMP!U63,CMP!D72,CMP!U72,CMP!D80,CMP!U80) -> 101 | H26: =sum(CMP!E7,CMP!V7,CMP!E15,CMP!V15,CMP!E23,CMP!V23,CMP!E31,CMP!V31,CMP!E39,CMP!V39,CMP!E47,CMP!V47,CMP!E55,CMP!V55,CMP!E63,CMP!V63,CMP!E72,CMP!V72,CMP!E80,CMP!V80) -> 0 | I26: =sum(CMP!F7,CMP!W7,CMP!F15,CMP!W15,CMP!F23,CMP!W23,CMP!F31,CMP!W31,CMP!F39,CMP!W39,CMP!F47,CMP!W47,CMP!F55,CMP!W55,CMP!F63,CMP!W63,CMP!F72,CMP!W72,CMP!F80,CMP!W80) -> 142 | J26: =sum(CMP!G7,CMP!X7,CMP!G15,CMP!X15,CMP!G23,CMP!X23,CMP!G31,CMP!X31,CMP!G39,CMP!X39,CMP!G47,CMP!X47,CMP!G55,CMP!X55,CMP!G63,CMP!X63,CMP!G72,CMP!X72,CMP!G80,CMP!X80) -> 0.024618056 | K26: =sum(CMP!H7,CMP!Y7,CMP!H15,CMP!Y15,CMP!H23,CMP!Y23,CMP!H31,CMP!Y31,CMP!H39,CMP!Y39,CMP!H47,CMP!Y47,CMP!H55,CMP!Y55,CMP!H63,CMP!Y63,CMP!H72,CMP!Y72,CMP!H80,CMP!Y80) -> -41 | L26: =K26/(HOUR(J26)*60+(MINUTE(J26)+((SECOND(J26)/60)))) -> -1.1565585 | M26: =sum(CMP!J7,CMP!AA7,CMP!J15,CMP!AA15,CMP!J23,CMP!AA23,CMP!J31,CMP!AA31,CMP!J39,CMP!AA39,CMP!J47,CMP!AA47,CMP!J55,CMP!AA55,CMP!J63,CMP!AA63,CMP!J72,CMP!AA72,CMP!J80,CMP!AA80) -> 2 | N26: =sum(CMP!K7,CMP!AB7,CMP!K15,CMP!AB15,CMP!K23,CMP!AB23,CMP!K31,CMP!AB31,CMP!K39,CMP!AB39,CMP!K47,CMP!AB47,CMP!K55,CMP!AB55,CMP!K63,CMP!AB63,CMP!K72,CMP!AB72,CMP!K80,CMP!AB80) -> 11 | O26: =sum(CMP!L7,CMP!AC7,CMP!L15,CMP!AC15,CMP!L23,CMP!AC23,CMP!L31,CMP!AC31,CMP!L39,CMP!AC39,CMP!L47,CMP!AC47,CMP!L55,CMP!AC55,CMP!L63,CMP!AC63,CMP!L72,CMP!AC72,CMP!L80,CMP!AC80) -> 3 | P26: =sum(CMP!M7,CMP!AD7,CMP!M15,CMP!AD15,CMP!M23,CMP!AD23,CMP!M31,CMP!AD31,CMP!M39,CMP!AD39,CMP!M47,CMP!AD47,CMP!M55,CMP!AD55,CMP!M63,CMP!AD63,CMP!M72,CMP!AD72,CMP!M80,CMP!AD80) -> 0 | Q26: =sum(CMP!N7,CMP!AE7,CMP!N15,CMP!AE15,CMP!N23,CMP!AE23,CMP!N31,CMP!AE31,CMP!N39,CMP!AE39,CMP!N47,CMP!AE47,CMP!N55,CMP!AE55,CMP!N63,CMP!AE63,CMP!N72,CMP!AE72,CMP!N80,CMP!AE80) -> 0 | R26: =sum(CMP!O7,CMP!AF7,CMP!O15,CMP!AF15,CMP!O23,CMP!AF23,CMP!O31,CMP!AF31,CMP!O39,CMP!AF39,CMP!O47,CMP!AF47,CMP!O55,CMP!AF55,CMP!O63,CMP!AF63,CMP!O72,CMP!AF72,CMP!O80,CMP!AF80) -> 0 | S26: =sum(CMP!P7,CMP!AG7,CMP!P15,CMP!AG15,CMP!P23,CMP!AG23,CMP!P31,CMP!AG31,CMP!P39,CMP!AG39,CMP!P47,CMP!AG47,CMP!P55,CMP!AG55,CMP!P63,CMP!AG63,CMP!P72,CMP!AG72,CMP!P80,CMP!AG80) -> 0 | T26: =J26/I26 -> 0.00017336659
B27: AJ (Sub) | C27: =sum(D27:E27) -> 2 | D27: 0 | E27: 2 | F27: =sum(CMP!C64,CMP!T64) -> 0 | G27: =sum(CMP!D64,CMP!U64) -> 123 | H27: =sum(CMP!E64,CMP!V64) -> 0 | I27: =sum(CMP!F64,CMP!W64) -> 134 | J27: =sum(CMP!G64,CMP!X64) -> 0.024618056 | K27: =sum(CMP!H64,CMP!Y64) -> -11 | L27: =K27/(HOUR(J27)*60+(MINUTE(J27)+((SECOND(J27)/60)))) -> -0.31029619 | M27: =sum(CMP!J64,CMP!AA64) -> 1 | N27: =sum(CMP!K64,CMP!AB64) -> 18 | O27: =sum(CMP!L64,CMP!AC64) -> 3 | P27: =sum(CMP!M64,CMP!AD64) -> 1 | Q27: =sum(CMP!N64,CMP!AE64) -> 4 | R27: =sum(CMP!O64,CMP!AF64) -> 0 | S27: =sum(CMP!P64,CMP!AG64) -> 0 | T27: =J27/I27 -> 0.00018371683
